File: data/Long/Specimen_RawData_3.csv
Specimen number (included),3
Modulus (Automatic Young's),"259,371.60226",MPa
Length,"26.00000",mm
Specimen ID,"0040"
Thickness,"2.04500",mm
Width,"10.15000",mm
Tensile stress at Tensile strength,"806.69379",MPa
Tensile strain (Strain 1) at Tensile strength,"0.03669",mm/mm

Time,Extension,Load,Tensile strain (Strain 1),Tensile stress
(s),(mm),(N),(%),(MPa)
"0.00000","0.00181","505.08188","-0.0008","24.3334"
"0.20000","0.00400","543.89502","-0.0001","26.2033"
"0.40000","0.00831","668.74487","0.0018","32.2182"
"0.60000","0.01175","757.94550","0.0035","36.5156"
"0.80000","0.01537","833.14423","0.0046","40.1385"
"1.00000","0.01837","892.74701","0.0057","43.0100"
"1.20000","0.02231","965.67773","0.0065","46.5236"
"1.40000","0.02475","1,006.28992","0.0076","48.4801"
"1.60000","0.02850","1,078.00061","0.0085","51.9349"
"1.80000","0.03181","1,132.07458","0.0097","54.5401"
"2.00000","0.03525","1,197.65283","0.0107","57.6994"
"2.20000","0.03869","1,249.27930","0.0118","60.1867"
"2.40000","0.04169","1,301.46899","0.0127","62.7010"
"2.60000","0.04537","1,361.07983","0.0137","65.5729"
"2.80000","0.04812","1,402.05493","0.0145","67.5469"
"3.00000","0.05187","1,467.99072","0.0161","70.7235"
"3.20000","0.05500","1,511.87988","0.0165","72.8380"
"3.40000","0.05881","1,576.62354","0.0177","75.9571"
"3.60000","0.06169","1,609.67749","0.0185","77.5496"
"3.80000","0.06512","1,664.69922","0.0193","80.2004"
"4.00000","0.06862","1,715.11194","0.0199","82.6291"
"4.20000","0.07156","1,754.29822","0.0210","84.5170"
"4.40000","0.07537","1,814.07690","0.0219","87.3970"
"4.60000","0.07825","1,848.15930","0.0226","89.0390"
"4.80000","0.08225","1,909.36499","0.0234","91.9877"
"5.00000","0.08481","1,931.83032","0.0241","93.0700"
"5.20000","0.08850","1,986.62817","0.0250","95.7100"
"5.40000","0.09194","2,031.71313","0.0260","97.8820"
"5.60000","0.09500","2,071.77856","0.0267","99.8123"
"5.80000","0.09869","2,123.04053","0.0276","102.2819"
"6.00000","0.10169","2,157.13452","0.0284","103.9245"
"6.20000","0.10562","2,209.04858","0.0294","106.4256"
"6.40000","0.10806","2,229.90576","0.0301","107.4304"
"6.60000","0.11194","2,285.51489","0.0308","110.1095"
"6.80000","0.11512","2,320.32568","0.0316","111.7866"
"7.00000","0.11856","2,366.48779","0.0321","114.0105"
"7.20000","0.12194","2,402.20801","0.0330","115.7314"
"7.40000","0.12506","2,439.96094","0.0339","117.5502"
"7.60000","0.12875","2,484.01245","0.0344","119.6725"
"7.80000","0.13137","2,508.29883","0.0353","120.8426"
"8.00000","0.13525","2,561.86475","0.0361","123.4232"
"8.20000","0.13837","2,592.11890","0.0369","124.8808"
"8.40000","0.14212","2,641.76636","0.0376","127.2726"
"8.60000","0.14500","2,665.05884","0.0380","128.3948"
"8.80000","0.14844","2,708.29297","0.0389","130.4777"
"9.00000","0.15200","2,748.45703","0.0396","132.4127"
"9.20000","0.15487","2,774.67822","0.0404","133.6759"
"9.40000","0.15862","2,826.13721","0.0414","136.1551"
"9.60000","0.16162","2,851.18335","0.0421","137.3617"
"9.80000","0.16562","2,900.67188","0.0430","139.7460"
"10.00000","0.16812","2,916.14380","0.0430","140.4913"
"10.20000","0.17181","2,964.12744","0.0440","142.8031"
"10.40000","0.17525","3,000.51050","0.0447","144.5559"
"10.60000","0.17837","3,032.98511","0.0454","146.1204"
"10.80000","0.18200","3,075.24194","0.0462","148.1562"
"11.00000","0.18500","3,101.52563","0.0469","149.4225"
"11.20000","0.18894","3,147.69482","0.0476","151.6468"
"11.40000","0.19137","3,162.99341","0.0481","152.3839"
"11.60000","0.19519","3,211.35449","0.0491","154.7137"
"11.80000","0.19844","3,241.06592","0.0494","156.1452"
"12.00000","0.20194","3,281.10303","0.0506","158.0740"
"12.20000","0.20525","3,310.76074","0.0510","159.5029"
"12.40000","0.20844","3,344.66064","0.0517","161.1360"
"12.60000","0.21206","3,383.32983","0.0524","162.9990"
"12.80000","0.21475","3,402.84863","0.0528","163.9394"
"13.00000","0.21856","3,451.45654","0.0537","166.2812"
"13.20000","0.22169","3,476.18237","0.0546","167.4724"
"13.40000","0.22550","3,522.99243","0.0554","169.7276"
"13.60000","0.22831","3,539.37793","0.0557","170.5170"
"13.80000","0.23175","3,577.81543","0.0567","172.3688"
"14.00000","0.23531","3,614.15601","0.0573","174.1196"
"14.20000","0.23819","3,635.45679","0.0578","175.1458"
"14.40000","0.24200","3,683.05396","0.0588","177.4389"
"14.60000","0.24506","3,704.32202","0.0594","178.4635"
"14.80000","0.24894","3,747.55737","0.0599","180.5464"
"15.00000","0.25150","3,759.75366","0.0603","181.1340"
"15.20000","0.25519","3,802.09570","0.0612","183.1739"
"15.40000","0.25850","3,833.34082","0.0616","184.6792"
"15.60000","0.26175","3,863.83228","0.0624","186.1482"
"15.80000","0.26531","3,902.64648","0.0629","188.0182"
"16.00000","0.26837","3,926.04907","0.0635","189.1457"
"16.20000","0.27231","3,967.69189","0.0648","191.1519"
"16.40000","0.27469","3,979.10669","0.0649","191.7018"
"16.60000","0.27850","4,023.64648","0.0658","193.8476"
"16.80000","0.28181","4,051.20483","0.0666","195.1753"
"17.00000","0.28531","4,089.26636","0.0672","197.0090"
"17.20000","0.28869","4,116.00830","0.0675","198.2973"
"17.40000","0.29175","4,141.73682","0.0680","199.5369"
"17.60000","0.29537","4,176.96533","0.0686","201.2341"
"17.80000","0.29812","4,194.14746","0.0691","202.0619"
"18.00000","0.30187","4,237.82715","0.0701","204.1662"
"18.20000","0.30500","4,261.14258","0.0705","205.2895"
"18.40000","0.30875","4,299.85156","0.0713","207.1544"
"18.60000","0.31169","4,316.14355","0.0719","207.9393"
"18.80000","0.31512","4,350.22559","0.0729","209.5813"
"19.00000","0.31856","4,378.69336","0.0731","210.9527"
"19.20000","0.32156","4,393.64746","0.0736","211.6732"
"19.40000","0.32531","4,432.14453","0.0744","213.5279"
"19.60000","0.32831","4,445.96973","0.0746","214.1939"
"19.80000","0.33231","4,485.76807","0.0752","216.1113"
"20.00000","0.33487","4,490.38623","0.0756","216.3338"
"20.20000","0.33850","4,524.98096","0.0760","218.0005"
"20.40000","0.34200","4,551.05908","0.0770","219.2568"
"20.60000","0.34500","4,570.09277","0.0775","220.1738"
"20.80000","0.34869","4,605.33838","0.0777","221.8718"
"21.00000","0.35175","4,621.54785","0.0782","222.6528"
"21.20000","0.35556","4,655.72607","0.0786","224.2994"
"21.40000","0.35806","4,661.83057","0.0794","224.5935"
"21.60000","0.36194","4,702.77686","0.0799","226.5661"
"21.80000","0.36512","4,721.88184","0.0803","227.4866"
"22.00000","0.36856","4,750.06592","0.0810","228.8444"
"22.20000","0.37194","4,774.43506","0.0812","230.0184"
"22.40000","0.37506","4,796.39893","0.0819","231.0766"
"22.60000","0.37881","4,826.89160","0.0825","232.5456"
"22.80000","0.38144","4,836.00195","0.0828","232.9845"
"23.00000","0.38525","4,876.16260","0.0834","234.9194"
"23.20000","0.38837","4,892.98340","0.0840","235.7298"
"23.40000","0.39206","4,926.84375","0.0847","237.3610"
"23.60000","0.39500","4,940.54346","0.0850","238.0211"
"23.80000","0.39844","4,970.54395","0.0855","239.4664"
"24.00000","0.40194","4,998.84961","0.0860","240.8301"
"24.20000","0.40487","5,013.49170","0.0865","241.5355"
"24.40000","0.40862","5,053.49463","0.0874","243.4627"
"24.60000","0.41169","5,066.71973","0.0876","244.0999"
"24.80000","0.41562","5,103.97168","0.0884","245.8945"
"25.00000","0.41812","5,108.60645","0.0884","246.1178"
"25.20000","0.42181","5,144.70166","0.0894","247.8568"
"25.40000","0.42525","5,170.89258","0.0897","249.1186"
"25.60000","0.42837","5,191.00781","0.0904","250.0877"
"25.80000","0.43200","5,225.64404","0.0910","251.7564"
"26.00000","0.43500","5,241.14746","0.0912","252.5033"
"26.20000","0.43894","5,274.64990","0.0918","254.1173"
"26.40000","0.44137","5,279.43359","0.0922","254.3478"
"26.60000","0.44519","5,317.50977","0.0927","256.1822"
"26.80000","0.44850","5,337.65479","0.0929","257.1527"
"27.00000","0.45194","5,365.50732","0.0937","258.4946"
"27.20000","0.45525","5,384.50195","0.0941","259.4097"
"27.40000","0.45844","5,408.80713","0.0949","260.5806"
"27.60000","0.46206","5,434.98096","0.0952","261.8416"
"27.80000","0.46475","5,443.50391","0.0955","262.2522"
"28.00000","0.46862","5,481.07275","0.0962","264.0622"
"28.20000","0.47169","5,495.34326","0.0967","264.7497"
"28.40000","0.47550","5,529.62549","0.0972","266.4013"
"28.60000","0.47837","5,535.45166","0.0973","266.6820"
"28.80000","0.48175","5,562.61523","0.0982","267.9907"
"29.00000","0.48531","5,588.76270","0.0985","269.2504"
"29.20000","0.48819","5,599.96631","0.0988","269.7901"
"29.40000","0.49194","5,636.79004","0.0995","271.5642"
"29.60000","0.49506","5,648.77734","0.0995","272.1417"
"29.80000","0.49894","5,681.98389","0.1007","273.7415"
"30.00000","0.50150","5,684.65283","0.1005","273.8701"
"30.20000","0.50519","5,716.03369","0.1011","275.3819"
"30.40000","0.50850","5,738.03369","0.1019","276.4418"
"30.60000","0.51175","5,759.72363","0.1021","277.4868"
"30.80000","0.51537","5,788.51221","0.1030","278.8737"
"31.00000","0.51837","5,801.74072","0.1030","279.5110"
"31.20000","0.52231","5,833.09668","0.1036","281.0217"
"31.40000","0.52469","5,835.31445","0.1036","281.1285"
"31.60000","0.52856","5,871.41943","0.1044","282.8680"
"31.80000","0.53181","5,888.61279","0.1048","283.6963"
"32.00000","0.53525","5,916.00781","0.1055","285.0161"
"32.20000","0.53869","5,934.52783","0.1055","285.9083"
"32.40000","0.54175","5,951.85889","0.1061","286.7433"
"32.60000","0.54531","5,977.49951","0.1067","287.9786"
"32.80000","0.54812","5,986.61719","0.1070","288.4178"
"33.00000","0.55187","6,021.26367","0.1074","290.0870"
"33.20000","0.55500","6,037.00928","0.1081","290.8456"
"33.40000","0.55881","6,069.89502","0.1087","292.4299"
"33.60000","0.56169","6,077.75977","0.1089","292.8088"
"33.80000","0.56519","6,105.37109","0.1094","294.1391"
"34.00000","0.56856","6,128.32373","0.1099","295.2448"
"34.20000","0.57150","6,141.51562","0.1103","295.8804"
"34.40000","0.57537","6,177.86230","0.1114","297.6315"
"34.60000","0.57819","6,186.72656","0.1112","298.0585"
"34.80000","0.58225","6,223.41162","0.1120","299.8259"
"35.00000","0.58487","6,225.84180","0.1121","299.9430"
"35.20000","0.58850","6,257.15332","0.1128","301.4515"
"35.40000","0.59200","6,280.68213","0.1135","302.5851"
"35.60000","0.59500","6,296.68018","0.1137","303.3558"
"35.80000","0.59869","6,329.34473","0.1143","304.9295"
"36.00000","0.60175","6,342.34033","0.1146","305.5555"
"36.20000","0.60562","6,372.92139","0.1150","307.0289"
"36.40000","0.60806","6,376.20996","0.1152","307.1873"
"36.60000","0.61194","6,411.26953","0.1157","308.8764"
"36.80000","0.61512","6,426.96045","0.1160","309.6323"
"37.00000","0.61856","6,452.55762","0.1169","310.8655"
"37.20000","0.62187","6,471.96533","0.1174","311.8005"
"37.40000","0.62506","6,492.16699","0.1178","312.7738"
"37.60000","0.62875","6,518.78174","0.1187","314.0560"
"37.80000","0.63137","6,525.15723","0.1184","314.3632"
"38.00000","0.63531","6,561.22559","0.1193","316.1008"
"38.20000","0.63837","6,573.77002","0.1196","316.7052"
"38.40000","0.64212","6,604.89355","0.1201","318.2046"
"38.60000","0.64506","6,612.71533","0.1205","318.5815"
"38.80000","0.64844","6,640.05225","0.1211","319.8985"
"39.00000","0.65194","6,665.32666","0.1212","321.1161"
"39.20000","0.65487","6,677.18213","0.1220","321.6873"
"39.40000","0.65862","6,713.94629","0.1226","323.4585"
"39.60000","0.66169","6,727.86230","0.1228","324.1289"
"39.80000","0.66556","6,761.91650","0.1236","325.7695"
"40.00000","0.66812","6,764.71289","0.1241","325.9042"
"40.20000","0.67181","6,799.33057","0.1245","327.5720"
"40.40000","0.67525","6,820.26953","0.1248","328.5808"
"40.60000","0.67837","6,839.98633","0.1254","329.5307"
"40.80000","0.68206","6,868.87793","0.1260","330.9226"
"41.00000","0.68500","6,880.80127","0.1263","331.4970"
"41.20000","0.68900","6,914.58643","0.1271","333.1247"
"41.40000","0.69144","6,917.20557","0.1273","333.2509"
"41.60000","0.69519","6,952.61230","0.1279","334.9567"
"41.80000","0.69850","6,970.79395","0.1280","335.8326"
"42.00000","0.70194","6,995.96045","0.1287","337.0451"
"42.20000","0.70525","7,012.57861","0.1292","337.8457"
"42.40000","0.70844","7,034.97168","0.1295","338.9245"
"42.60000","0.71200","7,060.17090","0.1302","340.1385"
"42.80000","0.71475","7,068.93066","0.1305","340.5606"
"43.00000","0.71862","7,106.06152","0.1312","342.3494"
"43.20000","0.72169","7,118.41650","0.1317","342.9446"
"43.40000","0.72550","7,151.29590","0.1323","344.5287"
"43.60000","0.72837","7,156.93066","0.1326","344.8001"
"43.80000","0.73181","7,185.07471","0.1329","346.1561"
"44.00000","0.73531","7,210.78516","0.1336","347.3947"
"44.20000","0.73819","7,222.12354","0.1337","347.9409"
"44.40000","0.74200","7,259.67236","0.1345","349.7499"
"44.60000","0.74500","7,272.30225","0.1350","350.3584"
"44.80000","0.74894","7,305.40771","0.1353","351.9533"
"45.00000","0.75144","7,308.51904","0.1358","352.1032"
"45.20000","0.75512","7,339.74854","0.1363","353.6078"
"45.40000","0.75850","7,360.38818","0.1369","354.6021"
"45.60000","0.76175","7,382.51221","0.1372","355.6680"
"45.80000","0.76531","7,409.36768","0.1379","356.9619"
"46.00000","0.76837","7,425.48389","0.1382","357.7383"
"46.20000","0.77231","7,455.52197","0.1386","359.1854"
"46.40000","0.77469","7,457.67676","0.1389","359.2892"
"46.60000","0.77856","7,494.72168","0.1398","361.0739"
"46.80000","0.78181","7,513.33154","0.1403","361.9705"
"47.00000","0.78525","7,542.06787","0.1409","363.3549"
"47.20000","0.78869","7,561.69482","0.1414","364.3005"
"47.40000","0.79175","7,581.27490","0.1418","365.2438"
"47.60000","0.79525","7,607.34912","0.1422","366.5000"
"47.80000","0.79812","7,619.71240","0.1429","367.0956"
"48.00000","0.80187","7,655.01025","0.1435","368.7962"
"48.20000","0.80500","7,672.57129","0.1435","369.6422"
"48.40000","0.80875","7,706.25342","0.1445","371.2649"
"48.60000","0.81162","7,715.59570","0.1444","371.7150"
"48.80000","0.81512","7,745.62891","0.1452","373.1619"
"49.00000","0.81856","7,769.38623","0.1459","374.3065"
"49.20000","0.82156","7,784.92529","0.1462","375.0551"
"49.40000","0.82537","7,820.28711","0.1470","376.7588"
"49.60000","0.82825","7,832.25098","0.1473","377.3351"
"49.80000","0.83225","7,869.58838","0.1481","379.1339"
"50.00000","0.83487","7,872.04150","0.1482","379.2521"
"50.20000","0.83844","7,904.21045","0.1492","380.8019"
"50.40000","0.84200","7,929.73926","0.1494","382.0318"
"50.60000","0.84500","7,947.44580","0.1498","382.8849"
"50.80000","0.84862","7,977.86328","0.1506","384.3503"
"51.00000","0.85169","7,995.68799","0.1510","385.2090"
"51.20000","0.85556","8,026.73779","0.1517","386.7049"
"51.40000","0.85806","8,032.05225","0.1520","386.9610"
"51.60000","0.86194","8,070.11279","0.1526","388.7946"
"51.80000","0.86512","8,087.99707","0.1529","389.6562"
"52.00000","0.86862","8,117.01562","0.1535","391.0543"
"52.20000","0.87194","8,135.86133","0.1540","391.9622"
"52.40000","0.87506","8,160.67627","0.1547","393.1577"
"52.60000","0.87881","8,188.94873","0.1552","394.5198"
"52.80000","0.88137","8,197.96680","0.1555","394.9543"
"53.00000","0.88525","8,236.38867","0.1562","396.8053"
"53.20000","0.88837","8,253.08594","0.1569","397.6097"
"53.40000","0.89206","8,286.05469","0.1572","399.1981"
"53.60000","0.89500","8,296.55762","0.1576","399.7041"
"53.80000","0.89844","8,326.15820","0.1581","401.1302"
"54.00000","0.90194","8,352.45801","0.1591","402.3972"
"54.20000","0.90487","8,366.22461","0.1590","403.0604"
"54.40000","0.90862","8,402.76465","0.1598","404.8208"
"54.60000","0.91175","8,417.87500","0.1601","405.5488"
"54.80000","0.91562","8,453.56250","0.1612","407.2681"
"55.00000","0.91812","8,457.22266","0.1612","407.4445"
"55.20000","0.92187","8,493.10449","0.1619","409.1731"
"55.40000","0.92525","8,516.79395","0.1626","410.3144"
"55.60000","0.92837","8,536.83008","0.1630","411.2797"
"55.80000","0.93200","8,566.34375","0.1636","412.7016"
"56.00000","0.93500","8,583.64746","0.1640","413.5352"
"56.20000","0.93894","8,617.88965","0.1647","415.1849"
"56.40000","0.94137","8,623.03516","0.1652","415.4328"
"56.60000","0.94519","8,663.32910","0.1659","417.3741"
"56.80000","0.94856","8,684.47168","0.1660","418.3926"
"57.00000","0.95194","8,713.46484","0.1665","419.7895"
"57.20000","0.95525","8,730.91699","0.1673","420.6302"
"57.40000","0.95850","8,758.42578","0.1679","421.9555"
"57.60000","0.96206","8,785.31348","0.1683","423.2509"
"57.80000","0.96469","8,797.40527","0.1691","423.8335"
"58.00000","0.96862","8,838.56055","0.1696","425.8162"
"58.20000","0.97169","8,854.33887","0.1700","426.5764"
"58.40000","0.97550","8,891.50488","0.1707","428.3669"
"58.60000","0.97831","8,899.02344","0.1709","428.7291"
"58.80000","0.98175","8,931.49902","0.1717","430.2937"
"59.00000","0.98531","8,959.15137","0.1722","431.6259"
"59.20000","0.98819","8,974.43848","0.1729","432.3624"
"59.40000","0.99200","9,012.35254","0.1732","434.1890"
"59.60000","0.99506","9,028.90820","0.1737","434.9866"
"59.80000","0.99894","9,063.99219","0.1746","436.6768"
"60.00000","1.00150","9,069.77441","0.1751","436.9554"
"60.20000","1.00519","9,106.36230","0.1756","438.7181"
"60.40000","1.00844","9,127.58008","0.1760","439.7403"
"60.60000","1.01175","9,154.82227","0.1767","441.0528"
"60.80000","1.01531","9,183.79492","0.1772","442.4486"
"61.00000","1.01837","9,204.56836","0.1778","443.4494"
"61.20000","1.02225","9,238.18750","0.1788","445.0691"
"61.40000","1.02469","9,244.44531","0.1790","445.3705"
"61.60000","1.02856","9,283.29102","0.1795","447.2420"
"61.80000","1.03175","9,304.68262","0.1800","448.2726"
"62.00000","1.03525","9,337.66699","0.1807","449.8617"
"62.14600","1.03731","9,340.58301","0.1806","450.0022"
"80.78200","1.03850","9,150.82324","0.1851","440.8601"
"80.98200","1.04144","9,203.16016","0.1964","443.3816"
"81.18200","1.04631","9,331.63574","0.2152","449.5711"
"81.38200","1.04887","9,388.65137","0.2250","452.3180"
"81.58200","1.05256","9,460.91602","0.2392","455.7995"
"81.78200","1.05600","9,503.09668","0.2524","457.8316"
"81.98200","1.05919","9,519.14746","0.2647","458.6049"
"82.18200","1.06269","9,535.34570","0.2781","459.3853"
"82.38200","1.06581","9,550.08594","0.2902","460.0954"
"82.58200","1.06956","9,576.54688","0.3046","461.3702"
"82.78200","1.07212","9,585.09180","0.3144","461.7819"
"82.98200","1.07600","9,622.13965","0.3293","463.5668"
"83.18200","1.07912","9,638.17188","0.3414","464.3392"
"83.38200","1.08275","9,673.75781","0.3553","466.0536"
"83.58200","1.08587","9,686.60938","0.3673","466.6727"
"83.78200","1.08919","9,716.23242","0.3801","468.0999"
"83.98200","1.09294","9,748.10547","0.3945","469.6354"
"84.18200","1.09550","9,756.32227","0.4043","470.0313"
"84.38200","1.09931","9,795.40137","0.4190","471.9140"
"84.58200","1.10244","9,811.90625","0.4310","472.7092"
"84.78200","1.10619","9,848.69531","0.4455","474.4816"
"84.98200","1.10894","9,856.45312","0.4560","474.8553"
"85.18200","1.11256","9,891.72266","0.4700","476.5545"
"85.38200","1.11600","9,919.02246","0.4832","477.8697"
"85.58200","1.11900","9,938.53418","0.4947","478.8098"
"85.78200","1.12269","9,971.50391","0.5089","480.3981"
"85.98200","1.12581","9,990.79395","0.5209","481.3275"
"86.18200","1.12962","10,026.63965","0.5356","483.0544"
"86.38200","1.13212","10,032.11621","0.5452","483.3183"
"86.58200","1.13594","10,070.91016","0.5599","485.1872"
"86.78200","1.13925","10,094.15918","0.5726","486.3073"
"86.98200","1.14256","10,122.53125","0.5854","487.6742"
"87.18200","1.14612","10,149.71777","0.5991","488.9839"
"87.38200","1.14912","10,169.15039","0.6106","489.9202"
"87.58200","1.15294","10,201.90625","0.6253","491.4982"
"87.78200","1.15544","10,211.36230","0.6349","491.9538"
"87.98200","1.15925","10,250.40430","0.6495","493.8347"
"88.18200","1.16256","10,271.30469","0.6623","494.8417"
"88.38200","1.16606","10,302.74805","0.6757","496.3565"
"88.58200","1.16912","10,317.10840","0.6875","497.0483"
"88.78200","1.17250","10,347.78809","0.7005","498.5264"
"88.98200","1.17600","10,376.75586","0.7140","499.9220"
"89.18200","1.17881","10,391.66406","0.7248","500.6402"
"89.38200","1.18262","10,429.36816","0.7394","502.4567"
"89.58200","1.18575","10,447.15430","0.7515","503.3136"
"89.78200","1.18962","10,485.04004","0.7664","505.1388"
"89.98200","1.19225","10,490.40820","0.7765","505.3974"
"90.18200","1.19587","10,527.70996","0.7904","507.1945"
"90.38200","1.19937","10,556.48145","0.8039","508.5807"
"90.58200","1.20231","10,574.98926","0.8152","509.4723"
"90.78200","1.20612","10,610.17480","0.8298","511.1674"
"90.98200","1.20912","10,628.95215","0.8414","512.0721"
"91.18200","1.21300","10,663.89258","0.8563","513.7554"
"91.38200","1.21550","10,670.46191","0.8659","514.0719"
"91.58200","1.21925","10,709.65332","0.8803","515.9600"
"91.78200","1.22256","10,732.68457","0.8931","517.0696"
"91.98200","1.22594","10,763.35645","0.9060","518.5473"
"92.18200","1.22944","10,786.73340","0.9195","519.6735"
"92.38200","1.23244","10,810.87988","0.9310","520.8369"
"92.58200","1.23631","10,844.87891","0.9459","522.4748"
"92.78200","1.23875","10,853.86426","0.9553","522.9077"
"92.98200","1.24262","10,894.50098","0.9702","524.8655"
"93.18200","1.24581","10,915.55469","0.9825","525.8798"
"93.38200","1.24944","10,953.24707","0.9964","527.6957"
"93.58200","1.25256","10,967.53809","1.0084","528.3842"
"93.78200","1.25581","10,997.45312","1.0209","529.8254"
"93.98200","1.25931","11,026.26660","1.0344","531.2136"
"94.18200","1.26225","11,044.08691","1.0457","532.0721"
"94.38200","1.26594","11,082.00879","1.0599","533.8990"
"94.58200","1.26912","11,102.64258","1.0721","534.8931"
"94.78200","1.27294","11,139.63770","1.0868","536.6754"
"94.98200","1.27562","11,147.22461","1.0971","537.0410"
"95.18200","1.27931","11,185.29590","1.1113","538.8751"
"95.38200","1.28256","11,210.64941","1.1238","540.0966"
"95.58200","1.28569","11,233.76172","1.1358","541.2100"
"95.78200","1.28950","11,270.52637","1.1505","542.9813"
"95.98200","1.29237","11,285.42383","1.1616","543.6990"
"96.18200","1.29631","11,322.65137","1.1767","545.4925"
"96.38200","1.29887","11,330.68164","1.1866","545.8794"
"96.58200","1.30250","11,368.25000","1.2005","547.6893"
"96.78200","1.30600","11,395.76855","1.2140","549.0151"
"96.98200","1.30919","11,421.36523","1.2262","550.2482"
"97.18200","1.31275","11,448.59375","1.2399","551.5601"
"97.38200","1.31581","11,471.88281","1.2517","552.6820"
"97.58200","1.31956","11,504.14551","1.2661","554.2363"
"97.78200","1.32212","11,516.18555","1.2760","554.8164"
"97.98200","1.32600","11,556.41699","1.2909","556.7546"
"98.18200","1.32912","11,575.77344","1.3029","557.6872"
"98.38200","1.33275","11,614.38672","1.3168","559.5475"
"98.58200","1.33581","11,628.31543","1.3286","560.2185"
"98.78200","1.33912","11,660.41406","1.3414","561.7649"
"98.98200","1.34294","11,695.11914","1.3560","563.4369"
"99.18200","1.34550","11,705.30273","1.3659","563.9276"
"99.38200","1.34937","11,746.30273","1.3808","565.9028"
"99.58200","1.35250","11,765.49902","1.3928","566.8276"
"99.78200","1.35625","11,803.16602","1.4072","568.6423"
"99.98200","1.35900","11,812.34082","1.4178","569.0843"
"100.18200","1.36256","11,848.29297","1.4315","570.8164"
"100.38200","1.36606","11,877.22070","1.4450","572.2100"
"100.58200","1.36900","11,897.05176","1.4563","573.1655"
"100.78200","1.37269","11,931.42578","1.4705","574.8215"
"100.98200","1.37581","11,952.36719","1.4825","575.8304"
"101.18200","1.37962","11,989.28613","1.4971","577.6090"
"101.38200","1.38212","11,996.29492","1.5068","577.9467"
"101.58200","1.38594","12,037.41895","1.5214","579.9279"
"101.78200","1.38925","12,060.52930","1.5342","581.0413"
"101.98200","1.39250","12,089.61230","1.5467","582.4424"
"102.18200","1.39619","12,119.09082","1.5608","583.8626"
"102.38200","1.39906","12,139.45312","1.5719","584.8436"
"102.58200","1.40294","12,175.01367","1.5868","586.5568"
"102.78200","1.40544","12,185.12598","1.5964","587.0440"
"102.98200","1.40931","12,226.35840","1.6113","589.0305"
"103.18200","1.41256","12,249.20703","1.6238","590.1313"
"103.38200","1.41600","12,283.04395","1.6370","591.7614"
"103.58200","1.41919","12,298.65332","1.6493","592.5134"
"103.78200","1.42250","12,330.96387","1.6620","594.0701"
"103.98200","1.42600","12,361.51562","1.6755","595.5419"
"104.18200","1.42881","12,378.97754","1.6863","596.3832"
"104.38200","1.43256","12,418.44824","1.7007","598.2848"
"104.58200","1.43575","12,436.84570","1.7130","599.1711"
"104.78200","1.43962","12,477.55957","1.7279","601.1326"
"104.98200","1.44225","12,483.25000","1.7380","601.4067"
"105.18200","1.44587","12,521.77637","1.7519","603.2629"
"105.38200","1.44937","12,551.74414","1.7654","604.7066"
"105.58200","1.45231","12,572.44824","1.7767","605.7041"
"105.78200","1.45612","12,610.21777","1.7914","607.5237"
"105.98200","1.45912","12,629.72461","1.8029","608.4635"
"106.18200","1.46300","12,665.35059","1.8178","610.1799"
"106.38200","1.46550","12,672.91504","1.8274","610.5443"
"106.58200","1.46919","12,712.44629","1.8416","612.4488"
"106.78200","1.47256","12,738.45117","1.8546","613.7016"
"106.98200","1.47587","12,770.86133","1.8673","615.2631"
"107.18200","1.47937","12,793.22070","1.8808","616.3403"
"107.38200","1.48244","12,819.45898","1.8926","617.6044"
"107.58200","1.48631","12,854.43457","1.9075","619.2894"
"107.78200","1.48875","12,864.03809","1.9168","619.7520"
"107.98200","1.49269","12,905.85742","1.9320","621.7668"
"108.18200","1.49581","12,926.85547","1.9440","622.7784"
"108.38200","1.49944","12,964.94141","1.9580","624.6133"
"108.58200","1.50262","12,981.04199","1.9702","625.3889"
"108.78200","1.50581","13,010.98438","1.9825","626.8315"
"108.98200","1.50931","13,041.47070","1.9959","628.3002"
"109.18200","1.51219","13,060.64453","2.0070","629.2239"
"109.38200","1.51587","13,099.43945","2.0212","631.0930"
"109.58200","1.51912","13,121.61523","2.0337","632.1614"
"109.78200","1.52287","13,160.86035","2.0481","634.0521"
"109.98200","1.52562","13,169.17871","2.0587","634.4528"
"110.18200","1.52925","13,208.31055","2.0726","636.3381"
"110.38200","1.53262","13,235.26758","2.0856","637.6368"
"110.58200","1.53569","13,259.56738","2.0974","638.8075"
"110.78200","1.53950","13,297.47559","2.1120","640.6338"
"110.98200","1.54244","13,314.57520","2.1233","641.4576"
"111.18200","1.54637","13,354.11328","2.1385","643.3624"
"111.38200","1.54887","13,363.76953","2.1481","643.8276"
"111.58200","1.55256","13,403.20605","2.1623","645.7276"
"111.78200","1.55600","13,430.67285","2.1755","647.0508"
"111.98200","1.55919","13,460.05078","2.1878","648.4662"
"112.18200","1.56262","13,488.23633","2.2010","649.8241"
"112.38200","1.56581","13,515.54883","2.2132","651.1400"
"112.58200","1.56956","13,547.84863","2.2277","652.6960"
"112.78200","1.57212","13,561.59180","2.2375","653.3582"
"112.98200","1.57600","13,603.07520","2.2524","655.3567"
"113.18200","1.57919","13,623.97852","2.2647","656.3638"
"113.38200","1.58281","13,663.23340","2.2786","658.2549"
"113.58200","1.58581","13,677.77539","2.2902","658.9556"
"113.78200","1.58919","13,711.97266","2.3031","660.6031"
"113.98200","1.59300","13,747.37012","2.3178","662.3084"
"114.18200","1.59550","13,758.51953","2.3274","662.8456"
"114.38200","1.59931","13,800.30176","2.3421","664.8585"
"114.58200","1.60244","13,821.22754","2.3541","665.8666"
"114.78200","1.60619","13,858.80859","2.3685","667.6772"
"114.98200","1.60900","13,871.21484","2.3793","668.2749"
"115.18200","1.61256","13,908.86621","2.3931","670.0888"
"115.38200","1.61606","13,940.02734","2.4065","671.5901"
"115.58200","1.61900","13,962.01270","2.4178","672.6493"
"115.78200","1.62269","13,996.99121","2.4320","674.3344"
"115.98200","1.62581","14,019.00684","2.4440","675.3951"
"116.18200","1.62962","14,057.61523","2.4587","677.2551"
"116.38200","1.63212","14,065.83008","2.4683","677.6509"
"116.58200","1.63600","14,108.51953","2.4832","679.7075"
"116.78200","1.63925","14,133.47168","2.4957","680.9097"
"116.98200","1.64250","14,163.79395","2.5082","682.3705"
"117.18200","1.64619","14,193.13672","2.5224","683.7842"
"117.38200","1.64906","14,214.28906","2.5334","684.8032"
"117.58200","1.65294","14,252.14160","2.5483","686.6268"
"117.78200","1.65544","14,263.61816","2.5580","687.1797"
"117.98200","1.65925","14,304.51758","2.5726","689.1501"
"118.18200","1.66262","14,329.53613","2.5856","690.3555"
"118.38200","1.66606","14,363.34375","2.5988","691.9843"
"118.58200","1.66919","14,380.39551","2.6108","692.8057"
"118.78200","1.67250","14,413.08984","2.6236","694.3809"
"118.98200","1.67606","14,444.94922","2.6373","695.9158"
"119.18200","1.67887","14,462.95801","2.6481","696.7834"
"119.38200","1.68256","14,503.08398","2.6623","698.7165"
"119.58200","1.68575","14,524.36719","2.6745","699.7419"
"119.78200","1.68962","14,567.31543","2.6894","701.8110"
"119.98200","1.69219","14,574.16309","2.6993","702.1409"
"120.18200","1.69587","14,614.65332","2.7135","704.0916"
"120.38200","1.69937","14,646.45410","2.7269","705.6237"
"120.58200","1.70231","14,667.27539","2.7382","706.6268"
"120.78200","1.70612","14,704.61523","2.7529","708.4257"
"120.98200","1.70919","14,726.45801","2.7647","709.4780"
"121.18200","1.71300","14,763.42871","2.7793","711.2592"
"121.38200","1.71550","14,771.60352","2.7890","711.6530"
"121.58200","1.71919","14,811.24902","2.8031","713.5630"
"121.78200","1.72262","14,840.65820","2.8164","714.9799"
"121.98200","1.72594","14,872.87305","2.8291","716.5319"
"122.18200","1.72937","14,898.23145","2.8423","717.7535"
"122.38200","1.73244","14,925.63086","2.8541","719.0736"
"122.58200","1.73631","14,962.35449","2.8690","720.8428"
"122.78200","1.73875","14,972.35742","2.8784","721.3248"
"122.98200","1.74262","15,016.38770","2.8933","723.4460"
"123.18200","1.74581","15,038.92871","2.9056","724.5320"
"123.38200","1.74944","15,078.22559","2.9195","726.4252"
"123.58200","1.75256","15,093.82422","2.9315","727.1766"
"123.78200","1.75587","15,126.40137","2.9443","728.7462"
"123.98200","1.75937","15,157.83105","2.9577","730.2603"
"124.18200","1.76219","15,177.29883","2.9685","731.1982"
"124.38200","1.76594","15,216.89844","2.9830","733.1060"
"124.58200","1.76919","15,240.59277","2.9955","734.2476"
"124.78200","1.77294","15,279.09961","3.0099","736.1027"
"124.98200","1.77562","15,288.03711","3.0202","736.5333"
"125.18200","1.77931","15,327.90918","3.0344","738.4542"
"125.38200","1.78262","15,356.31445","3.0471","739.8227"
"125.58200","1.78562","15,380.76953","3.0587","741.0009"
"125.78200","1.78944","15,420.75391","3.0733","742.9272"
"125.98200","1.79244","15,438.43262","3.0849","743.7789"
"126.18200","1.79637","15,478.50977","3.1000","745.7097"
"126.38200","1.79881","15,487.36133","3.1094","746.1361"
"126.58200","1.80262","15,528.32715","3.1241","748.1097"
"126.78200","1.80606","15,556.25977","3.1373","749.4554"
"126.98200","1.80919","15,583.86426","3.1493","750.7853"
"127.18200","1.81269","15,612.52637","3.1628","752.1662"
"127.38200","1.81581","15,639.29199","3.1748","753.4557"
"127.58200","1.81950","15,672.11133","3.1890","755.0369"
"127.78200","1.82212","15,686.43750","3.1991","755.7271"
"127.98200","1.82594","15,727.73340","3.2137","757.7166"
"128.18200","1.82912","15,750.19238","3.2260","758.7986"
"128.38200","1.83275","15,790.63086","3.2399","760.7468"
"128.58200","1.83581","15,804.83887","3.2517","761.4313"
"128.78200","1.83919","15,839.99707","3.2647","763.1251"
"128.98200","1.84300","15,875.97852","3.2793","764.8586"
"129.18200","1.84544","15,886.64453","3.2887","765.3724"
"129.38200","1.84937","15,930.02930","3.3039","767.4626"
"129.58200","1.85244","15,950.57715","3.3156","768.4525"
"129.78200","1.85619","15,990.69434","3.3301","770.3853"
"129.98200","1.85900","16,001.63867","3.3409","770.9125"
"130.18200","1.86256","16,039.09766","3.3546","772.7172"
"130.38200","1.86606","16,070.78027","3.3681","774.2436"
"130.58200","1.86900","16,092.91113","3.3793","775.3098"
"130.78200","1.87262","16,128.33887","3.3933","777.0166"
"130.98200","1.87581","16,153.59375","3.4056","778.2333"
"131.18200","1.87962","16,191.71973","3.4202","780.0701"
"131.38200","1.88212","16,200.62598","3.4298","780.4991"
"131.58200","1.88600","16,243.63770","3.4447","782.5714"
"131.78200","1.88925","16,269.02344","3.4572","783.7944"
"131.98200","1.89256","16,300.46484","3.4700","785.3091"
"132.18200","1.89619","16,329.21289","3.4839","786.6941"
"132.38200","1.89906","16,353.85645","3.4950","787.8813"
"132.58200","1.90300","16,392.23633","3.5101","789.7304"
"132.78200","1.90544","16,402.12305","3.5195","790.2067"
"132.98200","1.90931","16,445.25586","3.5344","792.2847"
"133.18200","1.91262","16,470.60156","3.5471","793.5058"
"133.38200","1.91600","16,504.88086","3.5601","795.1573"
"133.58200","1.91912","16,522.33789","3.5721","795.9983"
"133.78200","1.92250","16,555.24609","3.5851","797.5837"
"133.98200","1.92600","16,587.54102","3.5986","799.1396"
"134.18200","1.92881","16,606.50000","3.6094","800.0530"
"134.38200","1.93256","16,646.04492","3.6238","801.9581"
"134.58200","1.93581","16,667.41016","3.6363","802.9875"
"134.78200","1.93962","16,708.06445","3.6510","804.9460"
"134.98200","1.94219","16,713.91602","3.6608","805.2280"
"135.09600","1.94500","16,388.85742","3.6717","789.5676"
"135.10000","1.94569","15,303.45703","3.6743","737.2762"
"135.10400","1.94650","13,730.62598","3.6774","661.5017"
"135.10800","1.94744","11,895.05664","3.6810","573.0693"
"135.11200","1.94831","9,978.20703","3.6844","480.7211"