File: data/Long/Specimen_RawData_1.csv
Specimen number (included),1
Modulus (Automatic Young's),"242,370.29658",MPa
Length,"26.00000",mm
Specimen ID,"0038"
Thickness,"2.04200",mm
Width,"10.17800",mm
Tensile stress at Tensile strength,"739.33423",MPa
Tensile strain (Strain 1) at Tensile strength,"0.03198",mm/mm

Time,Extension,Load,Tensile strain (Strain 1),Tensile stress
(s),(mm),(N),(%),(MPa)
"0.00000","0.01731","462.86465","-0.0002","22.2708"
"0.20000","0.01931","495.43265","0.0005","23.8378"
"0.40000","0.02400","598.33673","0.0026","28.7891"
"0.60000","0.02744","630.80292","0.0032","30.3512"
"0.80000","0.03050","659.28772","0.0033","31.7217"
"1.00000","0.03431","697.47919","0.0045","33.5593"
"1.20000","0.03681","712.48987","0.0042","34.2816"
"1.40000","0.04075","753.04095","0.0054","36.2327"
"1.60000","0.04375","773.59546","0.0056","37.2217"
"1.80000","0.04756","806.23059","0.0060","38.7919"
"2.00000","0.05056","826.39825","0.0065","39.7623"
"2.20000","0.05394","851.46698","0.0070","40.9685"
"2.40000","0.05750","879.28784","0.0078","42.3071"
"2.60000","0.06025","891.58026","0.0078","42.8985"
"2.80000","0.06412","927.47083","0.0085","44.6254"
"3.00000","0.06706","941.13361","0.0087","45.2828"
"3.20000","0.07106","972.53064","0.0091","46.7935"
"3.40000","0.07362","980.63715","0.0095","47.1835"
"3.60000","0.07731","1,007.28180","0.0099","48.4655"
"3.80000","0.08069","1,030.39905","0.0101","49.5778"
"4.00000","0.08381","1,042.88928","0.0103","50.1788"
"4.20000","0.08750","1,073.31104","0.0110","51.6425"
"4.40000","0.09050","1,083.85913","0.0115","52.1500"
"4.60000","0.09437","1,110.82544","0.0118","53.4475"
"4.80000","0.09681","1,116.23267","0.0118","53.7077"
"5.00000","0.10069","1,142.21765","0.0125","54.9580"
"5.20000","0.10394","1,161.35217","0.0126","55.8786"
"5.40000","0.10731","1,177.59058","0.0128","56.6599"
"5.60000","0.11081","1,199.68420","0.0134","57.7230"
"5.80000","0.11387","1,210.15442","0.0136","58.2268"
"6.00000","0.11762","1,231.90027","0.0139","59.2731"
"6.20000","0.12019","1,235.43311","0.0140","59.4430"
"6.40000","0.12400","1,260.05994","0.0143","60.6280"
"6.60000","0.12725","1,273.42419","0.0149","61.2710"
"6.80000","0.13087","1,291.87158","0.0151","62.1586"
"7.00000","0.13381","1,304.82593","0.0153","62.7819"
"7.20000","0.13725","1,318.83801","0.0153","63.4561"
"7.40000","0.14081","1,337.82275","0.0162","64.3695"
"7.60000","0.14362","1,342.76099","0.0161","64.6071"
"7.80000","0.14744","1,368.29407","0.0166","65.8357"
"8.00000","0.15044","1,375.94556","0.0167","66.2038"
"8.20000","0.15444","1,397.81641","0.0170","67.2561"
"8.40000","0.15694","1,400.77234","0.0172","67.3984"
"8.60000","0.16062","1,417.77112","0.0172","68.2163"
"8.80000","0.16400","1,432.42676","0.0177","68.9214"
"9.00000","0.16712","1,438.29102","0.0177","69.2036"
"9.20000","0.17087","1,462.08130","0.0181","70.3483"
"9.40000","0.17381","1,466.98682","0.0181","70.5843"
"9.60000","0.17769","1,485.51123","0.0183","71.4756"
"9.80000","0.18019","1,487.38049","0.0187","71.5655"
"10.00000","0.18400","1,504.31848","0.0190","72.3805"
"10.20000","0.18725","1,518.51257","0.0192","73.0635"
"10.40000","0.19069","1,529.43433","0.0192","73.5890"
"10.60000","0.19406","1,546.93774","0.0199","74.4311"
"10.80000","0.19719","1,553.41602","0.0199","74.7428"
"11.00000","0.20081","1,568.23755","0.0201","75.4560"
"11.20000","0.20356","1,570.57922","0.0201","75.5686"
"11.40000","0.20737","1,588.10095","0.0206","76.4117"
"11.60000","0.21050","1,598.18286","0.0213","76.8968"
"11.80000","0.21425","1,615.88940","0.0211","77.7488"
"12.00000","0.21725","1,626.57605","0.0215","78.2629"
"12.20000","0.22062","1,637.70764","0.0215","78.7985"
"12.40000","0.22412","1,653.24048","0.0220","79.5459"
"12.60000","0.22700","1,656.42908","0.0221","79.6993"
"12.80000","0.23075","1,679.37927","0.0225","80.8036"
"13.00000","0.23375","1,687.94946","0.0227","81.2159"
"13.20000","0.23769","1,708.11121","0.0227","82.1860"
"13.40000","0.24031","1,712.75916","0.0229","82.4097"
"13.60000","0.24394","1,727.74451","0.0234","83.1307"
"13.80000","0.24731","1,745.06348","0.0238","83.9640"
"14.00000","0.25050","1,751.97571","0.0237","84.2966"
"14.20000","0.25419","1,776.11523","0.0243","85.4580"
"14.40000","0.25712","1,781.27332","0.0245","85.7062"
"14.60000","0.26112","1,802.08044","0.0248","86.7074"
"14.80000","0.26356","1,802.73486","0.0247","86.7389"
"15.00000","0.26731","1,823.34778","0.0253","87.7306"
"15.20000","0.27056","1,837.41040","0.0252","88.4073"
"15.40000","0.27400","1,850.01477","0.0256","89.0137"
"15.60000","0.27744","1,869.14612","0.0258","89.9342"
"15.80000","0.28056","1,877.34192","0.0263","90.3286"
"16.00000","0.28425","1,895.99023","0.0264","91.2258"
"16.20000","0.28681","1,896.63062","0.0267","91.2567"
"16.40000","0.29069","1,921.01746","0.0269","92.4300"
"16.60000","0.29375","1,932.01282","0.0273","92.9591"
"16.80000","0.29756","1,950.48669","0.0276","93.8480"
"17.00000","0.30056","1,962.65796","0.0282","94.4336"
"17.20000","0.30394","1,976.39368","0.0283","95.0945"
"17.40000","0.30750","1,994.57068","0.0285","95.9691"
"17.60000","0.31031","1,998.71899","0.0286","96.1687"
"17.80000","0.31412","2,025.78906","0.0291","97.4711"
"18.00000","0.31706","2,032.76514","0.0295","97.8068"
"18.20000","0.32100","2,056.48779","0.0299","98.9482"
"18.40000","0.32362","2,061.13550","0.0303","99.1718"
"18.60000","0.32731","2,079.35376","0.0307","100.0484"
"18.80000","0.33069","2,096.99292","0.0308","100.8971"
"19.00000","0.33381","2,105.35400","0.0312","101.2994"
"19.20000","0.33744","2,131.15625","0.0316","102.5409"
"19.40000","0.34044","2,136.53516","0.0315","102.7997"
"19.60000","0.34437","2,159.50366","0.0317","103.9048"
"19.80000","0.34687","2,160.40771","0.0319","103.9483"
"20.00000","0.35069","2,180.70703","0.0323","104.9250"
"20.20000","0.35400","2,196.58032","0.0329","105.6888"
"20.40000","0.35737","2,209.23071","0.0329","106.2975"
"20.60000","0.36081","2,228.61792","0.0334","107.2303"
"20.80000","0.36381","2,236.38965","0.0335","107.6042"
"21.00000","0.36762","2,257.66431","0.0338","108.6279"
"21.20000","0.37019","2,260.03784","0.0338","108.7421"
"21.40000","0.37400","2,284.42871","0.0348","109.9156"
"21.60000","0.37719","2,296.75293","0.0349","110.5086"
"21.80000","0.38087","2,315.36694","0.0354","111.4042"
"22.00000","0.38381","2,326.46118","0.0356","111.9380"
"22.20000","0.38725","2,341.54834","0.0357","112.6639"
"22.40000","0.39081","2,360.53882","0.0362","113.5777"
"22.60000","0.39362","2,364.16895","0.0364","113.7523"
"22.80000","0.39744","2,392.33325","0.0370","115.1075"
"23.00000","0.40044","2,400.13037","0.0370","115.4826"
"23.20000","0.40444","2,424.85864","0.0376","116.6724"
"23.40000","0.40694","2,427.55127","0.0378","116.8020"
"23.60000","0.41062","2,450.44092","0.0384","117.9033"
"23.80000","0.41400","2,468.34839","0.0386","118.7649"
"24.00000","0.41712","2,478.01562","0.0388","119.2301"
"24.20000","0.42087","2,505.52417","0.0394","120.5537"
"24.40000","0.42381","2,510.67358","0.0395","120.8014"
"24.60000","0.42769","2,532.64844","0.0400","121.8587"
"24.80000","0.43019","2,532.40649","0.0399","121.8471"
"25.00000","0.43400","2,554.08276","0.0404","122.8901"
"25.20000","0.43725","2,568.86816","0.0404","123.6015"
"25.40000","0.44075","2,583.86914","0.0413","124.3232"
"25.60000","0.44412","2,603.17920","0.0414","125.2523"
"25.80000","0.44725","2,613.10156","0.0413","125.7298"
"26.00000","0.45087","2,633.05420","0.0420","126.6898"
"26.20000","0.45356","2,634.06494","0.0418","126.7384"
"26.40000","0.45731","2,659.20508","0.0425","127.9480"
"26.60000","0.46044","2,671.01562","0.0428","128.5163"
"26.80000","0.46425","2,693.23804","0.0434","129.5855"
"27.00000","0.46725","2,702.23462","0.0437","130.0184"
"27.20000","0.47056","2,717.95190","0.0438","130.7747"
"27.40000","0.47412","2,735.91895","0.0444","131.6391"
"27.60000","0.47700","2,740.48022","0.0445","131.8586"
"27.80000","0.48075","2,769.27563","0.0451","133.2441"
"28.00000","0.48381","2,777.08667","0.0448","133.6199"
"28.20000","0.48775","2,801.65381","0.0459","134.8020"
"28.40000","0.49037","2,803.61450","0.0459","134.8963"
"28.60000","0.49394","2,822.68335","0.0461","135.8138"
"28.80000","0.49731","2,840.10864","0.0466","136.6523"
"29.00000","0.50050","2,850.37134","0.0466","137.1460"
"29.20000","0.50419","2,876.06787","0.0476","138.3824"
"29.40000","0.50712","2,881.69897","0.0474","138.6534"
"29.60000","0.51106","2,905.30103","0.0482","139.7890"
"29.80000","0.51350","2,905.13330","0.0481","139.7809"
"30.00000","0.51737","2,928.85620","0.0488","140.9223"
"30.20000","0.52056","2,940.82788","0.0489","141.4984"
"30.40000","0.52406","2,956.32251","0.0488","142.2439"
"30.60000","0.52744","2,974.10425","0.0495","143.0995"
"30.80000","0.53056","2,983.77466","0.0497","143.5648"
"31.00000","0.53431","3,005.66040","0.0501","144.6178"
"31.20000","0.53687","3,005.33667","0.0502","144.6022"
"31.40000","0.54075","3,032.89062","0.0509","145.9280"
"31.60000","0.54375","3,043.23096","0.0513","146.4255"
"31.80000","0.54750","3,063.29419","0.0516","147.3909"
"32.00000","0.55050","3,075.43726","0.0519","147.9751"
"32.20000","0.55387","3,092.02515","0.0523","148.7732"
"32.40000","0.55750","3,111.62744","0.0525","149.7164"
"32.60000","0.56031","3,115.35547","0.0528","149.8958"
"32.80000","0.56412","3,144.03662","0.0534","151.2758"
"33.00000","0.56712","3,149.61719","0.0535","151.5443"
"33.20000","0.57106","3,172.50195","0.0541","152.6454"
"33.40000","0.57362","3,173.34839","0.0540","152.6861"
"33.60000","0.57731","3,193.78784","0.0543","153.6696"
"33.80000","0.58062","3,210.40820","0.0549","154.4693"
"34.00000","0.58381","3,219.36450","0.0554","154.9002"
"34.20000","0.58750","3,245.35327","0.0555","156.1507"
"34.40000","0.59044","3,248.70679","0.0557","156.3120"
"34.60000","0.59437","3,272.31323","0.0562","157.4478"
"34.80000","0.59681","3,271.72461","0.0559","157.4195"
"35.00000","0.60069","3,293.85742","0.0569","158.4844"
"35.20000","0.60394","3,309.16943","0.0570","159.2212"
"35.40000","0.60737","3,320.95654","0.0575","159.7883"
"35.60000","0.61081","3,339.19971","0.0578","160.6661"
"35.80000","0.61381","3,346.98486","0.0579","161.0407"
"36.00000","0.61762","3,366.26660","0.0583","161.9684"
"36.20000","0.62019","3,365.65894","0.0582","161.9392"
"36.40000","0.62400","3,390.59692","0.0592","163.1391"
"36.60000","0.62719","3,399.64551","0.0590","163.5744"
"36.80000","0.63087","3,418.57031","0.0595","164.4850"
"37.00000","0.63381","3,426.47363","0.0596","164.8653"
"37.20000","0.63725","3,441.42163","0.0599","165.5845"
"37.40000","0.64075","3,458.05933","0.0601","166.3850"
"37.60000","0.64362","3,460.85693","0.0602","166.5196"
"37.80000","0.64744","3,488.33154","0.0608","167.8416"
"38.00000","0.65044","3,493.15625","0.0609","168.0737"
"38.20000","0.65444","3,515.24902","0.0614","169.1367"
"38.40000","0.65694","3,513.04663","0.0615","169.0308"
"38.60000","0.66062","3,531.53174","0.0619","169.9202"
"38.80000","0.66406","3,546.84106","0.0619","170.6568"
"39.00000","0.66712","3,554.36914","0.0623","171.0190"
"39.20000","0.67087","3,579.31470","0.0628","172.2193"
"39.40000","0.67381","3,583.56543","0.0629","172.4238"
"39.60000","0.67769","3,604.76855","0.0634","173.4440"
"39.80000","0.68019","3,603.43945","0.0634","173.3800"
"40.00000","0.68400","3,627.94214","0.0639","174.5590"
"40.20000","0.68725","3,640.86060","0.0642","175.1805"
"40.40000","0.69069","3,653.11646","0.0646","175.7702"
"40.60000","0.69406","3,668.89355","0.0650","176.5294"
"40.80000","0.69725","3,679.18799","0.0651","177.0247"
"41.00000","0.70094","3,696.25024","0.0653","177.8456"
"41.20000","0.70350","3,697.42700","0.0654","177.9022"
"41.40000","0.70737","3,722.52246","0.0659","179.1097"
"41.60000","0.71050","3,730.53784","0.0661","179.4954"
"41.80000","0.71425","3,752.97412","0.0667","180.5749"
"42.00000","0.71725","3,761.22705","0.0669","180.9720"
"42.20000","0.72056","3,776.96191","0.0673","181.7291"
"42.40000","0.72406","3,795.28589","0.0677","182.6107"
"42.60000","0.72700","3,798.89209","0.0678","182.7843"
"42.80000","0.73069","3,826.43970","0.0683","184.1097"
"43.00000","0.73381","3,832.81177","0.0683","184.4163"
"43.20000","0.73775","3,856.31812","0.0688","185.5473"
"43.40000","0.74031","3,855.83203","0.0687","185.5239"
"43.60000","0.74400","3,876.05664","0.0694","186.4970"
"43.80000","0.74731","3,892.84790","0.0695","187.3049"
"44.00000","0.75050","3,903.74634","0.0697","187.8293"
"44.20000","0.75419","3,929.36182","0.0704","189.0618"
"44.40000","0.75712","3,934.29248","0.0706","189.2991"
"44.60000","0.76106","3,958.22290","0.0710","190.4505"
"44.80000","0.76356","3,956.87622","0.0711","190.3857"
"45.00000","0.76731","3,981.17188","0.0717","191.5547"
"45.20000","0.77056","3,994.76392","0.0720","192.2086"
"45.40000","0.77400","4,010.65308","0.0717","192.9732"
"45.60000","0.77737","4,027.41357","0.0724","193.7796"
"45.80000","0.78050","4,039.48730","0.0728","194.3605"
"46.00000","0.78425","4,060.63208","0.0731","195.3779"
"46.20000","0.78687","4,060.98340","0.0732","195.3948"
"46.40000","0.79069","4,088.85059","0.0738","196.7356"
"46.60000","0.79381","4,098.55078","0.0739","197.2024"
"46.80000","0.79756","4,119.94189","0.0746","198.2316"
"47.00000","0.80056","4,129.48389","0.0748","198.6907"
"47.20000","0.80394","4,145.11914","0.0751","199.4430"
"47.40000","0.80750","4,163.29541","0.0758","200.3176"
"47.60000","0.81031","4,167.94629","0.0759","200.5414"
"47.80000","0.81412","4,197.82568","0.0764","201.9790"
"48.00000","0.81706","4,203.05469","0.0763","202.2306"
"48.20000","0.82094","4,229.32324","0.0769","203.4945"
"48.40000","0.82362","4,230.37500","0.0769","203.5451"
"48.60000","0.82731","4,252.68066","0.0778","204.6184"
"48.80000","0.83069","4,269.73389","0.0777","205.4389"
"49.00000","0.83381","4,276.57764","0.0781","205.7682"
"49.20000","0.83750","4,302.11670","0.0787","206.9970"
"49.40000","0.84050","4,307.86182","0.0788","207.2734"
"49.60000","0.84437","4,331.21582","0.0792","208.3971"
"49.80000","0.84687","4,330.29688","0.0791","208.3529"
"50.00000","0.85069","4,355.14062","0.0799","209.5482"
"50.20000","0.85400","4,369.93896","0.0804","210.2603"
"50.40000","0.85737","4,385.03613","0.0805","210.9867"
"50.60000","0.86075","4,402.61035","0.0809","211.8322"
"50.80000","0.86381","4,414.51611","0.0810","212.4051"
"51.00000","0.86756","4,435.38818","0.0818","213.4093"
"51.20000","0.87019","4,437.82715","0.0822","213.5267"
"51.40000","0.87400","4,467.81689","0.0825","214.9697"
"51.60000","0.87725","4,480.35986","0.0828","215.5732"
"51.80000","0.88087","4,502.11084","0.0831","216.6197"
"52.00000","0.88381","4,509.33301","0.0836","216.9672"
"52.20000","0.88725","4,528.11572","0.0839","217.8710"
"52.40000","0.89081","4,549.23682","0.0843","218.8872"
"52.60000","0.89362","4,553.71240","0.0844","219.1025"
"52.80000","0.89744","4,584.22998","0.0850","220.5709"
"53.00000","0.90044","4,592.68799","0.0853","220.9779"
"53.20000","0.90444","4,620.57275","0.0857","222.3195"
"53.40000","0.90687","4,621.18213","0.0858","222.3489"
"53.60000","0.91062","4,647.62891","0.0864","223.6214"
"53.80000","0.91400","4,664.74805","0.0867","224.4450"
"54.00000","0.91712","4,677.46240","0.0872","225.0568"
"54.20000","0.92087","4,706.06104","0.0877","226.4328"
"54.40000","0.92387","4,713.94336","0.0876","226.8121"
"54.60000","0.92775","4,739.08838","0.0884","228.0219"
"54.80000","0.93019","4,739.56982","0.0886","228.0451"
"55.00000","0.93400","4,767.10596","0.0889","229.3700"
"55.20000","0.93731","4,783.22363","0.0894","230.1455"
"55.40000","0.94069","4,801.98486","0.0898","231.0482"
"55.60000","0.94406","4,819.77002","0.0903","231.9039"
"55.80000","0.94725","4,837.43896","0.0904","232.7541"
"56.00000","0.95081","4,857.33594","0.0910","233.7114"
"56.20000","0.95350","4,863.08691","0.0912","233.9881"
"56.40000","0.95737","4,894.85693","0.0917","235.5168"
"56.60000","0.96044","4,906.56689","0.0921","236.0802"
"56.80000","0.96425","4,934.98682","0.0929","237.4476"
"57.00000","0.96725","4,942.11035","0.0928","237.7904"
"57.20000","0.97062","4,962.64160","0.0936","238.7782"
"57.40000","0.97412","4,983.69043","0.0938","239.7910"
"57.60000","0.97700","4,989.72852","0.0940","240.0815"
"57.80000","0.98069","5,021.07227","0.0947","241.5896"
"58.00000","0.98381","5,031.69336","0.0947","242.1007"
"58.20000","0.98769","5,060.62744","0.0955","243.4928"
"58.40000","0.99037","5,063.69092","0.0958","243.6402"
"58.60000","0.99394","5,089.10449","0.0964","244.8630"
"58.80000","0.99725","5,108.44678","0.0965","245.7937"
"59.00000","1.00050","5,123.60156","0.0971","246.5228"
"59.20000","1.00406","5,149.40088","0.0975","247.7642"
"59.40000","1.00712","5,161.31201","0.0981","248.3373"
"59.60000","1.01112","5,189.60938","0.0985","249.6988"
"59.80000","1.01350","5,189.56592","0.0986","249.6967"
"60.00000","1.01737","5,220.88672","0.0992","251.2037"
"60.20000","1.02056","5,236.02393","0.0996","251.9321"
"60.40000","1.02400","5,257.46924","0.1000","252.9639"
"60.60000","1.02744","5,275.18506","0.1006","253.8163"
"60.80000","1.03050","5,289.92773","0.1008","254.5257"
"61.00000","1.03431","5,316.11963","0.1015","255.7859"
"61.20000","1.03687","5,318.64746","0.1016","255.9075"
"61.40000","1.04062","5,349.37939","0.1021","257.3862"
"61.60000","1.04375","5,361.32617","0.1025","257.9610"
"61.80000","1.04750","5,387.72412","0.1032","259.2311"
"62.00000","1.05050","5,397.59717","0.1034","259.7062"
"62.20000","1.05387","5,420.73975","0.1038","260.8197"
"62.40000","1.05744","5,442.18066","0.1043","261.8513"
"62.60000","1.06031","5,450.36621","0.1046","262.2452"
"62.80000","1.06412","5,482.13770","0.1053","263.7739"
"63.00000","1.06712","5,491.52588","0.1052","264.2256"
"63.20000","1.07100","5,521.94922","0.1061","265.6894"
"63.40000","1.07362","5,523.81006","0.1062","265.7789"
"63.60000","1.07731","5,553.09033","0.1068","267.1877"
"63.80000","1.08069","5,572.03613","0.1069","268.0993"
"64.00000","1.08375","5,584.28857","0.1076","268.6889"
"64.20000","1.08744","5,613.38477","0.1079","270.0888"
"64.40000","1.09050","5,623.67676","0.1083","270.5840"
"64.60000","1.09431","5,650.20312","0.1090","271.8604"
"64.80000","1.09681","5,653.46045","0.1091","272.0171"
"65.00000","1.10069","5,684.70410","0.1097","273.5204"
"65.20000","1.10400","5,702.03174","0.1101","274.3541"
"65.40000","1.10737","5,724.39990","0.1106","275.4304"
"65.60000","1.11075","5,743.55322","0.1111","276.3519"
"65.80000","1.11387","5,760.50049","0.1115","277.1673"
"66.00000","1.11762","5,785.52051","0.1117","278.3712"
"66.20000","1.12019","5,789.31738","0.1121","278.5539"
"66.40000","1.12406","5,822.91504","0.1127","280.1704"
"66.60000","1.12725","5,836.07959","0.1132","280.8038"
"66.80000","1.13087","5,862.54639","0.1136","282.0773"
"67.00000","1.13381","5,872.13086","0.1141","282.5385"
"67.20000","1.13719","5,895.01953","0.1145","283.6397"
"67.40000","1.14075","5,918.95410","0.1152","284.7914"
"67.60000","1.14369","5,928.32471","0.1153","285.2422"
"67.80000","1.14744","5,960.58008","0.1158","286.7942"
"68.00000","1.15050","5,971.11621","0.1162","287.3011"
"68.20000","1.15444","6,002.38672","0.1170","288.8057"
"68.40000","1.15687","6,003.24609","0.1170","288.8471"
"68.60000","1.16062","6,034.14014","0.1174","290.3335"
"68.80000","1.16400","6,053.09277","0.1182","291.2455"
"69.00000","1.16712","6,069.97705","0.1186","292.0578"
"69.20000","1.17094","6,099.94775","0.1192","293.4999"
"69.40000","1.17381","6,109.56787","0.1195","293.9628"
"69.60000","1.17769","6,138.30957","0.1205","295.3457"
"69.80000","1.18019","6,143.14648","0.1203","295.5784"
"70.00000","1.18400","6,174.22021","0.1208","297.0735"
"70.20000","1.18725","6,192.04980","0.1212","297.9314"
"70.40000","1.19069","6,214.90771","0.1218","299.0312"
"70.60000","1.19406","6,232.80225","0.1223","299.8922"
"70.80000","1.19725","6,253.31348","0.1226","300.8791"
"71.00000","1.20087","6,277.02100","0.1231","302.0198"
"71.20000","1.20350","6,286.11230","0.1236","302.4572"
"71.40000","1.20737","6,321.56201","0.1242","304.1629"
"71.60000","1.21050","6,335.18408","0.1247","304.8183"
"71.80000","1.21425","6,366.80029","0.1255","306.3395"
"72.00000","1.21719","6,374.83984","0.1253","306.7263"
"72.20000","1.22056","6,398.25439","0.1259","307.8530"
"72.40000","1.22412","6,424.34961","0.1265","309.1085"
"72.60000","1.22694","6,434.94727","0.1269","309.6184"
"72.80000","1.23069","6,468.57227","0.1276","311.2363"
"73.00000","1.23387","6,481.66309","0.1275","311.8662"
"73.20000","1.23775","6,512.29150","0.1284","313.3399"
"73.40000","1.24037","6,515.81201","0.1286","313.5092"
"73.60000","1.24394","6,544.47754","0.1291","314.8885"
"73.80000","1.24731","6,566.34570","0.1298","315.9407"
"74.00000","1.25050","6,585.37842","0.1302","316.8564"
"74.20000","1.25412","6,612.82861","0.1307","318.1772"
"74.40000","1.25712","6,626.75781","0.1311","318.8474"
"74.60000","1.26112","6,658.44775","0.1316","320.3722"
"74.80000","1.26350","6,660.31152","0.1318","320.4619"
"75.00000","1.26731","6,694.10400","0.1325","322.0878"
"75.20000","1.27062","6,712.28320","0.1331","322.9625"
"75.40000","1.27400","6,737.59521","0.1334","324.1804"
"75.60000","1.27744","6,756.08350","0.1341","325.0699"
"75.80000","1.28050","6,774.52441","0.1345","325.9572"
"76.00000","1.28431","6,802.02539","0.1350","327.2805"
"76.20000","1.28687","6,808.68799","0.1352","327.6010"
"76.40000","1.29069","6,842.48877","0.1358","329.2274"
"76.60000","1.29381","6,857.03613","0.1363","329.9273"
"76.80000","1.29750","6,887.35840","0.1369","331.3863"
"77.00000","1.30050","6,896.81006","0.1370","331.8410"
"77.20000","1.30387","6,922.48730","0.1379","333.0765"
"77.40000","1.30750","6,947.01953","0.1383","334.2569"
"77.60000","1.31025","6,957.55127","0.1387","334.7636"
"77.80000","1.31412","6,992.35938","0.1395","336.4384"
"78.00000","1.31706","7,003.69043","0.1397","336.9836"
"78.20000","1.32100","7,037.69385","0.1405","338.6197"
"78.40000","1.32362","7,041.03027","0.1404","338.7802"
"78.60000","1.32731","7,073.35010","0.1412","340.3353"
"78.80000","1.33075","7,095.36084","0.1416","341.3943"
"79.00000","1.33381","7,110.40332","0.1422","342.1181"
"79.20000","1.33750","7,140.84961","0.1427","343.5830"
"79.40000","1.34050","7,155.76855","0.1433","344.3008"
"79.60000","1.34431","7,185.30566","0.1436","345.7220"
"79.80000","1.34681","7,188.95215","0.1438","345.8975"
"80.00000","1.35069","7,223.22754","0.1445","347.5467"
"80.20000","1.35400","7,240.09717","0.1450","348.3583"
"80.40000","1.35737","7,265.27344","0.1457","349.5697"
"80.60000","1.36075","7,284.40430","0.1462","350.4902"
"80.80000","1.36381","7,304.08301","0.1465","351.4370"
"81.00000","1.36762","7,332.70361","0.1472","352.8141"
"81.20000","1.37019","7,338.96484","0.1473","353.1154"
"81.40000","1.37406","7,375.49902","0.1481","354.8732"
"81.60000","1.37725","7,391.61963","0.1486","355.6489"
"81.80000","1.38087","7,422.03516","0.1490","357.1123"
"82.00000","1.38387","7,431.62207","0.1492","357.5736"
"82.20000","1.38719","7,458.19971","0.1499","358.8524"
"82.40000","1.39081","7,484.89746","0.1506","360.1369"
"82.60000","1.39369","7,495.21045","0.1504","360.6331"
"82.80000","1.39744","7,528.21338","0.1509","362.2211"
"83.00000","1.40050","7,541.72559","0.1517","362.8712"
"83.20000","1.40437","7,574.67920","0.1523","364.4568"
"83.40000","1.40687","7,576.77490","0.1523","364.5576"
"83.60000","1.41062","7,612.33936","0.1533","366.2688"
"83.80000","1.41400","7,633.83594","0.1536","367.3031"
"84.00000","1.41712","7,652.87646","0.1540","368.2193"
"84.20000","1.42094","7,683.63623","0.1551","369.6993"
"84.40000","1.42381","7,696.48193","0.1553","370.3174"
"84.60000","1.42769","7,726.55811","0.1556","371.7645"
"84.80000","1.43025","7,733.32324","0.1559","372.0900"
"85.00000","1.43400","7,767.93945","0.1565","373.7556"
"85.20000","1.43731","7,788.73193","0.1574","374.7560"
"85.40000","1.44069","7,813.87744","0.1578","375.9659"
"85.60000","1.44406","7,832.96289","0.1582","376.8842"
"85.80000","1.44725","7,856.64697","0.1587","378.0237"
"86.00000","1.45081","7,881.42627","0.1590","379.2160"
"86.20000","1.45350","7,891.78662","0.1595","379.7145"
"86.40000","1.45737","7,927.90283","0.1602","381.4522"
"86.60000","1.46050","7,943.70166","0.1606","382.2124"
"86.80000","1.46425","7,977.88184","0.1612","383.8570"
"87.00000","1.46719","7,985.97168","0.1617","384.2462"
"87.20000","1.47056","8,014.59326","0.1624","385.6233"
"87.40000","1.47419","8,041.40576","0.1629","386.9134"
"87.60000","1.47694","8,053.97705","0.1632","387.5183"
"87.80000","1.48069","8,089.09375","0.1639","389.2079"
"88.00000","1.48387","8,106.06494","0.1643","390.0245"
"88.20000","1.48769","8,137.93408","0.1650","391.5579"
"88.40000","1.49037","8,144.95361","0.1651","391.8956"
"88.60000","1.49394","8,176.89844","0.1657","393.4327"
"88.80000","1.49731","8,199.74121","0.1661","394.5318"
"89.00000","1.50050","8,221.52930","0.1669","395.5801"
"89.20000","1.50412","8,249.00391","0.1675","396.9020"
"89.40000","1.50712","8,266.65820","0.1676","397.7515"
"89.60000","1.51112","8,300.53711","0.1686","399.3816"
"89.80000","1.51350","8,303.27246","0.1687","399.5132"
"90.00000","1.51737","8,340.41797","0.1696","401.3004"
"90.20000","1.52062","8,360.57520","0.1702","402.2703"
"90.40000","1.52400","8,388.02051","0.1707","403.5909"
"90.60000","1.52744","8,409.79980","0.1711","404.6388"
"90.80000","1.53050","8,431.80176","0.1717","405.6974"
"91.00000","1.53425","8,461.93945","0.1721","407.1475"
"91.20000","1.53687","8,471.51172","0.1726","407.6080"
"91.40000","1.54062","8,507.87305","0.1734","409.3576"
"91.60000","1.54381","8,525.12598","0.1736","410.1877"
"91.80000","1.54750","8,557.98242","0.1743","411.7686"
"92.00000","1.55050","8,569.79297","0.1749","412.3369"
"92.20000","1.55394","8,600.52051","0.1753","413.8153"
"92.40000","1.55744","8,626.33398","0.1760","415.0573"
"92.60000","1.56031","8,641.27246","0.1764","415.7761"
"92.80000","1.56412","8,677.76660","0.1770","417.5320"
"93.00000","1.56706","8,690.74219","0.1774","418.1563"
"93.20000","1.57100","8,728.39355","0.1780","419.9679"
"93.40000","1.57362","8,732.37891","0.1783","420.1597"
"93.60000","1.57731","8,768.12012","0.1789","421.8794"
"93.80000","1.58069","8,792.21094","0.1795","423.0385"
"94.00000","1.58375","8,811.51074","0.1802","423.9671"
"94.20000","1.58750","8,842.53125","0.1807","425.4597"
"94.40000","1.59056","8,859.62891","0.1812","426.2823"
"94.60000","1.59437","8,891.45312","0.1817","427.8136"
"94.80000","1.59687","8,897.15527","0.1819","428.0879"
"95.00000","1.60069","8,934.72461","0.1826","429.8956"
"95.20000","1.60406","8,956.39062","0.1832","430.9380"
"95.40000","1.60737","8,982.93066","0.1840","432.2150"
"95.60000","1.61075","9,001.94336","0.1842","433.1298"
"95.80000","1.61387","9,025.54590","0.1846","434.2655"
"96.00000","1.61762","9,054.76465","0.1856","435.6713"
"96.20000","1.62019","9,064.46387","0.1858","436.1380"
"96.40000","1.62400","9,101.94238","0.1868","437.9413"
"96.60000","1.62725","9,120.90625","0.1870","438.8538"
"96.80000","1.63087","9,152.37500","0.1876","440.3679"
"97.00000","1.63387","9,162.58398","0.1878","440.8591"
"97.20000","1.63719","9,191.02539","0.1887","442.2275"
"97.40000","1.64087","9,219.92676","0.1894","443.6181"
"97.60000","1.64362","9,231.92676","0.1898","444.1955"
"97.80000","1.64744","9,266.71289","0.1902","445.8693"
"98.00000","1.65050","9,282.45020","0.1907","446.6265"
"98.20000","1.65437","9,318.81641","0.1914","448.3762"
"98.40000","1.65687","9,321.11816","0.1919","448.4870"
"98.51400","1.65937","9,352.72949","0.1924","450.0080"
"117.80800","1.65987","9,124.36328","0.1944","439.0201"
"118.00800","1.66319","9,185.65723","0.2071","441.9692"
"118.20800","1.66719","9,299.16992","0.2225","447.4309"
"118.40800","1.67100","9,375.05176","0.2371","451.0820"
"118.60800","1.67394","9,430.90430","0.2484","453.7693"
"118.80800","1.67781","9,490.42871","0.2633","456.6334"
"119.00800","1.68031","9,500.09375","0.2730","457.0984"
"119.20800","1.68406","9,528.37988","0.2874","458.4594"
"119.40800","1.68750","9,541.74316","0.3006","459.1024"
"119.60800","1.69075","9,561.15820","0.3131","460.0365"
"119.80800","1.69419","9,580.25488","0.3263","460.9554"
"120.00800","1.69737","9,602.53125","0.3386","462.0272"
"120.20800","1.70100","9,627.98438","0.3525","463.2519"
"120.40800","1.70362","9,638.41992","0.3626","463.7540"
"120.60800","1.70744","9,674.88770","0.3773","465.5086"
"120.80800","1.71062","9,693.16992","0.3895","466.3883"
"121.00800","1.71431","9,728.92285","0.4037","468.1086"
"121.20800","1.71731","9,739.10742","0.4153","468.5986"
"121.40800","1.72069","9,768.80176","0.4282","470.0273"
"121.60800","1.72431","9,797.35449","0.4422","471.4012"
"121.80800","1.72706","9,809.91602","0.4528","472.0056"
"122.00800","1.73081","9,846.59375","0.4672","473.7703"
"122.20800","1.73394","9,864.48633","0.4792","474.6312"
"122.40800","1.73775","9,898.33887","0.4939","476.2600"
"122.60800","1.74050","9,905.97070","0.5044","476.6272"
"122.80800","1.74400","9,938.27637","0.5179","478.1816"
"123.00800","1.74744","9,963.83887","0.5311","479.4116"
"123.20800","1.75056","9,986.28320","0.5431","480.4915"
"123.40800","1.75419","10,016.37500","0.5571","481.9394"
"123.60800","1.75719","10,035.19336","0.5686","482.8448"
"123.80800","1.76112","10,070.46973","0.5838","484.5421"
"124.00800","1.76362","10,074.46777","0.5934","484.7345"
"124.20800","1.76744","10,112.67676","0.6081","486.5729"
"124.40800","1.77069","10,133.48926","0.6206","487.5743"
"124.60800","1.77406","10,162.61328","0.6335","488.9756"
"124.80800","1.77762","10,186.07617","0.6472","490.1046"
"125.00800","1.78062","10,206.20605","0.6588","491.0731"
"125.20800","1.78444","10,239.05176","0.6734","492.6535"
"125.40800","1.78694","10,247.75391","0.6831","493.0722"
"125.60800","1.79075","10,285.50977","0.6977","494.8888"
"125.80800","1.79394","10,304.18262","0.7100","495.7873"
"126.00800","1.79750","10,336.98730","0.7237","497.3657"
"126.20800","1.80062","10,351.65332","0.7357","498.0713"
"126.40800","1.80400","10,382.31543","0.7487","499.5466"
"126.60800","1.80756","10,408.75586","0.7624","500.8188"
"126.80800","1.81031","10,423.17871","0.7730","501.5128"
"127.00800","1.81425","10,460.67383","0.7881","503.3169"
"127.20800","1.81719","10,475.24023","0.7994","504.0177"
"127.40800","1.82112","10,513.63086","0.8145","505.8649"
"127.60800","1.82375","10,517.89258","0.8246","506.0699"
"127.80800","1.82737","10,554.31641","0.8386","507.8225"
"128.00800","1.83087","10,580.61914","0.8520","509.0880"
"128.20800","1.83381","10,599.31934","0.8633","509.9878"
"128.40800","1.83756","10,633.11719","0.8778","511.6140"
"128.60800","1.84062","10,650.55469","0.8895","512.4530"
"128.80800","1.84444","10,684.22168","0.9042","514.0729"
"129.00800","1.84694","10,692.21387","0.9138","514.4575"
"129.20800","1.85075","10,730.04883","0.9285","516.2779"
"129.40800","1.85419","10,754.70703","0.9417","517.4643"
"129.60800","1.85744","10,780.47266","0.9542","518.7040"
"129.80800","1.86087","10,802.30664","0.9674","519.7546"
"130.00800","1.86394","10,827.50586","0.9792","520.9670"
"130.20800","1.86781","10,859.77832","0.9941","522.5198"
"130.40800","1.87025","10,868.68750","1.0035","522.9485"
"130.60800","1.87419","10,907.74805","1.0186","524.8279"
"130.80800","1.87737","10,927.17871","1.0309","525.7628"
"131.00800","1.88094","10,961.25684","1.0446","527.4025"
"131.20800","1.88400","10,973.95801","1.0564","528.0136"
"131.40800","1.88725","11,002.78320","1.0689","529.4005"
"131.60800","1.89100","11,035.13086","1.0833","530.9570"
"131.80800","1.89369","11,047.72949","1.0936","531.5631"
"132.00800","1.89750","11,083.93457","1.1083","533.3051"
"132.20800","1.90062","11,101.85059","1.1203","534.1672"
"132.40800","1.90444","11,139.21582","1.1350","535.9650"
"132.60800","1.90700","11,145.25195","1.1448","536.2554"
"132.80800","1.91075","11,183.63770","1.1593","538.1024"
"133.00800","1.91412","11,208.44824","1.1722","539.2961"
"133.20800","1.91719","11,231.38477","1.1840","540.3997"
"133.40800","1.92100","11,266.15820","1.1987","542.0729"
"133.60800","1.92394","11,282.98438","1.2100","542.8824"
"133.80800","1.92781","11,318.31738","1.2249","544.5825"
"134.00800","1.93031","11,326.61816","1.2345","544.9819"
"134.20800","1.93406","11,365.46680","1.2489","546.8511"
"134.40800","1.93744","11,389.56250","1.2619","548.0105"
"134.60800","1.94075","11,417.41016","1.2746","549.3503"
"134.80800","1.94419","11,440.21191","1.2879","550.4475"
"135.00800","1.94737","11,467.43262","1.3001","551.7572"
"135.20800","1.95094","11,493.67578","1.3138","553.0199"
"135.40800","1.95362","11,508.91895","1.3242","553.7534"
"135.60800","1.95744","11,546.87500","1.3388","555.5796"
"135.80800","1.96062","11,566.78125","1.3511","556.5374"
"136.00800","1.96431","11,605.10449","1.3653","558.3813"
"136.20800","1.96737","11,616.57227","1.3770","558.9331"
"136.40800","1.97069","11,647.11230","1.3898","560.4025"
"136.60800","1.97431","11,678.29883","1.4037","561.9031"
"136.80800","1.97700","11,691.85742","1.4141","562.5554"
"137.00800","1.98081","11,729.82812","1.4287","564.3824"
"137.20800","1.98394","11,749.22559","1.4407","565.3157"
"137.40800","1.98775","11,785.94336","1.4554","567.0824"
"137.60800","1.99050","11,794.13379","1.4660","567.4765"
"137.80800","1.99400","11,826.82715","1.4794","569.0495"
"138.00800","1.99744","11,855.28418","1.4927","570.4188"
"138.20800","2.00056","11,878.93945","1.5047","571.5569"
"138.40800","2.00419","11,909.04199","1.5186","573.0053"
"138.60800","2.00725","11,929.60547","1.5304","573.9948"
"138.80800","2.01119","11,966.30859","1.5456","575.7607"
"139.00800","2.01362","11,970.53906","1.5549","575.9642"
"139.20800","2.01744","12,010.78125","1.5696","577.9005"
"139.40800","2.02069","12,032.81543","1.5821","578.9607"
"139.60800","2.02406","12,064.08887","1.5951","580.4654"
"139.80800","2.02762","12,088.23828","1.6088","581.6274"
"140.00800","2.03056","12,110.93750","1.6201","582.7195"
"140.20800","2.03444","12,145.21973","1.6350","584.3690"
"140.40800","2.03694","12,154.40137","1.6446","584.8108"
"140.60800","2.04075","12,193.98926","1.6593","586.7156"
"140.80800","2.04394","12,213.33105","1.6715","587.6462"
"141.00800","2.04750","12,248.08984","1.6852","589.3187"
"141.20800","2.05069","12,262.93945","1.6975","590.0331"
"141.40800","2.05400","12,294.84863","1.7102","591.5685"
"141.60800","2.05756","12,323.15918","1.7239","592.9306"
"141.80800","2.06037","12,339.23047","1.7347","593.7039"
"142.00800","2.06419","12,377.15137","1.7494","595.5284"
"142.20800","2.06719","12,393.41797","1.7609","596.3112"
"142.40800","2.07106","12,433.23340","1.7758","598.2269"
"142.60800","2.07375","12,439.39062","1.7862","598.5231"
"142.80800","2.07737","12,476.83105","1.8001","600.3246"
"143.00800","2.08087","12,504.06934","1.8136","601.6351"
"143.20800","2.08381","12,524.22754","1.8249","602.6050"
"143.40800","2.08756","12,558.44727","1.8393","604.2515"
"143.60800","2.09062","12,577.26855","1.8511","605.1571"
"143.80800","2.09444","12,612.30664","1.8657","606.8430"
"144.00800","2.09694","12,619.54590","1.8754","607.1913"
"144.20800","2.10075","12,656.75391","1.8900","608.9816"
"144.40800","2.10425","12,683.09766","1.9035","610.2491"
"144.60800","2.10744","12,708.91016","1.9157","611.4911"
"144.80800","2.11081","12,731.34375","1.9287","612.5705"
"145.00800","2.11394","12,757.15723","1.9407","613.8125"
"145.20800","2.11775","12,789.64551","1.9554","615.3757"
"145.40800","2.12025","12,800.19434","1.9650","615.8832"
"145.60800","2.12412","12,840.12012","1.9799","617.8043"
"145.80800","2.12731","12,860.70898","1.9922","618.7949"
"146.00800","2.13094","12,895.60352","2.0061","620.4739"
"146.20800","2.13400","12,908.64160","2.0179","621.1012"
"146.40800","2.13725","12,939.03027","2.0304","622.5634"
"146.60800","2.14100","12,972.35352","2.0448","624.1667"
"146.80800","2.14369","12,986.04199","2.0552","624.8253"
"147.00800","2.14750","13,023.35449","2.0698","626.6206"
"147.20800","2.15062","13,042.60742","2.0819","627.5470"
"147.40800","2.15444","13,080.49121","2.0965","629.3698"
"147.60800","2.15700","13,086.86133","2.1064","629.6763"
"147.80800","2.16075","13,125.72656","2.1208","631.5463"
"148.00800","2.16406","13,150.99902","2.1335","632.7623"
"148.20800","2.16719","13,176.69727","2.1456","633.9987"
"148.40800","2.17100","13,211.45020","2.1602","635.6709"
"148.60800","2.17394","13,228.21484","2.1715","636.4775"
"148.80800","2.17781","13,264.31055","2.1864","638.2142"
"149.00800","2.18025","13,272.46680","2.1958","638.6067"
"149.20800","2.18406","13,311.18750","2.2105","640.4697"
"149.40800","2.18744","13,335.77344","2.2234","641.6527"
"149.60800","2.19069","13,364.77539","2.2359","643.0482"
"149.80800","2.19419","13,388.39258","2.2494","644.1845"
"150.00800","2.19731","13,416.88770","2.2614","645.5555"
"150.20800","2.20094","13,446.06738","2.2754","646.9595"
"150.40800","2.20362","13,461.74512","2.2857","647.7139"
"150.60800","2.20744","13,500.61426","2.3004","649.5840"
"150.80800","2.21062","13,521.92773","2.3126","650.6096"
"151.00800","2.21431","13,560.19824","2.3268","652.4509"
"151.20800","2.21731","13,571.84473","2.3383","653.0113"
"151.40800","2.22062","13,603.92871","2.3511","654.5551"
"151.60800","2.22456","13,634.59277","2.3662","656.0305"
"151.80800","2.22700","13,644.74023","2.3756","656.5187"
"152.00800","2.23081","13,685.80762","2.3903","658.4946"
"152.20800","2.23394","13,706.98242","2.4023","659.5135"
"152.40800","2.23775","13,745.19727","2.4169","661.3522"
"152.60800","2.24044","13,753.47852","2.4273","661.7507"
"152.80800","2.24400","13,789.37500","2.4410","663.4778"
"153.00800","2.24744","13,818.02246","2.4542","664.8562"
"153.20800","2.25056","13,842.38574","2.4662","666.0284"
"153.40800","2.25419","13,872.54492","2.4802","667.4796"
"153.60800","2.25725","13,893.72461","2.4919","668.4986"
"153.80800","2.26119","13,931.59375","2.5071","670.3207"
"154.00800","2.26362","13,937.58496","2.5165","670.6089"
"154.20800","2.26744","13,977.91309","2.5311","672.5493"
"154.40800","2.27075","14,002.18750","2.5439","673.7173"
"154.60800","2.27406","14,033.99512","2.5566","675.2477"
"154.80800","2.27756","14,057.33203","2.5701","676.3706"
"155.00800","2.28062","14,081.97754","2.5819","677.5564"
"155.20800","2.28444","14,114.84668","2.5965","679.1379"
"155.40800","2.28694","14,127.03516","2.6061","679.7244"
"155.60800","2.29075","14,166.74121","2.6208","681.6348"
"155.80800","2.29400","14,188.12305","2.6333","682.6636"
"156.00800","2.29750","14,222.83789","2.6468","684.3339"
"156.20800","2.30062","14,238.48828","2.6588","685.0870"
"156.40800","2.30400","14,271.86914","2.6718","686.6931"
"156.60800","2.30756","14,300.80859","2.6855","688.0855"
"156.80800","2.31031","14,317.62988","2.6960","688.8949"
"157.00800","2.31419","14,356.62109","2.7109","690.7709"
"157.20800","2.31725","14,373.95215","2.7227","691.6048"
"157.40800","2.32106","14,413.41895","2.7374","693.5038"
"157.60800","2.32369","14,420.04590","2.7475","693.8226"
"157.80800","2.32744","14,459.01074","2.7619","695.6974"
"158.00800","2.33087","14,487.60449","2.7751","697.0732"
"158.20800","2.33381","14,507.20312","2.7864","698.0162"
"158.40800","2.33756","14,542.96387","2.8008","699.7368"
"158.60800","2.34062","14,562.49219","2.8126","700.6765"
"158.80800","2.34444","14,598.55469","2.8273","702.4116"
"159.00800","2.34694","14,606.51270","2.8369","702.7945"
"159.20800","2.35075","14,645.10449","2.8516","704.6514"
"159.40800","2.35425","14,672.36621","2.8650","705.9631"
"159.60800","2.35744","14,698.08398","2.8773","707.2005"
"159.80800","2.36087","14,721.11523","2.8905","708.3087"
"160.00800","2.36400","14,748.94141","2.9025","709.6475"
"160.20800","2.36775","14,780.81641","2.9169","711.1812"
"160.40800","2.37025","14,793.08301","2.9266","711.7714"
"160.60800","2.37412","14,834.57715","2.9415","713.7679"
"160.80800","2.37731","14,855.33008","2.9537","714.7664"
"161.00800","2.38094","14,891.52637","2.9677","716.5080"
"161.20800","2.38400","14,905.84863","2.9794","717.1971"
"161.40800","2.38725","14,936.28320","2.9919","718.6614"
"161.60800","2.39100","14,971.26660","3.0064","720.3447"
"161.80800","2.39369","14,985.72656","3.0167","721.0405"
"162.00800","2.39750","15,024.04785","3.0314","722.8843"
"162.20800","2.40062","15,042.87891","3.0434","723.7903"
"162.40800","2.40437","15,079.12305","3.0578","725.5342"
"162.60800","2.40700","15,087.04688","3.0679","725.9155"
"162.80800","2.41075","15,126.85449","3.0823","727.8308"
"163.00800","2.41412","15,152.42188","3.0953","729.0610"
"163.20800","2.41719","15,177.26465","3.1071","730.2563"
"163.40800","2.42100","15,211.01562","3.1218","731.8802"
"163.60800","2.42394","15,229.87305","3.1331","732.7876"
"163.80800","2.42781","15,265.00293","3.1480","734.4778"
"164.00800","2.43025","15,274.08691","3.1573","734.9149"
"164.20800","2.43406","15,314.42090","3.1720","736.8556"
"164.40800","2.43750","15,339.54004","3.1852","738.0642"
"164.60800","2.44075","15,365.93555","3.1977","739.3342"
"164.69200","2.44225","14,691.43750","3.2035","706.8807"
"164.69600","2.44294","13,465.21680","3.2061","647.8809"
"164.70000","2.44375","11,901.46973","3.2093","572.6410"
"164.70400","2.44462","10,166.89062","3.2126","489.1814"
"164.70800","2.44550","8,413.95215","3.2160","404.8385"