File: data/Long/Specimen_RawData_7.csv
Specimen number (included),7
Modulus (Automatic Young's),"318,192.67396",MPa
Length,"26.00000",mm
Specimen ID,"0036"
Thickness,"2.07700",mm
Width,"10.20500",mm
Tensile stress at Tensile strength,"784.16650",MPa
Tensile strain (Strain 1) at Tensile strength,"0.03587",mm/mm

Time,Extension,Load,Tensile strain (Strain 1),Tensile stress
(s),(mm),(N),(%),(MPa)
"0.00000","-0.00350","504.89203","-0.0014","23.8204"
"0.20000","-0.00081","548.96448","-0.0007","25.8997"
"0.40000","0.00331","671.31183","0.0011","31.6719"
"0.60000","0.00637","748.71820","0.0023","35.3239"
"0.80000","0.01012","827.85291","0.0033","39.0574"
"1.00000","0.01275","878.82178","0.0040","41.4621"
"1.20000","0.01650","955.46375","0.0052","45.0780"
"1.40000","0.01975","1,011.69122","0.0061","47.7308"
"1.60000","0.02331","1,079.78125","0.0070","50.9432"
"1.80000","0.02662","1,126.59583","0.0075","53.1519"
"2.00000","0.02975","1,179.23877","0.0081","55.6355"
"2.20000","0.03325","1,233.05981","0.0091","58.1748"
"2.40000","0.03612","1,272.06519","0.0095","60.0150"
"2.60000","0.03994","1,333.58337","0.0105","62.9174"
"2.80000","0.04294","1,370.37549","0.0109","64.6532"
"3.00000","0.04687","1,430.93652","0.0120","67.5104"
"3.20000","0.04962","1,456.61316","0.0123","68.7218"
"3.40000","0.05312","1,505.98108","0.0130","71.0510"
"3.60000","0.05662","1,549.43176","0.0137","73.1009"
"3.80000","0.05956","1,580.79749","0.0140","74.5807"
"4.00000","0.06331","1,634.20923","0.0149","77.1007"
"4.20000","0.06637","1,661.98999","0.0152","78.4113"
"4.40000","0.07031","1,713.78687","0.0161","80.8551"
"4.60000","0.07281","1,729.77954","0.0160","81.6096"
"4.80000","0.07656","1,777.63757","0.0169","83.8675"
"5.00000","0.07981","1,811.88904","0.0175","85.4835"
"5.20000","0.08306","1,848.25330","0.0178","87.1991"
"5.40000","0.08669","1,890.24622","0.0183","89.1803"
"5.60000","0.08969","1,916.79004","0.0187","90.4326"
"5.80000","0.09362","1,960.39233","0.0194","92.4897"
"6.00000","0.09606","1,975.15430","0.0194","93.1862"
"6.20000","0.09987","2,022.18420","0.0204","95.4050"
"6.40000","0.10312","2,051.02637","0.0207","96.7658"
"6.60000","0.10662","2,089.20312","0.0212","98.5669"
"6.80000","0.10994","2,119.02856","0.0217","99.9741"
"7.00000","0.11312","2,148.83081","0.0221","101.3801"
"7.20000","0.11675","2,186.87329","0.0226","103.1749"
"7.40000","0.11944","2,203.69678","0.0226","103.9686"
"7.60000","0.12325","2,248.81030","0.0235","106.0970"
"7.80000","0.12637","2,272.22534","0.0238","107.2018"
"8.00000","0.13012","2,314.29883","0.0246","109.1867"
"8.20000","0.13294","2,330.48730","0.0248","109.9505"
"8.40000","0.13650","2,366.49097","0.0254","111.6491"
"8.60000","0.13994","2,399.41504","0.0257","113.2025"
"8.80000","0.14287","2,418.91455","0.0261","114.1224"
"9.00000","0.14669","2,462.34448","0.0266","116.1714"
"9.20000","0.14969","2,480.19482","0.0269","117.0136"
"9.40000","0.15362","2,521.58252","0.0275","118.9662"
"9.60000","0.15619","2,532.02686","0.0279","119.4590"
"9.80000","0.15987","2,569.54907","0.0282","121.2292"
"10.00000","0.16325","2,599.65259","0.0286","122.6495"
"10.20000","0.16644","2,623.88135","0.0293","123.7926"
"10.40000","0.17000","2,659.87256","0.0298","125.4906"
"10.60000","0.17306","2,678.95142","0.0303","126.3908"
"10.80000","0.17687","2,714.25806","0.0307","128.0565"
"11.00000","0.17937","2,726.10181","0.0310","128.6153"
"11.20000","0.18319","2,764.14575","0.0315","130.4102"
"11.40000","0.18650","2,789.15894","0.0321","131.5903"
"11.60000","0.19000","2,818.52124","0.0325","132.9756"
"11.80000","0.19319","2,841.21729","0.0330","134.0463"
"12.00000","0.19637","2,865.42578","0.0330","135.1885"
"12.20000","0.20006","2,896.01099","0.0338","136.6315"
"12.40000","0.20275","2,908.23364","0.0342","137.2081"
"12.60000","0.20662","2,948.60449","0.0347","139.1128"
"12.80000","0.20975","2,966.36011","0.0349","139.9505"
"13.00000","0.21350","3,001.35278","0.0357","141.6014"
"13.20000","0.21631","3,013.64941","0.0356","142.1815"
"13.40000","0.21975","3,040.89551","0.0363","143.4670"
"13.60000","0.22319","3,067.76758","0.0367","144.7348"
"13.80000","0.22625","3,083.71460","0.0370","145.4872"
"14.00000","0.23000","3,120.22192","0.0376","147.2095"
"14.20000","0.23300","3,132.76685","0.0374","147.8014"
"14.40000","0.23700","3,163.41699","0.0383","149.2475"
"14.60000","0.23944","3,164.75220","0.0384","149.3104"
"14.80000","0.24325","3,195.41626","0.0388","150.7572"
"15.00000","0.24650","3,215.10034","0.0391","151.6858"
"15.20000","0.24981","3,234.59106","0.0397","152.6054"
"15.40000","0.25344","3,263.86621","0.0404","153.9866"
"15.60000","0.25637","3,275.49438","0.0406","154.5352"
"15.80000","0.26019","3,304.11572","0.0411","155.8855"
"16.00000","0.26275","3,309.57666","0.0409","156.1431"
"16.20000","0.26650","3,342.22363","0.0413","157.6834"
"16.40000","0.26975","3,360.27710","0.0419","158.5352"
"16.60000","0.27331","3,384.22778","0.0423","159.6651"
"16.80000","0.27656","3,404.18677","0.0426","160.6068"
"17.00000","0.27981","3,423.54883","0.0429","161.5203"
"17.20000","0.28337","3,448.40186","0.0437","162.6928"
"17.40000","0.28612","3,456.68164","0.0440","163.0834"
"17.60000","0.28994","3,490.89844","0.0446","164.6978"
"17.80000","0.29300","3,504.98828","0.0446","165.3625"
"18.00000","0.29687","3,537.08374","0.0453","166.8767"
"18.20000","0.29969","3,545.25195","0.0455","167.2621"
"18.40000","0.30319","3,569.93384","0.0457","168.4266"
"18.60000","0.30662","3,594.19214","0.0462","169.5711"
"18.80000","0.30956","3,604.55933","0.0465","170.0602"
"19.00000","0.31331","3,640.59814","0.0476","171.7605"
"19.20000","0.31637","3,650.22974","0.0476","172.2149"
"19.40000","0.32025","3,683.08081","0.0483","173.7648"
"19.60000","0.32281","3,687.11157","0.0481","173.9549"
"19.80000","0.32656","3,717.23877","0.0486","175.3763"
"20.00000","0.32987","3,738.09961","0.0493","176.3605"
"20.20000","0.33312","3,754.80347","0.0496","177.1486"
"20.40000","0.33675","3,785.81543","0.0500","178.6117"
"20.60000","0.33969","3,797.26147","0.0503","179.1517"
"20.80000","0.34362","3,827.58032","0.0510","180.5821"
"21.00000","0.34606","3,829.11450","0.0508","180.6545"
"21.20000","0.34994","3,862.73608","0.0520","182.2408"
"21.40000","0.35312","3,879.47412","0.0522","183.0304"
"21.60000","0.35662","3,904.40161","0.0527","184.2065"
"21.80000","0.35987","3,923.79761","0.0529","185.1216"
"22.00000","0.36306","3,941.00659","0.0532","185.9335"
"22.20000","0.36675","3,967.89282","0.0538","187.2020"
"22.40000","0.36944","3,973.33691","0.0541","187.4588"
"22.60000","0.37325","4,009.73413","0.0550","189.1760"
"22.80000","0.37637","4,022.55322","0.0551","189.7808"
"23.00000","0.38012","4,051.75537","0.0553","191.1585"
"23.20000","0.38300","4,060.01685","0.0557","191.5483"
"23.40000","0.38650","4,085.88086","0.0558","192.7686"
"23.60000","0.38994","4,108.45801","0.0570","193.8337"
"23.80000","0.39287","4,119.18066","0.0571","194.3396"
"24.00000","0.39669","4,153.99219","0.0575","195.9820"
"24.20000","0.39969","4,161.94043","0.0577","196.3570"
"24.40000","0.40356","4,193.64355","0.0585","197.8527"
"24.60000","0.40612","4,197.12305","0.0585","198.0169"
"24.80000","0.40987","4,226.71045","0.0592","199.4128"
"25.00000","0.41319","4,246.58691","0.0596","200.3505"
"25.20000","0.41644","4,263.40381","0.0601","201.1439"
"25.40000","0.42006","4,292.28076","0.0608","202.5063"
"25.60000","0.42306","4,304.32520","0.0609","203.0746"
"25.80000","0.42687","4,330.07422","0.0612","204.2894"
"26.00000","0.42937","4,333.53320","0.0618","204.4526"
"26.20000","0.43319","4,365.54590","0.0623","205.9629"
"26.40000","0.43650","4,382.56738","0.0626","206.7660"
"26.60000","0.44000","4,405.33105","0.0630","207.8400"
"26.80000","0.44319","4,421.82959","0.0634","208.6183"
"27.00000","0.44637","4,441.26758","0.0639","209.5354"
"27.20000","0.45006","4,466.71338","0.0643","210.7359"
"27.40000","0.45275","4,471.74170","0.0645","210.9732"
"27.60000","0.45662","4,508.10889","0.0650","212.6889"
"27.80000","0.45975","4,519.43408","0.0656","213.2232"
"28.00000","0.46350","4,549.15234","0.0659","214.6253"
"28.20000","0.46631","4,555.06982","0.0661","214.9045"
"28.40000","0.46981","4,577.93750","0.0665","215.9834"
"28.60000","0.47319","4,601.03955","0.0669","217.0733"
"28.80000","0.47625","4,611.66016","0.0674","217.5744"
"29.00000","0.48000","4,642.50879","0.0682","219.0298"
"29.20000","0.48300","4,651.57715","0.0682","219.4576"
"29.40000","0.48700","4,682.06201","0.0688","220.8959"
"29.60000","0.48937","4,681.55469","0.0690","220.8720"
"29.80000","0.49319","4,713.41943","0.0700","222.3753"
"30.00000","0.49650","4,732.18457","0.0701","223.2606"
"30.20000","0.49981","4,750.96436","0.0706","224.1467"
"30.40000","0.50344","4,776.93018","0.0709","225.3717"
"30.60000","0.50637","4,786.66406","0.0711","225.8309"
"30.80000","0.51025","4,813.62500","0.0717","227.1029"
"31.00000","0.51275","4,815.74268","0.0718","227.2028"
"31.20000","0.51650","4,845.37793","0.0724","228.6010"
"31.40000","0.51981","4,861.86182","0.0729","229.3787"
"31.60000","0.52331","4,883.45605","0.0732","230.3975"
"31.80000","0.52656","4,900.05029","0.0735","231.1804"
"32.00000","0.52981","4,918.32373","0.0742","232.0425"
"32.20000","0.53325","4,938.60352","0.0744","232.9993"
"32.40000","0.53606","4,946.54004","0.0748","233.3737"
"32.60000","0.53994","4,978.59521","0.0754","234.8861"
"32.80000","0.54300","4,988.41553","0.0758","235.3494"
"33.00000","0.54687","5,017.99561","0.0765","236.7450"
"33.20000","0.54969","5,023.71777","0.0764","237.0149"
"33.40000","0.55312","5,046.92920","0.0771","238.1100"
"33.60000","0.55662","5,068.43457","0.0773","239.1246"
"33.80000","0.55956","5,076.25732","0.0780","239.4937"
"34.00000","0.56331","5,109.47754","0.0783","241.0610"
"34.20000","0.56637","5,117.39551","0.0784","241.4346"
"34.40000","0.57031","5,147.30762","0.0793","242.8458"
"34.60000","0.57287","5,148.18164","0.0792","242.8870"
"34.80000","0.57656","5,175.60547","0.0799","244.1809"
"35.00000","0.57981","5,194.00977","0.0800","245.0492"
"35.20000","0.58306","5,210.72510","0.0807","245.8378"
"35.40000","0.58669","5,236.86230","0.0810","247.0709"
"35.60000","0.58969","5,246.93457","0.0815","247.5461"
"35.80000","0.59369","5,274.77295","0.0818","248.8595"
"36.00000","0.59606","5,271.97754","0.0820","248.7276"
"36.20000","0.59994","5,304.69531","0.0825","250.2712"
"36.40000","0.60312","5,317.89990","0.0825","250.8942"
"36.60000","0.60662","5,340.21143","0.0832","251.9469"
"36.80000","0.60994","5,356.57275","0.0838","252.7188"
"37.00000","0.61306","5,372.23975","0.0839","253.4579"
"37.20000","0.61675","5,395.89014","0.0842","254.5737"
"37.40000","0.61944","5,400.13281","0.0849","254.7739"
"37.60000","0.62325","5,433.10205","0.0854","256.3293"
"37.80000","0.62637","5,444.73047","0.0858","256.8780"
"38.00000","0.63012","5,472.97656","0.0863","258.2106"
"38.20000","0.63300","5,479.11426","0.0864","258.5002"
"38.40000","0.63650","5,504.08154","0.0869","259.6781"
"38.60000","0.63994","5,523.70312","0.0875","260.6039"
"38.80000","0.64294","5,533.31396","0.0876","261.0573"
"39.00000","0.64669","5,565.90820","0.0884","262.5950"
"39.20000","0.64969","5,572.49072","0.0888","262.9056"
"39.40000","0.65356","5,602.90527","0.0893","264.3405"
"39.60000","0.65612","5,602.80322","0.0893","264.3357"
"39.80000","0.65981","5,632.48047","0.0900","265.7359"
"40.00000","0.66325","5,652.48633","0.0904","266.6797"
"40.20000","0.66644","5,668.70850","0.0909","267.4451"
"40.40000","0.67000","5,693.80371","0.0913","268.6291"
"40.60000","0.67306","5,707.57812","0.0916","269.2789"
"40.80000","0.67681","5,732.22168","0.0922","270.4416"
"41.00000","0.67937","5,735.72266","0.0922","270.6068"
"41.20000","0.68319","5,767.19043","0.0928","272.0914"
"41.40000","0.68650","5,785.31104","0.0934","272.9463"
"41.60000","0.69000","5,809.17480","0.0938","274.0722"
"41.80000","0.69325","5,823.14062","0.0943","274.7310"
"42.00000","0.69637","5,842.55957","0.0945","275.6472"
"42.20000","0.70006","5,867.85693","0.0950","276.8407"
"42.40000","0.70275","5,873.37158","0.0956","277.1009"
"42.60000","0.70662","5,909.07129","0.0962","278.7852"
"42.80000","0.70975","5,919.44678","0.0964","279.2747"
"43.00000","0.71350","5,950.23145","0.0973","280.7271"
"43.20000","0.71631","5,954.65771","0.0974","280.9359"
"43.40000","0.71975","5,979.67969","0.0979","282.1165"
"43.60000","0.72319","6,002.56738","0.0979","283.1963"
"43.80000","0.72631","6,014.32178","0.0985","283.7508"
"44.00000","0.73000","6,044.98145","0.0994","285.1973"
"44.20000","0.73300","6,054.33301","0.0993","285.6385"
"44.40000","0.73700","6,085.91113","0.0999","287.1284"
"44.60000","0.73944","6,085.10010","0.1001","287.0901"
"44.80000","0.74319","6,117.10303","0.1009","288.6000"
"45.00000","0.74650","6,134.76611","0.1013","289.4333"
"45.20000","0.74981","6,155.69336","0.1018","290.4206"
"45.40000","0.75344","6,180.51855","0.1025","291.5919"
"45.60000","0.75637","6,193.57471","0.1024","292.2079"
"45.80000","0.76019","6,219.19336","0.1032","293.4165"
"46.00000","0.76275","6,223.30811","0.1031","293.6106"
"46.20000","0.76650","6,255.38672","0.1043","295.1241"
"46.40000","0.76981","6,272.19092","0.1044","295.9169"
"46.60000","0.77331","6,296.43896","0.1049","297.0609"
"46.80000","0.77656","6,311.10449","0.1053","297.7528"
"47.00000","0.77981","6,332.86475","0.1060","298.7794"
"47.20000","0.78331","6,354.25146","0.1060","299.7885"
"47.40000","0.78612","6,364.53125","0.1065","300.2734"
"47.60000","0.78994","6,398.69043","0.1071","301.8850"
"47.80000","0.79300","6,409.87695","0.1075","302.4128"
"48.00000","0.79681","6,440.29980","0.1084","303.8481"
"48.20000","0.79969","6,446.66455","0.1083","304.1484"
"48.40000","0.80312","6,472.92432","0.1088","305.3873"
"48.60000","0.80662","6,496.69092","0.1091","306.5086"
"48.80000","0.80956","6,507.51465","0.1097","307.0193"
"49.00000","0.81331","6,540.59521","0.1103","308.5800"
"49.20000","0.81637","6,551.03760","0.1106","309.0727"
"49.40000","0.82031","6,582.83105","0.1113","310.5726"
"49.60000","0.82281","6,585.25293","0.1116","310.6869"
"49.80000","0.82656","6,617.70459","0.1120","312.2180"
"50.00000","0.82987","6,637.91309","0.1123","313.1714"
"50.20000","0.83312","6,656.66748","0.1132","314.0562"
"50.40000","0.83669","6,682.15771","0.1137","315.2588"
"50.60000","0.83962","6,694.03223","0.1141","315.8190"
"50.80000","0.84362","6,725.54248","0.1144","317.3057"
"51.00000","0.84600","6,725.82324","0.1147","317.3189"
"51.20000","0.84987","6,760.53320","0.1152","318.9565"
"51.40000","0.85312","6,774.69727","0.1155","319.6247"
"51.60000","0.85662","6,799.48047","0.1162","320.7940"
"51.80000","0.85987","6,814.74561","0.1165","321.5142"
"52.00000","0.86306","6,835.05908","0.1171","322.4726"
"52.20000","0.86675","6,860.23975","0.1176","323.6606"
"52.40000","0.86944","6,866.20752","0.1181","323.9421"
"52.60000","0.87325","6,901.65820","0.1188","325.6147"
"52.80000","0.87637","6,916.05225","0.1188","326.2937"
"53.00000","0.88019","6,947.68799","0.1198","327.7863"
"53.20000","0.88294","6,952.58398","0.1199","328.0173"
"53.40000","0.88650","6,981.13818","0.1203","329.3644"
"53.60000","0.88994","7,002.83496","0.1209","330.3881"
"53.80000","0.89287","7,014.89355","0.1211","330.9570"
"54.00000","0.89669","7,049.01660","0.1221","332.5669"
"54.20000","0.89969","7,059.71191","0.1221","333.0715"
"54.40000","0.90356","7,091.06543","0.1233","334.5507"
"54.60000","0.90619","7,092.95410","0.1231","334.6398"
"54.80000","0.90981","7,124.10791","0.1239","336.1096"
"55.00000","0.91325","7,145.40186","0.1243","337.1143"
"55.20000","0.91644","7,163.64307","0.1245","337.9749"
"55.40000","0.92006","7,190.45703","0.1252","339.2399"
"55.60000","0.92312","7,206.77002","0.1256","340.0096"
"55.80000","0.92687","7,233.55566","0.1262","341.2733"
"56.00000","0.92937","7,239.19287","0.1266","341.5392"
"56.20000","0.93319","7,272.72168","0.1274","343.1211"
"56.40000","0.93650","7,291.35205","0.1277","344.0001"
"56.60000","0.94000","7,318.35938","0.1282","345.2743"
"56.80000","0.94312","7,331.61035","0.1286","345.8994"
"57.00000","0.94637","7,355.06201","0.1291","347.0059"
"57.20000","0.95006","7,380.83350","0.1297","348.2217"
"57.40000","0.95275","7,387.33545","0.1297","348.5285"
"57.60000","0.95662","7,423.67676","0.1308","350.2431"
"57.80000","0.95975","7,436.59277","0.1307","350.8524"
"58.00000","0.96350","7,469.60107","0.1317","352.4097"
"58.20000","0.96637","7,474.59668","0.1319","352.6454"
"58.40000","0.96981","7,500.90039","0.1327","353.8864"
"58.60000","0.97319","7,524.18506","0.1327","354.9850"
"58.80000","0.97625","7,538.50586","0.1333","355.6606"
"59.00000","0.98000","7,570.77637","0.1337","357.1831"
"59.20000","0.98300","7,584.28516","0.1342","357.8204"
"59.40000","0.98700","7,618.33252","0.1350","359.4268"
"59.60000","0.98937","7,619.51953","0.1352","359.4828"
"59.80000","0.99319","7,654.50586","0.1357","361.1334"
"60.00000","0.99650","7,674.17383","0.1364","362.0613"
"60.20000","0.99981","7,696.92139","0.1370","363.1345"
"60.40000","1.00344","7,723.01025","0.1375","364.3654"
"60.60000","1.00637","7,738.46191","0.1381","365.0944"
"60.80000","1.01012","7,766.89893","0.1384","366.4360"
"61.00000","1.01275","7,774.76855","0.1387","366.8073"
"61.20000","1.01650","7,807.91553","0.1394","368.3711"
"61.40000","1.01981","7,828.95752","0.1398","369.3639"
"61.60000","1.02325","7,856.04639","0.1405","370.6419"
"61.80000","1.02650","7,871.69629","0.1407","371.3802"
"62.00000","1.02987","7,898.67041","0.1416","372.6529"
"62.20000","1.03331","7,921.71143","0.1420","373.7399"
"62.40000","1.03612","7,933.79932","0.1425","374.3102"
"62.60000","1.03994","7,968.98682","0.1429","375.9703"
"62.80000","1.04300","7,982.70947","0.1434","376.6178"
"63.00000","1.04687","8,018.92432","0.1439","378.3264"
"63.20000","1.04969","8,024.32666","0.1443","378.5812"
"63.40000","1.05306","8,053.84277","0.1451","379.9738"
"63.60000","1.05669","8,081.31152","0.1458","381.2697"
"63.80000","1.05956","8,092.98438","0.1463","381.8205"
"64.00000","1.06331","8,128.61621","0.1466","383.5015"
"64.20000","1.06637","8,142.59668","0.1472","384.1611"
"64.40000","1.07025","8,176.71582","0.1476","385.7708"
"64.60000","1.07281","8,180.59424","0.1477","385.9538"
"64.80000","1.07650","8,214.67578","0.1485","387.5618"
"65.00000","1.07981","8,235.44336","0.1491","388.5416"
"65.20000","1.08312","8,259.87207","0.1498","389.6941"
"65.40000","1.08669","8,285.85449","0.1505","390.9199"
"65.60000","1.08969","8,305.58203","0.1507","391.8506"
"65.80000","1.09375","8,339.93945","0.1515","393.4716"
"66.00000","1.09606","8,340.45215","0.1516","393.4958"
"66.20000","1.09994","8,379.01465","0.1523","395.3151"
"66.40000","1.10312","8,398.27051","0.1531","396.2236"
"66.60000","1.10662","8,428.10156","0.1536","397.6310"
"66.80000","1.10987","8,445.43652","0.1539","398.4489"
"67.00000","1.11306","8,470.43066","0.1546","399.6281"
"67.20000","1.11681","8,500.71387","0.1551","401.0568"
"67.40000","1.11944","8,510.01172","0.1555","401.4955"
"67.60000","1.12325","8,547.19238","0.1564","403.2496"
"67.80000","1.12644","8,564.61719","0.1566","404.0717"
"68.00000","1.13006","8,597.83398","0.1573","405.6389"
"68.20000","1.13294","8,606.49316","0.1577","406.0474"
"68.40000","1.13650","8,639.83887","0.1582","407.6206"
"68.60000","1.13994","8,664.83691","0.1587","408.8000"
"68.80000","1.14287","8,679.99609","0.1595","409.5152"
"69.00000","1.14669","8,716.01855","0.1601","411.2147"
"69.20000","1.14969","8,728.40234","0.1606","411.7990"
"69.40000","1.15362","8,764.03027","0.1612","413.4799"
"69.60000","1.15612","8,768.39941","0.1613","413.6860"
"69.80000","1.15981","8,804.70312","0.1622","415.3988"
"70.00000","1.16325","8,828.98828","0.1627","416.5445"
"70.20000","1.16644","8,850.20605","0.1632","417.5456"
"70.40000","1.17000","8,877.36621","0.1637","418.8270"
"70.60000","1.17306","8,896.33691","0.1641","419.7220"
"70.80000","1.17687","8,926.99805","0.1650","421.1685"
"71.00000","1.17937","8,934.58691","0.1651","421.5266"
"71.20000","1.18319","8,971.62793","0.1659","423.2741"
"71.40000","1.18656","8,992.53223","0.1662","424.2604"
"71.60000","1.19000","9,021.03809","0.1668","425.6053"
"71.80000","1.19312","9,035.54590","0.1673","426.2897"
"72.00000","1.19637","9,063.20703","0.1681","427.5948"
"72.20000","1.20006","9,092.34082","0.1687","428.9693"
"72.40000","1.20275","9,103.05371","0.1689","429.4747"
"72.60000","1.20662","9,143.06348","0.1698","431.3623"
"72.80000","1.20975","9,158.62988","0.1703","432.0967"
"73.00000","1.21350","9,192.97266","0.1708","433.7170"
"73.20000","1.21631","9,199.92188","0.1711","434.0449"
"73.40000","1.21975","9,229.77441","0.1719","435.4533"
"73.60000","1.22312","9,255.17383","0.1723","436.6516"
"73.80000","1.22631","9,274.41016","0.1728","437.5592"
"74.00000","1.23000","9,308.58398","0.1734","439.1714"
"74.20000","1.23300","9,324.63477","0.1740","439.9287"
"74.40000","1.23694","9,360.58984","0.1748","441.6251"
"74.60000","1.23937","9,363.72852","0.1748","441.7731"
"74.80000","1.24325","9,401.91699","0.1757","443.5748"
"75.00000","1.24650","9,423.21387","0.1761","444.5796"
"75.20000","1.24975","9,450.10840","0.1767","445.8484"
"75.40000","1.25344","9,477.60156","0.1773","447.1456"
"75.60000","1.25637","9,495.80957","0.1777","448.0046"
"75.80000","1.26019","9,527.51953","0.1784","449.5007"
"95.85400","1.26169","9,335.83691","0.1817","440.4572"
"96.05400","1.26194","9,336.29980","0.1826","440.4791"
"96.25400","1.26681","9,454.49219","0.2014","446.0553"
"96.45400","1.27044","9,538.34668","0.2153","450.0115"
"96.65400","1.27356","9,607.94043","0.2274","453.2949"
"96.85400","1.27719","9,670.50879","0.2413","456.2468"
"97.05400","1.28025","9,704.15039","0.2531","457.8340"
"97.25400","1.28400","9,719.70703","0.2675","458.5679"
"97.45400","1.28656","9,710.69141","0.2774","458.1425"
"97.65400","1.29037","9,737.38379","0.2920","459.4019"
"97.85400","1.29356","9,753.91992","0.3043","460.1820"
"98.05400","1.29719","9,786.51953","0.3182","461.7201"
"98.25400","1.30031","9,799.34961","0.3302","462.3254"
"98.45400","1.30362","9,827.88770","0.3430","463.6718"
"98.65400","1.30737","9,856.64746","0.3574","465.0287"
"98.85400","1.30987","9,863.41504","0.3670","465.3479"
"99.05400","1.31381","9,902.45117","0.3822","467.1896"
"99.25400","1.31687","9,918.94531","0.3939","467.9678"
"99.45400","1.32069","9,956.20898","0.4086","469.7259"
"99.65400","1.32350","9,964.59082","0.4194","470.1213"
"99.85400","1.32700","9,995.89062","0.4329","471.5980"
"100.05400","1.33044","10,022.07129","0.4461","472.8332"
"100.25400","1.33337","10,040.49805","0.4574","473.7026"
"100.45400","1.33712","10,075.98535","0.4718","475.3768"
"100.65400","1.34012","10,093.51562","0.4834","476.2039"
"100.85400","1.34406","10,131.53613","0.4985","477.9977"
"101.05400","1.34662","10,134.63770","0.5084","478.1440"
"101.25400","1.35037","10,173.22266","0.5228","479.9644"
"101.45400","1.35375","10,197.31738","0.5358","481.1012"
"101.65400","1.35694","10,220.82812","0.5480","482.2104"
"101.85400","1.36056","10,250.01367","0.5620","483.5873"
"102.05400","1.36356","10,269.28613","0.5735","484.4966"
"102.25400","1.36750","10,305.13086","0.5887","486.1877"
"102.45400","1.36987","10,311.02832","0.5978","486.4660"
"102.65400","1.37369","10,350.49023","0.6125","488.3278"
"102.85400","1.37706","10,374.00391","0.6254","489.4371"
"103.05400","1.38037","10,403.23926","0.6382","490.8164"
"103.25400","1.38369","10,423.64844","0.6509","491.7793"
"103.45400","1.38694","10,451.70996","0.6634","493.1032"
"103.65400","1.39050","10,480.36426","0.6771","494.4551"
"103.85400","1.39325","10,494.07422","0.6877","495.1019"
"104.05400","1.39706","10,533.06348","0.7024","496.9414"
"104.25400","1.40025","10,550.03906","0.7146","497.7423"
"104.45400","1.40400","10,587.07422","0.7290","499.4896"
"104.65400","1.40681","10,595.86035","0.7399","499.9041"
"104.85400","1.41031","10,629.85742","0.7533","501.5081"
"105.05400","1.41381","10,658.24707","0.7668","502.8475"
"105.25400","1.41669","10,674.78613","0.7778","503.6278"
"105.45400","1.42050","10,711.63379","0.7925","505.3662"
"105.65400","1.42356","10,728.69531","0.8043","506.1712"
"105.85400","1.42737","10,763.94727","0.8189","507.8343"
"106.05400","1.43000","10,770.35156","0.8290","508.1365"
"106.25400","1.43356","10,805.41602","0.8427","509.7908"
"106.45400","1.43712","10,833.75195","0.8564","511.1277"
"106.65400","1.44025","10,856.25488","0.8685","512.1893"
"106.85400","1.44381","10,882.55273","0.8822","513.4301"
"107.05400","1.44687","10,904.59473","0.8939","514.4700"
"107.25400","1.45075","10,938.03516","0.9089","516.0477"
"107.45400","1.45319","10,945.03516","0.9182","516.3779"
"107.65400","1.45712","10,986.32129","0.9334","518.3257"
"107.85400","1.46031","11,005.70508","0.9456","519.2402"
"108.05400","1.46381","11,038.40039","0.9591","520.7828"
"108.25400","1.46712","11,055.86621","0.9718","521.6068"
"108.45400","1.47019","11,081.13574","0.9836","522.7990"
"108.65400","1.47375","11,109.55078","0.9973","524.1396"
"108.85400","1.47662","11,124.83496","1.0084","524.8607"
"109.05400","1.48044","11,162.01562","1.0230","526.6149"
"109.25400","1.48356","11,180.63965","1.0351","527.4935"
"109.45400","1.48731","11,217.65430","1.0495","529.2399"
"109.65400","1.49012","11,224.46973","1.0603","529.5614"
"109.85400","1.49369","11,259.70898","1.0740","531.2239"
"110.05400","1.49700","11,284.42480","1.0867","532.3900"
"110.25400","1.50006","11,305.20508","1.0985","533.3704"
"110.45400","1.50387","11,342.92188","1.1132","535.1498"
"110.65400","1.50687","11,358.81543","1.1247","535.8997"
"110.85400","1.51081","11,395.76074","1.1399","537.6428"
"111.05400","1.51325","11,402.25781","1.1492","537.9493"
"111.25400","1.51694","11,439.38574","1.1634","539.7009"
"111.45400","1.52044","11,468.61914","1.1769","541.0801"
"111.65400","1.52356","11,492.94043","1.1889","542.2276"
"111.85400","1.52712","11,522.61816","1.2026","543.6278"
"112.05400","1.53031","11,546.19043","1.2149","544.7399"
"112.25400","1.53400","11,576.14258","1.2290","546.1530"
"112.45400","1.53656","11,588.46582","1.2389","546.7344"
"112.65400","1.54037","11,627.87695","1.2536","548.5938"
"112.85400","1.54362","11,648.97852","1.2661","549.5894"
"113.05400","1.54719","11,685.58789","1.2798","551.3166"
"113.25400","1.55037","11,701.12793","1.2920","552.0497"
"113.45400","1.55356","11,730.32227","1.3043","553.4271"
"113.65400","1.55725","11,761.23828","1.3185","554.8857"
"113.85400","1.55987","11,774.76758","1.3286","555.5240"
"114.05400","1.56375","11,816.08691","1.3435","557.4734"
"114.25400","1.56687","11,835.02637","1.3555","558.3669"
"114.45400","1.57069","11,873.03418","1.3701","560.1602"
"114.65400","1.57350","11,882.40625","1.3810","560.6023"
"114.85400","1.57700","11,916.71875","1.3944","562.2211"
"115.05400","1.58044","11,943.83105","1.4076","563.5003"
"115.25400","1.58344","11,964.22461","1.4192","564.4624"
"115.45400","1.58712","11,999.98438","1.4334","566.1495"
"115.65400","1.59012","12,018.27539","1.4449","567.0125"
"115.85400","1.59406","12,057.76953","1.4601","568.8758"
"116.05400","1.59662","12,061.61328","1.4699","569.0571"
"116.25400","1.60044","12,102.29199","1.4846","570.9763"
"116.45400","1.60369","12,125.89258","1.4971","572.0898"
"116.65400","1.60687","12,152.00293","1.5093","573.3217"
"116.85400","1.61056","12,183.18555","1.5235","574.7928"
"117.05400","1.61350","12,203.75488","1.5348","575.7632"
"117.25400","1.61744","12,240.96680","1.5500","577.5189"
"117.45400","1.61987","12,247.96387","1.5593","577.8490"
"117.65400","1.62375","12,289.24805","1.5742","579.7968"
"117.85400","1.62706","12,313.08496","1.5870","580.9214"
"118.05400","1.63037","12,343.20801","1.5997","582.3426"
"118.25400","1.63375","12,363.66602","1.6127","583.3077"
"118.45400","1.63694","12,394.18066","1.6250","584.7474"
"118.65400","1.64050","12,422.80566","1.6387","586.0979"
"118.85400","1.64325","12,437.75977","1.6492","586.8034"
"119.05400","1.64706","12,477.11523","1.6639","588.6602"
"119.25400","1.65019","12,496.01465","1.6759","589.5519"
"119.45400","1.65400","12,535.66602","1.6906","591.4225"
"119.65400","1.65675","12,544.13281","1.7012","591.8220"
"119.85400","1.66031","12,580.92090","1.7149","593.5577"
"120.05400","1.66381","12,609.49121","1.7283","594.9056"
"120.25400","1.66669","12,627.92773","1.7394","595.7754"
"120.45400","1.67050","12,664.78320","1.7540","597.5142"
"120.65400","1.67356","12,683.69824","1.7658","598.4066"
"120.85400","1.67744","12,720.77734","1.7807","600.1560"
"121.05400","1.68000","12,728.51660","1.7906","600.5211"
"121.25400","1.68356","12,764.34766","1.8043","602.2116"
"121.45400","1.68719","12,795.37500","1.8182","603.6754"
"121.65400","1.69025","12,819.51074","1.8300","604.8141"
"121.85400","1.69375","12,845.09863","1.8435","606.0214"
"122.05400","1.69687","12,871.23145","1.8555","607.2543"
"122.25400","1.70069","12,906.34570","1.8701","608.9109"
"122.45400","1.70319","12,914.91797","1.8798","609.3154"
"122.65400","1.70712","12,957.19336","1.8949","611.3099"
"122.85400","1.71031","12,979.10352","1.9072","612.3436"
"123.05400","1.71381","13,013.78027","1.9206","613.9796"
"123.25400","1.71719","13,032.86816","1.9336","614.8802"
"123.45400","1.72025","13,060.21191","1.9454","616.1702"
"123.65400","1.72381","13,090.07227","1.9591","617.5790"
"123.85400","1.72662","13,108.21777","1.9699","618.4351"
"124.05400","1.73037","13,147.61914","1.9843","620.2940"
"124.25400","1.73362","13,168.24121","1.9968","621.2670"
"124.45400","1.73731","13,205.78125","2.0110","623.0381"
"124.65400","1.74006","13,214.91309","2.0216","623.4689"
"124.85400","1.74369","13,253.52051","2.0355","625.2903"
"125.05400","1.74700","13,280.05762","2.0483","626.5424"
"125.25400","1.75006","13,303.45312","2.0601","627.6461"
"125.45400","1.75387","13,341.06934","2.0747","629.4208"
"125.65400","1.75687","13,359.19336","2.0863","630.2759"
"125.85400","1.76081","13,397.35254","2.1014","632.0762"
"126.05400","1.76331","13,404.09082","2.1110","632.3942"
"126.25400","1.76700","13,443.20605","2.1252","634.2396"
"126.45400","1.77050","13,471.28906","2.1387","635.5645"
"126.65400","1.77356","13,495.69141","2.1504","636.7158"
"126.85400","1.77719","13,526.53223","2.1644","638.1708"
"127.05400","1.78031","13,550.82422","2.1764","639.3169"
"127.25400","1.78387","13,579.89453","2.1901","640.6884"
"127.45400","1.78656","13,595.50195","2.2004","641.4248"
"127.65400","1.79037","13,634.59082","2.2151","643.2690"
"127.85400","1.79362","13,658.52246","2.2276","644.3980"
"128.05400","1.79719","13,694.40430","2.2413","646.0909"
"128.25400","1.80031","13,710.73145","2.2533","646.8612"
"128.45400","1.80362","13,742.77051","2.2661","648.3728"
"128.65400","1.80731","13,775.45117","2.2802","649.9146"
"128.85400","1.80987","13,789.47070","2.2901","650.5760"
"129.05400","1.81375","13,831.92285","2.3050","652.5789"
"129.25400","1.81687","13,852.79102","2.3170","653.5635"
"129.45400","1.82062","13,892.17383","2.3314","655.4215"
"129.65400","1.82350","13,904.25684","2.3425","655.9916"
"129.85400","1.82700","13,940.40332","2.3560","657.6970"
"130.05400","1.83044","13,969.83105","2.3692","659.0853"
"130.25400","1.83337","13,991.32422","2.3805","660.0994"
"130.45400","1.83712","14,027.74023","2.3949","661.8174"
"130.65400","1.84019","14,048.58984","2.4067","662.8011"
"130.85400","1.84406","14,088.31348","2.4216","664.6752"
"131.05400","1.84662","14,095.54004","2.4314","665.0162"
"131.25400","1.85044","14,136.37109","2.4461","666.9426"
"131.45400","1.85375","14,162.17285","2.4589","668.1599"
"131.65400","1.85687","14,189.54102","2.4709","669.4510"
"131.85400","1.86056","14,221.29102","2.4851","670.9490"
"132.05400","1.86350","14,242.50488","2.4964","671.9498"
"132.25400","1.86744","14,282.58594","2.5115","673.8408"
"132.45400","1.86987","14,289.54785","2.5209","674.1693"
"132.65400","1.87369","14,331.57324","2.5355","676.1520"
"132.85400","1.87706","14,357.73242","2.5485","677.3862"
"133.05400","1.88037","14,389.30078","2.5613","678.8755"
"133.25400","1.88369","14,410.06836","2.5740","679.8553"
"133.45400","1.88700","14,441.33691","2.5867","681.3306"
"133.65400","1.89056","14,472.21191","2.6004","682.7872"
"133.85400","1.89325","14,488.59766","2.6108","683.5603"
"134.05400","1.89706","14,528.86035","2.6254","685.4598"
"134.25400","1.90031","14,550.22559","2.6379","686.4678"
"134.45400","1.90400","14,590.04980","2.6521","688.3467"
"134.65400","1.90675","14,600.25488","2.6627","688.8282"
"134.85400","1.91031","14,637.41699","2.6764","690.5815"
"135.05400","1.91381","14,668.01172","2.6899","692.0249"
"135.25400","1.91669","14,687.33203","2.7009","692.9365"
"135.45400","1.92050","14,725.81738","2.7156","694.7521"
"135.65400","1.92356","14,745.65430","2.7274","695.6880"
"135.85400","1.92737","14,783.32129","2.7420","697.4651"
"136.05400","1.92994","14,792.39648","2.7519","697.8933"
"136.25400","1.93356","14,829.31641","2.7658","699.6351"
"136.45400","1.93719","14,862.30078","2.7798","701.1913"
"136.65400","1.94025","14,886.60156","2.7915","702.3378"
"136.85400","1.94381","14,913.90723","2.8052","703.6260"
"137.05400","1.94687","14,940.72656","2.8170","704.8914"
"137.25400","1.95075","14,976.60547","2.8319","706.5841"
"137.45400","1.95319","14,985.06055","2.8413","706.9830"
"137.65400","1.95712","15,029.66602","2.8564","709.0875"
"137.85400","1.96031","15,051.85645","2.8687","710.1344"
"138.05400","1.96381","15,086.58203","2.8822","711.7727"
"138.25400","1.96712","15,105.01953","2.8949","712.6426"
"138.45400","1.97025","15,134.22852","2.9069","714.0206"
"138.65400","1.97375","15,165.87402","2.9204","715.5137"
"138.85400","1.97662","15,184.71387","2.9314","716.4025"
"139.05400","1.98037","15,224.44531","2.9459","718.2770"
"139.25400","1.98362","15,245.75098","2.9584","719.2822"
"139.45400","1.98731","15,284.44434","2.9726","721.1077"
"139.65400","1.99006","15,295.11230","2.9831","721.6110"
"139.85400","1.99375","15,334.41797","2.9973","723.4655"
"140.05400","1.99700","15,359.65625","3.0098","724.6561"
"140.25400","2.00006","15,384.29297","3.0216","725.8185"
"140.45400","2.00381","15,422.36035","3.0360","727.6145"
"140.65400","2.00687","15,441.04199","3.0478","728.4958"
"140.85400","2.01075","15,479.89258","3.0627","730.3288"
"141.05400","2.01325","15,488.18457","3.0723","730.7200"
"141.25400","2.01700","15,527.27832","3.0867","732.5644"
"141.45400","2.02050","15,557.07031","3.1002","733.9700"
"141.65400","2.02356","15,581.31445","3.1120","735.1138"
"141.85400","2.02712","15,610.61035","3.1257","736.4960"
"142.05400","2.03031","15,637.50098","3.1379","737.7646"
"142.25400","2.03394","15,668.66211","3.1519","739.2348"
"142.45400","2.03656","15,683.72363","3.1620","739.9454"
"142.65400","2.04037","15,724.04492","3.1766","741.8477"
"142.85400","2.04362","15,747.69922","3.1891","742.9637"
"143.05400","2.04719","15,784.75684","3.2028","744.7120"
"143.25400","2.05031","15,801.00781","3.2149","745.4788"
"143.45400","2.05356","15,833.96777","3.2274","747.0338"
"143.65400","2.05731","15,866.68945","3.2418","748.5776"
"143.85400","2.05987","15,880.18848","3.2516","749.2144"
"144.05400","2.06375","15,922.08398","3.2665","751.1910"
"144.25400","2.06694","15,943.46777","3.2788","752.1999"
"144.45400","2.07069","15,983.33105","3.2932","754.0806"
"144.65400","2.07350","15,993.68164","3.3040","754.5690"
"144.85400","2.07694","16,027.27441","3.3173","756.1538"
"145.05400","2.08044","16,056.86426","3.3307","757.5499"
"145.25400","2.08344","16,079.36914","3.3423","758.6116"
"145.45400","2.08706","16,115.66992","3.3562","760.3243"
"145.65400","2.09012","16,137.15430","3.3680","761.3379"
"145.85400","2.09406","16,178.67090","3.3831","763.2966"
"146.05400","2.09656","16,183.50781","3.3927","763.5248"
"146.25400","2.10037","16,227.09961","3.4074","765.5814"
"146.45400","2.10369","16,253.61914","3.4201","766.8326"
"146.65400","2.10687","16,279.27148","3.4324","768.0428"
"146.85400","2.11056","16,311.12695","3.4466","769.5458"
"147.05400","2.11350","16,332.70215","3.4579","770.5637"
"147.25400","2.11750","16,370.62305","3.4733","772.3527"
"147.45400","2.11987","16,378.78418","3.4824","772.7378"
"147.65400","2.12369","16,421.48828","3.4971","774.7525"
"147.85400","2.12712","16,448.88281","3.5103","776.0450"
"148.05400","2.13037","16,479.10742","3.5228","777.4709"
"148.25400","2.13369","16,500.08789","3.5355","778.4608"
"148.45400","2.13694","16,532.14844","3.5480","779.9734"
"148.65400","2.14044","16,561.17188","3.5615","781.3427"
"148.85400","2.14325","16,579.81641","3.5723","782.2223"
"149.05400","2.14706","16,621.02539","3.5870","784.1665"
"149.14200","2.14894","16,058.25879","3.5942","757.6157"
"149.14600","2.14969","14,816.25781","3.5971","699.0190"
"149.15000","2.15050","13,170.20020","3.6002","621.3594"
"149.15400","2.15144","11,309.27930","3.6038","533.5626"
"149.15800","2.15231","9,407.37988","3.6072","443.8326"