File: data/Long/Specimen_RawData_9.csv
Specimen number (included),9
Modulus (Automatic Young's),"295,683.99403",MPa
Length,"26.00000",mm
Specimen ID,"0037"
Thickness,"2.04000",mm
Width,"10.12100",mm
Tensile stress at Tensile strength,"778.88849",MPa
Tensile strain (Strain 1) at Tensile strength,"0.03464",mm/mm

Time,Extension,Load,Tensile strain (Strain 1),Tensile stress
(s),(mm),(N),(%),(MPa)
"0.00000","0.00144","513.33624","-0.0012","24.8627"
"0.20000","0.00394","557.53381","-0.0002","27.0033"
"0.40000","0.00794","675.59399","0.0015","32.7214"
"0.60000","0.01156","770.07257","0.0031","37.2974"
"0.80000","0.01500","837.54834","0.0041","40.5655"
"1.00000","0.01806","905.96283","0.0051","43.8790"
"1.20000","0.02175","976.09955","0.0062","47.2760"
"1.40000","0.02437","1,023.67255","0.0067","49.5801"
"1.60000","0.02825","1,098.44763","0.0077","53.2017"
"1.80000","0.03131","1,147.10828","0.0086","55.5585"
"2.00000","0.03506","1,216.56665","0.0097","58.9227"
"2.20000","0.03812","1,254.90479","0.0102","60.7795"
"2.40000","0.04137","1,310.03296","0.0111","63.4496"
"2.60000","0.04487","1,361.99377","0.0118","65.9662"
"2.80000","0.04781","1,402.12854","0.0126","67.9101"
"3.00000","0.05156","1,461.14575","0.0137","70.7685"
"3.20000","0.05462","1,497.25391","0.0140","72.5173"
"3.40000","0.05856","1,555.70361","0.0149","75.3483"
"3.60000","0.06119","1,578.60571","0.0153","76.4575"
"3.80000","0.06481","1,630.96521","0.0162","78.9935"
"4.00000","0.06819","1,671.01770","0.0166","80.9333"
"4.20000","0.07131","1,707.63696","0.0175","82.7069"
"4.40000","0.07500","1,756.93726","0.0181","85.0947"
"4.60000","0.07794","1,785.63538","0.0184","86.4847"
"4.80000","0.08194","1,836.53479","0.0193","88.9499"
"5.00000","0.08437","1,854.14087","0.0193","89.8027"
"5.20000","0.08812","1,903.83936","0.0202","92.2097"
"5.40000","0.09137","1,935.53564","0.0208","93.7449"
"5.60000","0.09481","1,975.88391","0.0212","95.6991"
"5.80000","0.09825","2,013.82056","0.0222","97.5365"
"6.00000","0.10137","2,046.65527","0.0226","99.1268"
"6.20000","0.10512","2,087.76978","0.0230","101.1181"
"6.40000","0.10769","2,107.14233","0.0235","102.0564"
"6.60000","0.11162","2,157.02905","0.0245","104.4726"
"6.80000","0.11462","2,182.90649","0.0251","105.7259"
"7.00000","0.11837","2,227.90356","0.0257","107.9053"
"7.20000","0.12137","2,250.57739","0.0260","109.0035"
"7.40000","0.12475","2,288.83301","0.0267","110.8563"
"7.60000","0.12825","2,324.64185","0.0273","112.5907"
"7.80000","0.13112","2,346.70874","0.0273","113.6595"
"8.00000","0.13487","2,393.89624","0.0287","115.9449"
"8.20000","0.13800","2,416.65820","0.0285","117.0474"
"8.40000","0.14181","2,460.27539","0.0298","119.1599"
"8.60000","0.14450","2,475.93774","0.0297","119.9185"
"8.80000","0.14812","2,516.15137","0.0304","121.8662"
"9.00000","0.15156","2,549.95923","0.0311","123.5036"
"9.20000","0.15469","2,575.35913","0.0315","124.7338"
"9.40000","0.15831","2,616.27856","0.0325","126.7157"
"9.60000","0.16131","2,637.51562","0.0325","127.7443"
"9.80000","0.16525","2,679.26611","0.0335","129.7664"
"10.00000","0.16769","2,690.76562","0.0338","130.3234"
"10.20000","0.17150","2,733.61743","0.0346","132.3988"
"10.40000","0.17481","2,762.64819","0.0354","133.8049"
"10.60000","0.17819","2,794.89893","0.0357","135.3669"
"10.80000","0.18162","2,825.29468","0.0363","136.8391"
"11.00000","0.18469","2,850.23730","0.0366","138.0471"
"11.20000","0.18844","2,886.99854","0.0374","139.8276"
"11.40000","0.19106","2,901.22729","0.0376","140.5168"
"11.60000","0.19487","2,945.38110","0.0385","142.6553"
"11.80000","0.19806","2,968.49829","0.0390","143.7749"
"12.00000","0.20175","3,006.92285","0.0395","145.6360"
"12.20000","0.20469","3,023.14087","0.0399","146.4215"
"12.40000","0.20812","3,056.87402","0.0408","148.0553"
"12.60000","0.21156","3,088.28345","0.0412","149.5766"
"12.80000","0.21444","3,106.37427","0.0416","150.4528"
"13.00000","0.21831","3,150.79907","0.0421","152.6044"
"13.20000","0.22131","3,168.16455","0.0428","153.4455"
"13.40000","0.22519","3,208.31128","0.0434","155.3900"
"13.60000","0.22781","3,218.85693","0.0438","155.9007"
"13.80000","0.23144","3,254.61377","0.0443","157.6325"
"14.00000","0.23487","3,284.50659","0.0449","159.0804"
"14.20000","0.23800","3,305.26416","0.0455","160.0857"
"14.40000","0.24169","3,344.57422","0.0459","161.9897"
"14.60000","0.24475","3,362.11475","0.0465","162.8392"
"14.80000","0.24850","3,394.45020","0.0470","164.4053"
"15.00000","0.25106","3,404.53125","0.0472","164.8936"
"15.20000","0.25481","3,441.86646","0.0480","166.7019"
"15.40000","0.25806","3,465.50708","0.0484","167.8469"
"15.60000","0.26156","3,493.95435","0.0492","169.2247"
"15.80000","0.26494","3,520.16357","0.0495","170.4941"
"16.00000","0.26806","3,542.32349","0.0501","171.5674"
"16.20000","0.27175","3,573.90503","0.0511","173.0970"
"16.40000","0.27437","3,583.03296","0.0512","173.5391"
"16.60000","0.27819","3,620.91699","0.0519","175.3739"
"16.80000","0.28137","3,640.84717","0.0518","176.3392"
"17.00000","0.28500","3,673.56055","0.0528","177.9236"
"17.20000","0.28819","3,691.28955","0.0531","178.7823"
"17.40000","0.29137","3,714.30444","0.0538","179.8970"
"17.60000","0.29487","3,743.01123","0.0542","181.2874"
"17.80000","0.29781","3,756.99438","0.0544","181.9646"
"18.00000","0.30156","3,793.83032","0.0550","183.7487"
"18.20000","0.30462","3,809.04761","0.0555","184.4857"
"18.40000","0.30850","3,843.06079","0.0556","186.1331"
"18.60000","0.31119","3,850.50024","0.0563","186.4935"
"18.80000","0.31481","3,881.01270","0.0567","187.9713"
"19.00000","0.31819","3,904.08447","0.0575","189.0887"
"19.20000","0.32131","3,920.75415","0.0579","189.8961"
"19.40000","0.32500","3,953.54517","0.0585","191.4843"
"19.60000","0.32787","3,960.89819","0.0585","191.8404"
"19.80000","0.33194","3,992.91357","0.0589","193.3910"
"20.00000","0.33437","3,992.71021","0.0590","193.3812"
"20.20000","0.33812","4,023.65576","0.0598","194.8800"
"20.40000","0.34150","4,042.82593","0.0600","195.8085"
"20.60000","0.34481","4,063.21240","0.0604","196.7959"
"20.80000","0.34825","4,087.89258","0.0608","197.9912"
"21.00000","0.35137","4,103.03711","0.0612","198.7247"
"21.20000","0.35506","4,127.67969","0.0617","199.9182"
"21.40000","0.35769","4,133.43506","0.0617","200.1970"
"21.60000","0.36156","4,167.70312","0.0626","201.8567"
"21.80000","0.36469","4,179.88037","0.0627","202.4465"
"22.00000","0.36837","4,207.21729","0.0633","203.7705"
"22.20000","0.37131","4,216.36328","0.0634","204.2135"
"22.40000","0.37475","4,237.72217","0.0639","205.2480"
"22.60000","0.37831","4,258.40137","0.0644","206.2496"
"22.80000","0.38112","4,263.68213","0.0645","206.5053"
"23.00000","0.38487","4,296.75732","0.0654","208.1073"
"23.20000","0.38800","4,306.76904","0.0655","208.5922"
"23.40000","0.39181","4,335.44092","0.0662","209.9809"
"23.60000","0.39450","4,341.52148","0.0662","210.2754"
"23.80000","0.39812","4,368.65771","0.0666","211.5897"
"24.00000","0.40156","4,390.51416","0.0670","212.6483"
"24.20000","0.40462","4,404.40430","0.0672","213.3210"
"24.40000","0.40831","4,434.49414","0.0680","214.7784"
"24.60000","0.41131","4,443.92725","0.0682","215.2352"
"24.80000","0.41525","4,470.27734","0.0686","216.5115"
"25.00000","0.41769","4,471.67529","0.0688","216.5792"
"25.20000","0.42150","4,501.95215","0.0695","218.0456"
"25.40000","0.42487","4,519.28760","0.0701","218.8852"
"25.60000","0.42819","4,536.77295","0.0700","219.7321"
"25.80000","0.43162","4,557.79150","0.0706","220.7501"
"26.00000","0.43469","4,571.69580","0.0709","221.4235"
"26.20000","0.43850","4,597.02148","0.0711","222.6501"
"26.40000","0.44106","4,599.75244","0.0715","222.7824"
"26.60000","0.44481","4,632.28711","0.0720","224.3582"
"26.80000","0.44800","4,643.56885","0.0722","224.9046"
"27.00000","0.45175","4,670.38672","0.0729","226.2035"
"27.20000","0.45462","4,677.52246","0.0730","226.5491"
"27.40000","0.45812","4,700.84326","0.0737","227.6786"
"27.60000","0.46156","4,719.75146","0.0739","228.5944"
"27.80000","0.46444","4,728.00830","0.0741","228.9943"
"28.00000","0.46831","4,763.71484","0.0746","230.7237"
"28.20000","0.47131","4,772.38623","0.0749","231.1437"
"28.40000","0.47525","4,804.59131","0.0759","232.7035"
"28.60000","0.47787","4,806.15869","0.0759","232.7794"
"28.80000","0.48144","4,832.82520","0.0763","234.0710"
"29.00000","0.48487","4,853.69482","0.0766","235.0817"
"29.20000","0.48794","4,866.56982","0.0767","235.7053"
"29.40000","0.49162","4,897.94336","0.0776","237.2249"
"29.60000","0.49469","4,907.76465","0.0780","237.7005"
"29.80000","0.49850","4,933.64600","0.0784","238.9541"
"30.00000","0.50106","4,938.46143","0.0786","239.1873"
"30.20000","0.50481","4,967.36475","0.0788","240.5872"
"30.40000","0.50806","4,983.96387","0.0796","241.3911"
"30.60000","0.51156","5,007.59619","0.0800","242.5357"
"30.80000","0.51494","5,026.06201","0.0804","243.4301"
"31.00000","0.51806","5,041.13916","0.0806","244.1603"
"31.20000","0.52181","5,064.15869","0.0813","245.2753"
"31.40000","0.52437","5,066.30664","0.0816","245.3793"
"31.60000","0.52819","5,098.30713","0.0821","246.9292"
"31.80000","0.53137","5,110.92969","0.0820","247.5405"
"32.00000","0.53506","5,137.27686","0.0826","248.8166"
"32.20000","0.53812","5,144.98486","0.0826","249.1900"
"32.40000","0.54137","5,163.58447","0.0834","250.0908"
"32.60000","0.54481","5,185.54492","0.0840","251.1544"
"32.80000","0.54787","5,195.02246","0.0841","251.6134"
"33.00000","0.55156","5,224.22021","0.0844","253.0276"
"33.20000","0.55462","5,235.59277","0.0853","253.5784"
"33.40000","0.55856","5,264.61279","0.0856","254.9840"
"33.60000","0.56119","5,265.75391","0.0854","255.0392"
"33.80000","0.56481","5,292.53760","0.0858","256.3365"
"34.00000","0.56812","5,309.49316","0.0863","257.1577"
"34.20000","0.57131","5,323.69336","0.0870","257.8454"
"34.40000","0.57494","5,350.41260","0.0873","259.1396"
"34.60000","0.57794","5,361.10107","0.0877","259.6572"
"34.80000","0.58194","5,390.57373","0.0882","261.0847"
"35.00000","0.58437","5,391.41650","0.0883","261.1255"
"35.20000","0.58812","5,422.58984","0.0890","262.6353"
"35.40000","0.59150","5,439.99609","0.0892","263.4784"
"35.60000","0.59481","5,461.38477","0.0897","264.5143"
"35.80000","0.59825","5,483.36035","0.0899","265.5787"
"36.00000","0.60137","5,499.54590","0.0904","266.3626"
"36.20000","0.60512","5,523.29785","0.0911","267.5130"
"36.40000","0.60769","5,528.51221","0.0912","267.7655"
"36.60000","0.61156","5,563.81494","0.0919","269.4754"
"36.80000","0.61469","5,575.70557","0.0924","270.0513"
"37.00000","0.61837","5,604.83057","0.0926","271.4619"
"37.20000","0.62137","5,615.97705","0.0929","272.0018"
"37.40000","0.62475","5,640.34424","0.0938","273.1820"
"37.60000","0.62825","5,660.95410","0.0940","274.1802"
"37.80000","0.63112","5,667.09912","0.0946","274.4778"
"38.00000","0.63494","5,700.70312","0.0950","276.1054"
"38.20000","0.63800","5,712.11768","0.0949","276.6582"
"38.40000","0.64181","5,741.61816","0.0958","278.0870"
"38.60000","0.64450","5,746.04639","0.0957","278.3015"
"38.80000","0.64812","5,772.31104","0.0963","279.5736"
"39.00000","0.65156","5,793.42773","0.0967","280.5963"
"39.20000","0.65462","5,807.69141","0.0972","281.2872"
"39.40000","0.65831","5,836.60986","0.0979","282.6878"
"39.60000","0.66131","5,847.42871","0.0984","283.2118"
"39.80000","0.66525","5,877.58203","0.0988","284.6722"
"40.00000","0.66769","5,879.37451","0.0989","284.7591"
"40.20000","0.67150","5,911.16162","0.0996","286.2986"
"40.40000","0.67487","5,927.61426","0.0998","287.0955"
"40.60000","0.67819","5,947.62402","0.1005","288.0646"
"40.80000","0.68169","5,967.07422","0.1006","289.0067"
"41.00000","0.68462","5,980.85547","0.1011","289.6741"
"41.20000","0.68850","6,007.69043","0.1018","290.9738"
"41.40000","0.69106","6,012.37939","0.1019","291.2010"
"41.60000","0.69487","6,046.89502","0.1021","292.8727"
"41.80000","0.69806","6,061.20557","0.1028","293.5658"
"42.00000","0.70169","6,087.28809","0.1035","294.8290"
"42.20000","0.70462","6,095.01025","0.1035","295.2031"
"42.40000","0.70812","6,119.75928","0.1041","296.4018"
"42.60000","0.71144","6,138.98193","0.1045","297.3328"
"42.80000","0.71444","6,149.95850","0.1046","297.8644"
"43.00000","0.71831","6,184.08740","0.1057","299.5174"
"43.20000","0.72131","6,193.76172","0.1059","299.9860"
"43.40000","0.72525","6,224.00049","0.1067","301.4505"
"43.60000","0.72787","6,226.93945","0.1065","301.5929"
"43.80000","0.73144","6,254.17090","0.1071","302.9118"
"44.00000","0.73494","6,275.14697","0.1076","303.9277"
"44.20000","0.73800","6,289.12354","0.1080","304.6047"
"44.40000","0.74169","6,318.77490","0.1088","306.0408"
"44.60000","0.74469","6,332.56592","0.1089","306.7087"
"44.80000","0.74850","6,357.87109","0.1096","307.9344"
"45.00000","0.75106","6,362.86426","0.1099","308.1762"
"45.20000","0.75475","6,391.32861","0.1100","309.5548"
"45.40000","0.75806","6,407.68311","0.1105","310.3469"
"45.60000","0.76156","6,432.73730","0.1108","311.5604"
"45.80000","0.76494","6,451.01514","0.1116","312.4456"
"46.00000","0.76806","6,469.85791","0.1120","313.3583"
"46.20000","0.77181","6,494.14746","0.1124","314.5347"
"46.40000","0.77437","6,497.31152","0.1127","314.6880"
"46.60000","0.77819","6,530.20752","0.1133","316.2812"
"46.80000","0.78137","6,543.91504","0.1136","316.9451"
"47.00000","0.78506","6,573.27002","0.1140","318.3669"
"47.20000","0.78812","6,581.95850","0.1143","318.7877"
"47.40000","0.79144","6,605.70020","0.1150","319.9376"
"47.60000","0.79487","6,629.26758","0.1154","321.0790"
"47.80000","0.79781","6,640.50293","0.1161","321.6232"
"48.00000","0.80150","6,674.26660","0.1165","323.2585"
"48.20000","0.80462","6,687.86914","0.1170","323.9173"
"48.40000","0.80850","6,719.66309","0.1175","325.4572"
"48.60000","0.81112","6,721.62109","0.1178","325.5521"
"48.80000","0.81481","6,752.48975","0.1185","327.0471"
"49.00000","0.81812","6,772.15381","0.1186","327.9995"
"49.20000","0.82131","6,788.59033","0.1191","328.7956"
"49.40000","0.82506","6,817.38623","0.1196","330.1903"
"49.60000","0.82794","6,829.56445","0.1198","330.7802"
"49.80000","0.83194","6,862.03516","0.1207","332.3528"
"50.00000","0.83437","6,864.80469","0.1208","332.4870"
"50.20000","0.83819","6,898.76318","0.1216","334.1317"
"50.40000","0.84150","6,914.90381","0.1221","334.9134"
"50.60000","0.84481","6,938.44629","0.1221","336.0537"
"50.80000","0.84819","6,959.26709","0.1229","337.0621"
"51.00000","0.85137","6,979.95410","0.1235","338.0641"
"51.20000","0.85506","7,004.83545","0.1239","339.2691"
"51.40000","0.85769","7,012.01172","0.1243","339.6167"
"51.60000","0.86156","7,047.42578","0.1248","341.3319"
"51.80000","0.86469","7,061.11572","0.1252","341.9950"
"52.00000","0.86837","7,092.83301","0.1259","343.5312"
"52.20000","0.87137","7,102.57568","0.1259","344.0031"
"52.40000","0.87475","7,130.21436","0.1269","345.3417"
"52.60000","0.87831","7,154.21729","0.1276","346.5042"
"52.80000","0.88112","7,165.10791","0.1275","347.0317"
"53.00000","0.88494","7,200.72559","0.1283","348.7568"
"53.20000","0.88800","7,214.80322","0.1289","349.4386"
"53.40000","0.89181","7,246.89648","0.1294","350.9930"
"53.60000","0.89450","7,252.66699","0.1296","351.2725"
"53.80000","0.89812","7,284.83203","0.1304","352.8304"
"54.00000","0.90156","7,308.57031","0.1310","353.9801"
"54.20000","0.90462","7,325.17773","0.1316","354.7845"
"54.40000","0.90831","7,355.29492","0.1319","356.2431"
"54.60000","0.91137","7,370.43896","0.1324","356.9766"
"54.80000","0.91531","7,402.48242","0.1329","358.5286"
"55.00000","0.91769","7,404.40625","0.1332","358.6218"
"55.20000","0.92150","7,440.86719","0.1341","360.3877"
"55.40000","0.92487","7,462.65576","0.1340","361.4430"
"55.60000","0.92819","7,487.31104","0.1350","362.6371"
"55.80000","0.93162","7,507.55957","0.1355","363.6179"
"56.00000","0.93462","7,525.85742","0.1357","364.5041"
"56.20000","0.93844","7,556.28418","0.1363","365.9778"
"56.40000","0.94106","7,563.03613","0.1367","366.3048"
"56.60000","0.94487","7,599.61963","0.1375","368.0767"
"56.80000","0.94806","7,616.77832","0.1377","368.9077"
"57.00000","0.95175","7,649.33984","0.1386","370.4848"
"57.20000","0.95462","7,657.17334","0.1389","370.8642"
"57.40000","0.95812","7,687.57910","0.1392","372.3369"
"57.60000","0.96156","7,710.21826","0.1402","373.4333"
"57.80000","0.96444","7,724.30078","0.1403","374.1154"
"58.00000","0.96825","7,760.39307","0.1408","375.8635"
"58.20000","0.97131","7,774.19336","0.1413","376.5319"
"58.40000","0.97525","7,808.35449","0.1420","378.1864"
"58.60000","0.97781","7,811.69385","0.1419","378.3482"
"58.80000","0.98144","7,845.08887","0.1428","379.9656"
"59.00000","0.98487","7,870.55029","0.1435","381.1988"
"59.20000","0.98794","7,889.03320","0.1439","382.0940"
"59.40000","0.99169","7,918.84082","0.1445","383.5377"
"59.60000","0.99475","7,936.17285","0.1451","384.3771"
"59.80000","0.99850","7,963.16650","0.1459","385.6845"
"60.00000","1.00106","7,970.70508","0.1459","386.0497"
"60.20000","1.00481","8,005.28516","0.1467","387.7245"
"60.40000","1.00812","8,024.29395","0.1470","388.6451"
"60.60000","1.01150","8,051.63477","0.1475","389.9694"
"60.80000","1.01494","8,071.37109","0.1480","390.9253"
"61.00000","1.01806","8,093.91602","0.1484","392.0172"
"61.20000","1.02181","8,122.20410","0.1492","393.3873"
"61.40000","1.02437","8,129.93213","0.1494","393.7616"
"61.60000","1.02819","8,167.15527","0.1501","395.5644"
"61.80000","1.03137","8,184.85986","0.1506","396.4219"
"62.00000","1.03506","8,219.22754","0.1513","398.0865"
"62.20000","1.03812","8,230.58594","0.1514","398.6366"
"62.40000","1.04137","8,257.43164","0.1526","399.9368"
"62.60000","1.04487","8,283.54980","0.1527","401.2018"
"62.80000","1.04781","8,298.28516","0.1534","401.9155"
"63.00000","1.05156","8,332.86719","0.1539","403.5905"
"63.20000","1.05469","8,347.78613","0.1543","404.3130"
"63.40000","1.05850","8,382.63965","0.1552","406.0011"
"63.60000","1.06112","8,387.40430","0.1552","406.2319"
"63.80000","1.06481","8,421.95898","0.1559","407.9055"
"64.00000","1.06812","8,443.66211","0.1567","408.9566"
"64.20000","1.07131","8,465.53906","0.1571","410.0162"
"64.40000","1.07500","8,495.74316","0.1575","411.4791"
"64.60000","1.07800","8,511.63770","0.1579","412.2489"
"64.80000","1.08194","8,545.38574","0.1589","413.8835"
"65.00000","1.08437","8,549.71094","0.1591","414.0930"
"65.20000","1.08812","8,585.17773","0.1596","415.8108"
"65.40000","1.09156","8,606.51855","0.1599","416.8444"
"65.60000","1.09481","8,631.26758","0.1606","418.0431"
"65.80000","1.09825","8,653.35742","0.1612","419.1129"
"66.00000","1.10137","8,676.95410","0.1618","420.2558"
"66.20000","1.10506","8,705.70801","0.1621","421.6485"
"66.40000","1.10769","8,714.80859","0.1627","422.0892"
"66.60000","1.11156","8,752.58887","0.1633","423.9191"
"66.80000","1.11469","8,769.37988","0.1637","424.7323"
"67.00000","1.11837","8,801.79590","0.1645","426.3023"
"67.20000","1.12137","8,813.47266","0.1647","426.8679"
"67.40000","1.12475","8,842.95215","0.1655","428.2957"
"67.60000","1.12825","8,868.19922","0.1659","429.5185"
"67.80000","1.13106","8,881.52832","0.1666","430.1641"
"68.00000","1.13494","8,919.02441","0.1672","431.9801"
"68.20000","1.13800","8,934.18457","0.1676","432.7144"
"68.40000","1.14181","8,968.41602","0.1683","434.3723"
"68.60000","1.14450","8,974.62305","0.1683","434.6730"
"68.80000","1.14812","9,007.75781","0.1693","436.2778"
"69.00000","1.15162","9,033.12598","0.1697","437.5065"
"69.20000","1.15462","9,050.29883","0.1700","438.3382"
"69.40000","1.15831","9,080.74121","0.1706","439.8127"
"69.60000","1.16131","9,098.54688","0.1710","440.6750"
"69.80000","1.16525","9,131.79102","0.1717","442.2852"
"70.00000","1.16769","9,137.39551","0.1720","442.5566"
"70.20000","1.17150","9,174.82520","0.1729","444.3695"
"70.40000","1.17487","9,197.10156","0.1733","445.4484"
"70.60000","1.17819","9,222.89062","0.1743","446.6974"
"70.80000","1.18156","9,244.06934","0.1742","447.7232"
"71.00000","1.18469","9,267.05371","0.1750","448.8364"
"71.14800","1.18744","9,291.30469","0.1753","450.0110"
"92.38200","1.18825","9,090.80176","0.1784","440.2999"
"92.58200","1.19106","9,145.12012","0.1893","442.9308"
"92.78200","1.19575","9,267.16309","0.2073","448.8417"
"92.98200","1.19931","9,341.69434","0.2210","452.4515"
"93.18200","1.20231","9,399.94629","0.2325","455.2729"
"93.38200","1.20606","9,451.00293","0.2469","457.7458"
"93.58200","1.20912","9,459.09668","0.2587","458.1378"
"93.78200","1.21294","9,474.47168","0.2734","458.8824"
"93.98200","1.21544","9,466.83398","0.2830","458.5125"
"94.18200","1.21919","9,499.03418","0.2974","460.0721"
"94.38200","1.22256","9,521.99707","0.3104","461.1843"
"94.58200","1.22594","9,549.59961","0.3234","462.5211"
"94.78200","1.22937","9,569.83301","0.3366","463.5011"
"94.98200","1.23244","9,591.89453","0.3484","464.5696"
"95.18200","1.23625","9,623.55664","0.3631","466.1031"
"95.38200","1.23869","9,630.40527","0.3724","466.4348"
"95.58200","1.24262","9,670.49414","0.3876","468.3765"
"95.78200","1.24575","9,688.32715","0.3996","469.2402"
"95.98200","1.24944","9,724.08496","0.4138","470.9721"
"96.18200","1.25256","9,737.63672","0.4258","471.6284"
"96.38200","1.25581","9,765.50488","0.4383","472.9782"
"96.58200","1.25925","9,793.95215","0.4515","474.3560"
"96.78200","1.26219","9,810.74902","0.4628","475.1695"
"96.98200","1.26587","9,847.96191","0.4770","476.9719"
"97.18200","1.26912","9,867.08301","0.4895","477.8980"
"97.38200","1.27294","9,902.49121","0.5042","479.6129"
"97.58200","1.27562","9,908.61133","0.5145","479.9094"
"97.78200","1.27925","9,944.81055","0.5284","481.6626"
"97.98200","1.28256","9,968.10742","0.5412","482.7910"
"98.18200","1.28569","9,989.81934","0.5532","483.8426"
"98.38200","1.28944","10,024.60547","0.5676","485.5274"
"98.58200","1.29237","10,038.97656","0.5789","486.2234"
"98.78200","1.29631","10,074.78711","0.5941","487.9579"
"98.98200","1.29875","10,080.77441","0.6034","488.2478"
"99.18200","1.30256","10,118.86230","0.6181","490.0926"
"99.38200","1.30594","10,142.51074","0.6311","491.2379"
"99.58200","1.30912","10,167.46191","0.6433","492.4464"
"99.78200","1.31269","10,194.03125","0.6570","493.7333"
"99.98200","1.31581","10,215.66797","0.6691","494.7812"
"100.18200","1.31956","10,245.84863","0.6835","496.2430"
"100.38200","1.32212","10,256.91113","0.6933","496.7787"
"100.58200","1.32594","10,295.42285","0.7080","498.6440"
"100.78200","1.32906","10,312.84668","0.7200","499.4879"
"100.98200","1.33275","10,350.89844","0.7342","501.3309"
"101.18200","1.33575","10,362.50000","0.7457","501.8928"
"101.38200","1.33912","10,393.00977","0.7587","503.3705"
"101.58200","1.34287","10,425.24316","0.7731","504.9317"
"101.78200","1.34544","10,434.97168","0.7830","505.4029"
"101.98200","1.34931","10,474.69824","0.7979","507.3270"
"102.18200","1.35244","10,492.13574","0.8099","508.1715"
"102.38200","1.35625","10,529.85840","0.8246","509.9986"
"102.58200","1.35894","10,536.14355","0.8349","510.3030"
"102.78200","1.36256","10,571.85352","0.8489","512.0325"
"102.98200","1.36600","10,598.18066","0.8621","513.3077"
"103.18200","1.36900","10,617.45312","0.8736","514.2411"
"103.38200","1.37262","10,650.20801","0.8876","515.8275"
"103.58200","1.37575","10,669.80566","0.8996","516.7767"
"103.78200","1.37962","10,705.34473","0.9145","518.4980"
"103.98200","1.38206","10,711.16309","0.9239","518.7798"
"104.18200","1.38594","10,751.24023","0.9388","520.7209"
"104.38200","1.38919","10,773.61816","0.9513","521.8047"
"104.58200","1.39250","10,802.68848","0.9640","523.2127"
"104.78200","1.39606","10,827.19824","0.9777","524.3998"
"104.98200","1.39906","10,849.33105","0.9893","525.4717"
"105.18200","1.40287","10,883.17285","1.0039","527.1108"
"105.38200","1.40544","10,892.50879","1.0138","527.5630"
"105.58200","1.40925","10,931.75000","1.0284","529.4636"
"105.78200","1.41256","10,954.26172","1.0412","530.5540"
"105.98200","1.41606","10,986.87793","1.0546","532.1337"
"106.18200","1.41912","11,000.43652","1.0664","532.7903"
"106.38200","1.42244","11,032.23926","1.0792","534.3307"
"106.58200","1.42600","11,061.05176","1.0929","535.7261"
"106.78200","1.42881","11,076.99805","1.1037","536.4985"
"106.98200","1.43256","11,114.24219","1.1181","538.3024"
"107.18200","1.43575","11,132.23828","1.1304","539.1740"
"107.38200","1.43962","11,171.11328","1.1453","541.0568"
"107.58200","1.44219","11,176.13379","1.1551","541.3000"
"107.78200","1.44581","11,212.91699","1.1691","543.0815"
"107.98200","1.44937","11,242.26172","1.1828","544.5028"
"108.18200","1.45231","11,261.35156","1.1941","545.4274"
"108.38200","1.45612","11,297.01562","1.2087","547.1547"
"108.58200","1.45912","11,315.61035","1.2203","548.0554"
"108.78200","1.46294","11,350.02930","1.2349","549.7224"
"108.98200","1.46544","11,357.68262","1.2445","550.0930"
"109.18200","1.46919","11,395.18555","1.2590","551.9094"
"109.38200","1.47250","11,420.58496","1.2717","553.1396"
"109.58200","1.47587","11,451.99512","1.2847","554.6609"
"109.78200","1.47931","11,474.03906","1.2979","555.7286"
"109.98200","1.48237","11,499.44531","1.3097","556.9591"
"110.18200","1.48625","11,533.23828","1.3246","558.5958"
"110.38200","1.48875","11,542.14453","1.3342","559.0272"
"110.58200","1.49262","11,582.83691","1.3491","560.9980"
"110.78200","1.49581","11,603.78027","1.3614","562.0125"
"110.98200","1.49944","11,641.09473","1.3753","563.8197"
"111.18200","1.50256","11,655.61328","1.3873","564.5229"
"111.38200","1.50581","11,684.47852","1.3998","565.9210"
"111.58200","1.50931","11,713.48535","1.4133","567.3259"
"111.78200","1.51219","11,730.79102","1.4244","568.1640"
"111.98200","1.51587","11,768.32715","1.4385","569.9820"
"112.18200","1.51906","11,789.56836","1.4508","571.0108"
"112.38200","1.52281","11,825.50000","1.4652","572.7511"
"112.58200","1.52556","11,835.10840","1.4758","573.2165"
"112.78200","1.52925","11,871.91211","1.4900","574.9990"
"112.98200","1.53256","11,897.48535","1.5027","576.2376"
"113.18200","1.53569","11,921.09668","1.5147","577.3812"
"113.38200","1.53950","11,957.39844","1.5294","579.1394"
"113.58200","1.54237","11,972.04297","1.5405","579.8487"
"113.78200","1.54637","12,010.78906","1.5558","581.7253"
"113.98200","1.54881","12,017.87793","1.5652","582.0687"
"114.18200","1.55256","12,055.91406","1.5796","583.9109"
"114.38200","1.55594","12,081.76855","1.5926","585.1631"
"114.58200","1.55912","12,109.41504","1.6049","586.5021"
"114.78200","1.56269","12,134.75879","1.6186","587.7296"
"114.98200","1.56575","12,158.09473","1.6304","588.8599"
"115.18200","1.56950","12,191.31348","1.6448","590.4688"
"115.38200","1.57212","12,204.10156","1.6549","591.0881"
"115.58200","1.57594","12,243.37793","1.6695","592.9904"
"115.78200","1.57912","12,263.58496","1.6818","593.9691"
"115.98200","1.58275","12,302.07422","1.6957","595.8333"
"116.18200","1.58581","12,315.10840","1.7075","596.4646"
"116.38200","1.58912","12,347.62598","1.7203","598.0396"
"116.58200","1.59287","12,381.43750","1.7347","599.6771"
"116.78200","1.59544","12,392.62012","1.7445","600.2188"
"116.98200","1.59931","12,433.29395","1.7594","602.1887"
"117.18200","1.60244","12,451.92773","1.7715","603.0912"
"117.38200","1.60619","12,491.01562","1.7859","604.9844"
"117.58200","1.60887","12,497.80566","1.7962","605.3133"
"117.78200","1.61250","12,535.45996","1.8102","607.1370"
"117.98200","1.61600","12,564.84277","1.8236","608.5601"
"118.18200","1.61900","12,585.19434","1.8352","609.5458"
"118.38200","1.62262","12,618.65527","1.8491","611.1664"
"118.58200","1.62581","12,640.14844","1.8614","612.2075"
"118.78200","1.62962","12,675.75195","1.8760","613.9318"
"118.98200","1.63212","12,682.98047","1.8856","614.2819"
"119.18200","1.63594","12,724.57812","1.9003","616.2967"
"119.38200","1.63919","12,747.74219","1.9128","617.4186"
"119.58200","1.64250","12,777.07227","1.9256","618.8392"
"119.78200","1.64612","12,804.03711","1.9395","620.1451"
"119.98200","1.64906","12,827.40820","1.9508","621.2771"
"120.18200","1.65287","12,861.74023","1.9655","622.9399"
"120.38200","1.65544","12,872.37988","1.9753","623.4553"
"120.58200","1.65925","12,912.65039","1.9900","625.4057"
"120.78200","1.66256","12,936.47559","2.0027","626.5596"
"120.98200","1.66600","12,970.40723","2.0159","628.2031"
"121.18200","1.66912","12,985.58398","2.0280","628.9381"
"121.38200","1.67250","13,019.12793","2.0409","630.5627"
"121.58200","1.67600","13,049.01270","2.0544","632.0102"
"121.78200","1.67881","13,066.25000","2.0652","632.8450"
"121.98200","1.68256","13,104.55957","2.0796","634.7005"
"122.18200","1.68575","13,124.45996","2.0919","635.6644"
"122.38200","1.68962","13,164.83789","2.1068","637.6200"
"122.58200","1.69225","13,171.08887","2.1169","637.9228"
"122.78200","1.69587","13,209.84668","2.1308","639.7999"
"122.98200","1.69931","13,239.25391","2.1441","641.2242"
"123.18200","1.70231","13,259.16211","2.1556","642.1885"
"123.38200","1.70606","13,294.30078","2.1700","643.8904"
"123.58200","1.70912","13,316.59863","2.1818","644.9703"
"123.78200","1.71294","13,350.88184","2.1965","646.6308"
"123.98200","1.71544","13,360.01758","2.2061","647.0732"
"124.18200","1.71919","13,398.00977","2.2205","648.9133"
"124.38200","1.72256","13,423.95801","2.2335","650.1701"
"124.58200","1.72587","13,456.57422","2.2462","651.7498"
"124.78200","1.72931","13,478.19434","2.2594","652.7970"
"124.98200","1.73244","13,505.29492","2.2715","654.1096"
"125.18200","1.73619","13,538.75586","2.2859","655.7302"
"125.38200","1.73875","13,550.18652","2.2957","656.2838"
"125.58200","1.74256","13,591.13867","2.3104","658.2673"
"125.78200","1.74581","13,612.88086","2.3229","659.3203"
"125.98200","1.74944","13,651.15039","2.3369","661.1739"
"126.18200","1.75256","13,664.76758","2.3489","661.8334"
"126.38200","1.75581","13,695.36523","2.3614","663.3154"
"126.58200","1.75931","13,724.98828","2.3748","664.7501"
"126.78200","1.76219","13,743.59473","2.3859","665.6512"
"126.98200","1.76587","13,781.85645","2.4001","667.5044"
"127.18200","1.76912","13,803.32129","2.4126","668.5441"
"127.38200","1.77287","13,839.72949","2.4270","670.3074"
"127.58200","1.77556","13,847.65527","2.4373","670.6913"
"127.78200","1.77919","13,885.22656","2.4513","672.5110"
"127.98200","1.78250","13,911.60059","2.4640","673.7884"
"128.18400","1.78569","13,937.62207","2.4763","675.0487"
"128.38400","1.78944","13,974.17383","2.4907","676.8190"
"128.58400","1.79244","13,990.33203","2.5022","677.6016"
"128.78400","1.79631","14,027.85449","2.5171","679.4190"
"128.98400","1.79881","14,036.86816","2.5268","679.8555"
"129.18400","1.80256","14,075.93652","2.5412","681.7477"
"129.38400","1.80600","14,103.25879","2.5544","683.0711"
"129.58400","1.80919","14,130.09766","2.5667","684.3710"
"129.78400","1.81269","14,157.50391","2.5801","685.6984"
"129.98400","1.81581","14,183.35742","2.5921","686.9506"
"130.18400","1.81956","14,215.75293","2.6066","688.5196"
"130.38400","1.82212","14,228.08594","2.6164","689.1169"
"130.58400","1.82594","14,269.56055","2.6311","691.1257"
"130.78400","1.82912","14,291.40723","2.6433","692.1838"
"130.98400","1.83275","14,329.94043","2.6573","694.0501"
"131.18400","1.83581","14,344.35547","2.6691","694.7482"
"131.38400","1.83919","14,378.12109","2.6820","696.3837"
"131.58400","1.84287","14,411.94824","2.6962","698.0220"
"131.78400","1.84550","14,425.05762","2.7063","698.6569"
"131.98400","1.84931","14,467.51465","2.7210","700.7133"
"132.18400","1.85244","14,488.98047","2.7330","701.7529"
"132.38400","1.85619","14,528.58594","2.7474","703.6712"
"132.58400","1.85900","14,539.48438","2.7582","704.1990"
"132.78400","1.86256","14,578.57812","2.7719","706.0925"
"132.98400","1.86606","14,610.14551","2.7854","707.6214"
"133.18400","1.86900","14,632.14648","2.7967","708.6870"
"133.38400","1.87262","14,667.17285","2.8107","710.3834"
"133.58400","1.87581","14,691.38672","2.8229","711.5562"
"133.78400","1.87962","14,729.42383","2.8376","713.3985"
"133.98400","1.88212","14,738.34473","2.8472","713.8306"
"134.18400","1.88594","14,780.11133","2.8619","715.8535"
"134.38400","1.88925","14,806.22754","2.8746","717.1183"
"134.58400","1.89256","14,836.29395","2.8873","718.5746"
"134.78400","1.89612","14,865.46289","2.9010","719.9874"
"134.98400","1.89912","14,889.70508","2.9126","721.1615"
"135.18400","1.90294","14,926.03418","2.9272","722.9210"
"135.38400","1.90550","14,937.54492","2.9371","723.4785"
"135.58400","1.90931","14,979.38379","2.9518","725.5049"
"135.78400","1.91262","15,004.39453","2.9645","726.7163"
"135.98400","1.91600","15,037.92969","2.9775","728.3405"
"136.18400","1.91912","15,054.08105","2.9895","729.1228"
"136.38400","1.92250","15,087.58496","3.0025","730.7455"
"136.58400","1.92600","15,118.01367","3.0159","732.2193"
"136.78400","1.92881","15,135.99902","3.0268","733.0904"
"136.98400","1.93256","15,175.36035","3.0412","734.9968"
"137.18400","1.93581","15,197.63965","3.0537","736.0759"
"137.38400","1.93962","15,237.53711","3.0683","738.0082"
"137.58400","1.94225","15,242.70898","3.0784","738.2587"
"137.78400","1.94587","15,283.13281","3.0924","740.2166"
"137.98400","1.94937","15,313.41992","3.1058","741.6835"
"138.18400","1.95231","15,333.05762","3.1171","742.6346"
"138.38400","1.95612","15,369.82520","3.1318","744.4154"
"138.58400","1.95919","15,392.45801","3.1436","745.5116"
"138.78400","1.96294","15,426.79395","3.1580","747.1746"
"138.98400","1.96544","15,435.14551","3.1676","747.5791"
"139.18400","1.96919","15,473.45703","3.1820","749.4347"
"139.38400","1.97256","15,501.52441","3.1950","750.7941"
"139.58400","1.97594","15,533.65918","3.2080","752.3505"
"139.78400","1.97937","15,557.31152","3.2212","753.4960"
"139.98400","1.98250","15,584.82520","3.2332","754.8286"
"140.18400","1.98631","15,620.42578","3.2479","756.5529"
"140.38400","1.98875","15,630.88281","3.2573","757.0594"
"140.58400","1.99262","15,671.31836","3.2722","759.0178"
"140.78400","1.99587","15,695.72656","3.2847","760.2000"
"140.98400","1.99944","15,731.82617","3.2984","761.9484"
"141.18400","2.00256","15,747.47754","3.3104","762.7065"
"141.38400","2.00581","15,778.49121","3.3229","764.2086"
"141.58400","2.00925","15,808.91602","3.3361","765.6821"
"141.78400","2.01219","15,829.84473","3.3474","766.6958"
"141.98400","2.01587","15,867.14941","3.3616","768.5026"
"142.18400","2.01912","15,890.83105","3.3741","769.6496"
"142.38400","2.02294","15,929.56934","3.3888","771.5258"
"142.58400","2.02562","15,937.28613","3.3991","771.8995"
"142.78400","2.02925","15,976.80762","3.4131","773.8137"
"142.98400","2.03269","16,004.26562","3.4263","775.1436"
"143.18400","2.03569","16,027.41309","3.4378","776.2647"
"143.38400","2.03950","16,064.38281","3.4525","778.0553"
"143.58400","2.04244","16,081.58496","3.4638","778.8885"
"143.65800","2.04437","15,480.69434","3.4712","749.7852"
"143.66200","2.04512","14,243.34668","3.4741","689.8560"
"143.66600","2.04594","12,631.22363","3.4772","611.7751"
"143.67000","2.04687","10,822.69727","3.4808","524.1818"
"143.67400","2.04781","8,983.07031","3.4844","435.0821"