File: data/Long/Specimen_RawData_10.csv
Specimen number (included),10
Modulus (Automatic Young's),"268,515.51151",MPa
Length,"26.00000",mm
Specimen ID,"0039"
Thickness,"2.03600",mm
Width,"10.11000",mm
Tensile stress at Tensile strength,"805.47852",MPa
Tensile strain (Strain 1) at Tensile strength,"0.03601",mm/mm

Time,Extension,Load,Tensile strain (Strain 1),Tensile stress
(s),(mm),(N),(%),(MPa)
"0.00000","-0.00169","496.73795","-0.0012","24.1323"
"0.20000","0.00000","524.19006","-0.0006","25.4659"
"0.40000","0.00487","659.23511","0.0017","32.0266"
"0.60000","0.00825","733.34717","0.0032","35.6271"
"0.80000","0.01162","810.86157","0.0043","39.3929"
"1.00000","0.01519","875.28442","0.0055","42.5226"
"1.20000","0.01819","932.64136","0.0065","45.3091"
"1.40000","0.02206","999.78448","0.0079","48.5710"
"1.60000","0.02450","1,039.19800","0.0084","50.4858"
"1.80000","0.02844","1,108.12952","0.0097","53.8346"
"2.00000","0.03156","1,152.12561","0.0101","55.9720"
"2.20000","0.03519","1,213.71716","0.0113","58.9642"
"2.40000","0.03837","1,253.23181","0.0122","60.8839"
"2.60000","0.04156","1,299.82092","0.0130","63.1473"
"2.80000","0.04506","1,348.22839","0.0140","65.4990"
"3.00000","0.04794","1,381.95496","0.0146","67.1375"
"3.20000","0.05169","1,436.34338","0.0153","69.7797"
"3.40000","0.05481","1,469.57666","0.0161","71.3943"
"3.60000","0.05869","1,521.35547","0.0170","73.9098"
"3.80000","0.06144","1,544.32410","0.0172","75.0256"
"4.00000","0.06500","1,587.72620","0.0182","77.1341"
"4.20000","0.06837","1,625.60266","0.0189","78.9742"
"4.40000","0.07144","1,654.43835","0.0193","80.3751"
"4.60000","0.07519","1,702.88867","0.0202","82.7289"
"4.80000","0.07806","1,724.55212","0.0204","83.7814"
"5.00000","0.08212","1,771.00171","0.0210","86.0379"
"5.20000","0.08456","1,785.08569","0.0215","86.7222"
"5.40000","0.08837","1,827.91553","0.0222","88.8029"
"5.60000","0.09169","1,858.92297","0.0229","90.3093"
"5.80000","0.09494","1,888.49792","0.0235","91.7461"
"6.00000","0.09850","1,927.05750","0.0240","93.6194"
"6.20000","0.10156","1,949.44141","0.0246","94.7068"
"6.40000","0.10537","1,987.12402","0.0253","96.5375"
"6.60000","0.10787","2,000.36462","0.0255","97.1807"
"6.80000","0.11175","2,042.05249","0.0263","99.2060"
"7.00000","0.11487","2,065.72998","0.0264","100.3563"
"7.20000","0.11850","2,099.94751","0.0271","102.0186"
"7.40000","0.12169","2,124.00879","0.0276","103.1876"
"7.60000","0.12494","2,150.70190","0.0281","104.4844"
"7.80000","0.12850","2,181.52686","0.0285","105.9819"
"8.00000","0.13125","2,196.23584","0.0288","106.6965"
"8.20000","0.13506","2,235.06738","0.0297","108.5830"
"8.40000","0.13819","2,254.87256","0.0301","109.5451"
"8.60000","0.14200","2,289.60938","0.0306","111.2327"
"8.80000","0.14475","2,303.98218","0.0309","111.9310"
"9.00000","0.14831","2,333.49683","0.0315","113.3648"
"9.20000","0.15175","2,362.46826","0.0321","114.7723"
"9.40000","0.15475","2,378.57104","0.0324","115.5546"
"9.60000","0.15844","2,415.14087","0.0329","117.3312"
"9.80000","0.16150","2,429.75537","0.0331","118.0412"
"10.00000","0.16544","2,463.88501","0.0338","119.6993"
"10.20000","0.16794","2,472.44580","0.0342","120.1152"
"10.40000","0.17162","2,503.97363","0.0345","121.6468"
"10.60000","0.17506","2,529.34229","0.0351","122.8793"
"10.80000","0.17825","2,548.91699","0.0355","123.8303"
"11.00000","0.18181","2,579.67676","0.0359","125.3246"
"11.20000","0.18481","2,593.90894","0.0363","126.0160"
"11.40000","0.18869","2,623.28833","0.0368","127.4433"
"11.60000","0.19119","2,631.69727","0.0372","127.8518"
"11.80000","0.19506","2,664.61328","0.0375","129.4510"
"12.00000","0.19831","2,685.00562","0.0379","130.4417"
"12.20000","0.20187","2,709.88623","0.0383","131.6504"
"12.40000","0.20494","2,727.71338","0.0389","132.5164"
"12.60000","0.20825","2,747.32886","0.0391","133.4694"
"12.80000","0.21175","2,770.81201","0.0398","134.6103"
"13.00000","0.21456","2,776.68042","0.0399","134.8954"
"13.20000","0.21844","2,809.07520","0.0402","136.4691"
"13.40000","0.22150","2,821.04395","0.0406","137.0506"
"13.60000","0.22537","2,850.17749","0.0412","138.4659"
"13.80000","0.22806","2,857.15308","0.0412","138.8048"
"14.00000","0.23162","2,880.69238","0.0415","139.9484"
"14.20000","0.23506","2,903.62305","0.0423","141.0624"
"14.40000","0.23806","2,912.31689","0.0422","141.4848"
"14.60000","0.24187","2,946.51074","0.0429","143.1460"
"14.80000","0.24487","2,956.81006","0.0431","143.6463"
"15.00000","0.24875","2,983.84204","0.0438","144.9596"
"15.20000","0.25125","2,988.41626","0.0436","145.1818"
"15.40000","0.25500","3,016.02588","0.0442","146.5231"
"15.60000","0.25825","3,035.96436","0.0448","147.4918"
"15.80000","0.26162","3,054.78418","0.0448","148.4061"
"16.00000","0.26512","3,080.70825","0.0454","149.6655"
"16.20000","0.26819","3,093.99731","0.0458","150.3111"
"16.40000","0.27200","3,119.90698","0.0462","151.5698"
"16.60000","0.27456","3,124.02759","0.0464","151.7700"
"16.80000","0.27837","3,154.09937","0.0470","153.2309"
"17.00000","0.28156","3,170.98389","0.0473","154.0512"
"17.20000","0.28519","3,194.69800","0.0475","155.2033"
"17.40000","0.28844","3,211.86401","0.0479","156.0372"
"17.60000","0.29156","3,227.62915","0.0483","156.8031"
"17.80000","0.29506","3,251.33325","0.0486","157.9547"
"18.00000","0.29800","3,258.73706","0.0489","158.3144"
"18.20000","0.30169","3,290.47412","0.0497","159.8562"
"18.40000","0.30481","3,302.97510","0.0499","160.4635"
"18.60000","0.30862","3,331.65747","0.0504","161.8570"
"18.80000","0.31144","3,338.94165","0.0509","162.2108"
"19.00000","0.31500","3,362.66431","0.0511","163.3633"
"19.20000","0.31837","3,383.55786","0.0515","164.3784"
"19.40000","0.32144","3,394.42603","0.0517","164.9064"
"19.60000","0.32519","3,426.62964","0.0522","166.4709"
"19.80000","0.32806","3,433.57178","0.0525","166.8081"
"20.00000","0.33212","3,465.02930","0.0531","168.3364"
"20.20000","0.33462","3,466.66211","0.0530","168.4157"
"20.40000","0.33837","3,494.18750","0.0536","169.7529"
"20.60000","0.34175","3,514.91040","0.0541","170.7597"
"20.80000","0.34494","3,530.16919","0.0545","171.5010"
"21.00000","0.34850","3,558.33472","0.0551","172.8693"
"21.20000","0.35156","3,569.71289","0.0550","173.4221"
"21.40000","0.35531","3,595.27881","0.0557","174.6641"
"21.60000","0.35787","3,599.30542","0.0560","174.8597"
"21.80000","0.36175","3,630.93579","0.0563","176.3964"
"22.00000","0.36487","3,644.91333","0.0565","177.0754"
"22.20000","0.36850","3,668.76025","0.0572","178.2339"
"22.40000","0.37162","3,684.93799","0.0575","179.0199"
"22.60000","0.37494","3,705.76929","0.0580","180.0319"
"22.80000","0.37850","3,729.18091","0.0586","181.1693"
"23.00000","0.38125","3,736.43628","0.0586","181.5217"
"23.20000","0.38506","3,771.50293","0.0593","183.2253"
"23.40000","0.38819","3,783.46118","0.0598","183.8063"
"23.60000","0.39194","3,811.99072","0.0601","185.1923"
"23.80000","0.39475","3,820.80420","0.0604","185.6205"
"24.00000","0.39831","3,845.26001","0.0607","186.8086"
"24.20000","0.40175","3,869.62891","0.0615","187.9924"
"24.40000","0.40475","3,880.53540","0.0616","188.5223"
"24.60000","0.40844","3,913.53931","0.0622","190.1257"
"24.80000","0.41150","3,923.34937","0.0624","190.6023"
"25.00000","0.41544","3,951.39307","0.0629","191.9647"
"25.20000","0.41787","3,954.52710","0.0633","192.1169"
"25.40000","0.42169","3,984.40552","0.0638","193.5685"
"25.60000","0.42506","4,005.08350","0.0641","194.5730"
"25.80000","0.42831","4,022.57031","0.0642","195.4226"
"26.00000","0.43181","4,048.01147","0.0647","196.6585"
"26.20000","0.43481","4,059.97119","0.0653","197.2396"
"26.40000","0.43869","4,087.20190","0.0658","198.5625"
"26.60000","0.44119","4,091.07104","0.0661","198.7504"
"26.80000","0.44500","4,123.28223","0.0667","200.3153"
"27.00000","0.44825","4,140.07617","0.0670","201.1312"
"27.20000","0.45181","4,164.30664","0.0673","202.3083"
"27.40000","0.45494","4,178.10352","0.0677","202.9786"
"27.60000","0.45831","4,199.69824","0.0682","204.0277"
"27.80000","0.46175","4,221.70605","0.0687","205.0969"
"28.00000","0.46462","4,230.13867","0.0689","205.5066"
"28.20000","0.46844","4,264.31445","0.0697","207.1669"
"28.40000","0.47150","4,275.03857","0.0696","207.6879"
"28.60000","0.47537","4,306.65234","0.0704","209.2237"
"28.80000","0.47806","4,310.42334","0.0705","209.4069"
"29.00000","0.48162","4,336.57227","0.0710","210.6773"
"29.20000","0.48506","4,360.88623","0.0715","211.8585"
"29.40000","0.48806","4,371.94873","0.0718","212.3959"
"29.60000","0.49181","4,405.97656","0.0725","214.0490"
"29.80000","0.49487","4,416.70410","0.0724","214.5702"
"30.00000","0.49875","4,445.15283","0.0729","215.9523"
"30.20000","0.50125","4,449.82812","0.0734","216.1794"
"30.40000","0.50500","4,479.54346","0.0739","217.6230"
"30.60000","0.50825","4,498.13135","0.0746","218.5260"
"30.80000","0.51162","4,518.34668","0.0748","219.5081"
"31.00000","0.51512","4,543.11182","0.0753","220.7113"
"31.20000","0.51825","4,557.76953","0.0756","221.4234"
"31.40000","0.52206","4,583.17041","0.0763","222.6574"
"31.60000","0.52456","4,585.55518","0.0760","222.7732"
"31.80000","0.52837","4,618.56201","0.0767","224.3768"
"32.00000","0.53156","4,633.80762","0.0774","225.1174"
"32.20000","0.53519","4,660.02490","0.0779","226.3911"
"32.40000","0.53844","4,675.60107","0.0780","227.1478"
"32.60000","0.54156","4,692.89893","0.0782","227.9882"
"32.80000","0.54512","4,717.79297","0.0789","229.1975"
"33.00000","0.54800","4,725.13379","0.0792","229.5542"
"33.20000","0.55169","4,758.49756","0.0795","231.1750"
"33.40000","0.55481","4,770.03027","0.0801","231.7353"
"33.60000","0.55869","4,800.42188","0.0804","233.2118"
"33.80000","0.56144","4,805.20020","0.0807","233.4439"
"34.00000","0.56500","4,831.29053","0.0812","234.7114"
"34.20000","0.56831","4,850.67334","0.0818","235.6531"
"34.40000","0.57144","4,863.97900","0.0820","236.2995"
"34.60000","0.57519","4,894.90479","0.0825","237.8019"
"34.80000","0.57812","4,903.73291","0.0827","238.2308"
"35.00000","0.58212","4,933.60303","0.0836","239.6819"
"35.20000","0.58456","4,933.59180","0.0834","239.6814"
"35.40000","0.58831","4,964.31885","0.0843","241.1741"
"35.60000","0.59175","4,983.55273","0.0845","242.1086"
"35.80000","0.59494","4,998.93848","0.0846","242.8560"
"36.00000","0.59850","5,025.43994","0.0850","244.1435"
"36.20000","0.60156","5,037.62939","0.0855","244.7357"
"36.40000","0.60537","5,062.91553","0.0859","245.9641"
"36.60000","0.60787","5,066.12939","0.0862","246.1203"
"36.80000","0.61175","5,098.27832","0.0867","247.6821"
"37.00000","0.61487","5,111.22314","0.0872","248.3110"
"37.20000","0.61850","5,137.01904","0.0876","249.5642"
"37.40000","0.62162","5,150.75879","0.0881","250.2317"
"37.60000","0.62494","5,171.39014","0.0884","251.2340"
"37.80000","0.62844","5,191.83789","0.0887","252.2274"
"38.00000","0.63125","5,199.78613","0.0890","252.6135"
"38.20000","0.63506","5,232.98389","0.0898","254.2263"
"38.40000","0.63825","5,245.14111","0.0898","254.8169"
"38.60000","0.64194","5,272.93945","0.0905","256.1674"
"38.80000","0.64475","5,278.93848","0.0906","256.4588"
"39.00000","0.64831","5,305.87646","0.0913","257.7675"
"39.20000","0.65175","5,328.31006","0.0919","258.8574"
"39.40000","0.65475","5,337.22119","0.0922","259.2903"
"39.60000","0.65844","5,368.41406","0.0924","260.8057"
"39.80000","0.66150","5,378.77100","0.0931","261.3089"
"40.00000","0.66544","5,408.51514","0.0932","262.7539"
"40.20000","0.66794","5,409.09082","0.0934","262.7818"
"40.40000","0.67169","5,439.52344","0.0938","264.2603"
"40.60000","0.67506","5,458.95605","0.0946","265.2044"
"40.80000","0.67831","5,477.70947","0.0950","266.1154"
"41.00000","0.68187","5,500.55420","0.0954","267.2253"
"41.20000","0.68487","5,514.75977","0.0955","267.9154"
"41.40000","0.68869","5,541.00635","0.0960","269.1905"
"41.60000","0.69125","5,544.45898","0.0965","269.3582"
"41.80000","0.69500","5,577.38037","0.0968","270.9576"
"42.00000","0.69831","5,592.62793","0.0972","271.6984"
"42.20000","0.70181","5,616.52783","0.0979","272.8594"
"42.40000","0.70494","5,628.35107","0.0980","273.4338"
"42.60000","0.70825","5,650.35205","0.0984","274.5027"
"42.80000","0.71169","5,671.46777","0.0988","275.5285"
"43.00000","0.71456","5,681.61279","0.0993","276.0214"
"43.20000","0.71844","5,715.91748","0.0999","277.6880"
"43.40000","0.72150","5,726.32471","0.1003","278.1935"
"43.60000","0.72537","5,757.05371","0.1010","279.6864"
"43.80000","0.72806","5,760.37891","0.1010","279.8480"
"44.00000","0.73162","5,787.76709","0.1013","281.1785"
"44.20000","0.73512","5,809.49268","0.1021","282.2340"
"44.40200","0.73812","5,819.81592","0.1021","282.7355"
"44.60200","0.74187","5,853.28564","0.1032","284.3615"
"44.80200","0.74494","5,864.46582","0.1031","284.9047"
"45.00200","0.74875","5,892.68311","0.1039","286.2755"
"45.20200","0.75131","5,895.56299","0.1040","286.4154"
"45.40200","0.75494","5,923.99707","0.1045","287.7968"
"45.60200","0.75831","5,945.66748","0.1051","288.8495"
"45.80200","0.76169","5,965.67578","0.1054","289.8216"
"46.00200","0.76519","5,988.39893","0.1059","290.9255"
"46.20200","0.76825","6,002.98242","0.1063","291.6340"
"46.40200","0.77212","6,029.02100","0.1065","292.8990"
"46.60200","0.77456","6,030.96387","0.1069","292.9934"
"46.80200","0.77837","6,064.18457","0.1075","294.6073"
"47.00200","0.78162","6,077.91699","0.1078","295.2744"
"47.20200","0.78519","6,105.24365","0.1083","296.6020"
"47.40200","0.78844","6,119.07520","0.1086","297.2740"
"47.60200","0.79162","6,137.77441","0.1089","298.1824"
"47.80200","0.79512","6,161.15283","0.1096","299.3181"
"48.00200","0.79794","6,170.25781","0.1097","299.7605"
"48.20200","0.80175","6,204.35303","0.1106","301.4169"
"48.40200","0.80487","6,217.96338","0.1109","302.0781"
"48.60200","0.80869","6,249.97266","0.1116","303.6331"
"48.80200","0.81144","6,254.82275","0.1115","303.8688"
"49.00200","0.81500","6,283.26025","0.1120","305.2503"
"49.20200","0.81844","6,305.30566","0.1125","306.3213"
"49.40200","0.82144","6,318.95312","0.1129","306.9843"
"49.60200","0.82519","6,350.95215","0.1135","308.5389"
"49.80200","0.82812","6,360.79248","0.1137","309.0170"
"50.00200","0.83212","6,394.61377","0.1145","310.6600"
"50.20200","0.83462","6,395.80127","0.1149","310.7177"
"50.40200","0.83837","6,427.93799","0.1151","312.2790"
"50.60200","0.84175","6,447.32324","0.1159","313.2208"
"50.80200","0.84494","6,467.64355","0.1160","314.2079"
"51.00200","0.84850","6,494.68506","0.1169","315.5217"
"51.20200","0.85156","6,511.56445","0.1170","316.3417"
"51.40200","0.85537","6,539.09229","0.1175","317.6790"
"51.60200","0.85787","6,544.28369","0.1178","317.9312"
"51.80200","0.86181","6,579.88867","0.1187","319.6610"
"52.00200","0.86494","6,595.84473","0.1189","320.4362"
"52.20200","0.86850","6,624.36621","0.1198","321.8218"
"52.40200","0.87169","6,639.50732","0.1200","322.5573"
"52.60200","0.87494","6,662.73926","0.1206","323.6860"
"52.80200","0.87856","6,688.05322","0.1213","324.9158"
"53.00200","0.88131","6,696.85693","0.1213","325.3435"
"53.20200","0.88512","6,733.77441","0.1221","327.1370"
"53.40200","0.88825","6,747.59375","0.1225","327.8083"
"53.60200","0.89194","6,778.55762","0.1227","329.3126"
"53.80200","0.89475","6,786.76123","0.1230","329.7112"
"54.00200","0.89831","6,816.01904","0.1237","331.1325"
"54.20200","0.90175","6,840.52246","0.1244","332.3230"
"54.40200","0.90475","6,854.40674","0.1247","332.9975"
"54.60200","0.90850","6,887.47168","0.1254","334.6038"
"54.80200","0.91156","6,901.14551","0.1257","335.2681"
"55.00200","0.91550","6,933.57080","0.1262","336.8434"
"55.20200","0.91794","6,936.20166","0.1265","336.9712"
"55.40200","0.92169","6,971.41064","0.1274","338.6817"
"55.60200","0.92512","6,993.19189","0.1276","339.7399"
"55.80200","0.92831","7,014.07861","0.1282","340.7546"
"56.00200","0.93187","7,039.83740","0.1287","342.0060"
"56.20200","0.93481","7,054.38867","0.1291","342.7129"
"56.40200","0.93875","7,085.80859","0.1298","344.2393"
"56.60200","0.94125","7,090.18115","0.1298","344.4518"
"56.80200","0.94506","7,126.54834","0.1305","346.2185"
"57.00200","0.94837","7,144.57031","0.1309","347.0941"
"57.20200","0.95187","7,172.88574","0.1315","348.4697"
"57.40200","0.95500","7,185.54492","0.1319","349.0847"
"57.60200","0.95837","7,211.57324","0.1322","350.3492"
"57.80200","0.96181","7,235.15967","0.1331","351.4950"
"58.00200","0.96462","7,247.18066","0.1333","352.0790"
"58.20200","0.96844","7,283.37012","0.1341","353.8372"
"58.40200","0.97156","7,298.10498","0.1343","354.5530"
"58.60200","0.97544","7,332.37549","0.1349","356.2179"
"58.80200","0.97812","7,337.81689","0.1354","356.4823"
"59.00200","0.98162","7,368.25635","0.1357","357.9611"
"59.20200","0.98512","7,393.36768","0.1365","359.1810"
"59.40200","0.98812","7,406.68848","0.1368","359.8282"
"59.60200","0.99187","7,440.53809","0.1376","361.4726"
"59.80200","0.99494","7,456.65674","0.1379","362.2557"
"60.00200","0.99875","7,485.88525","0.1384","363.6757"
"60.20200","1.00131","7,492.63330","0.1387","364.0035"
"60.40200","1.00500","7,526.60107","0.1394","365.6537"
"60.60200","1.00831","7,547.85303","0.1396","366.6862"
"60.80200","1.01162","7,572.51807","0.1406","367.8844"
"61.00200","1.01519","7,597.74170","0.1408","369.1098"
"61.20200","1.01825","7,617.51074","0.1414","370.0702"
"61.40200","1.02206","7,647.03467","0.1419","371.5045"
"61.60200","1.02456","7,651.31787","0.1422","371.7126"
"61.80200","1.02837","7,687.74805","0.1426","373.4825"
"62.00200","1.03162","7,705.45215","0.1431","374.3426"
"62.20200","1.03519","7,736.09131","0.1438","375.8311"
"62.40200","1.03850","7,751.00732","0.1444","376.5557"
"62.60200","1.04156","7,773.99463","0.1449","377.6725"
"62.80200","1.04519","7,800.42773","0.1453","378.9566"
"63.00200","1.04800","7,812.02148","0.1455","379.5199"
"63.20200","1.05175","7,847.47803","0.1465","381.2424"
"63.40200","1.05487","7,861.81152","0.1468","381.9388"
"63.60200","1.05862","7,895.21387","0.1473","383.5615"
"63.80200","1.06144","7,901.55322","0.1475","383.8694"
"64.00200","1.06500","7,933.16064","0.1482","385.4050"
"64.20200","1.06837","7,955.56299","0.1488","386.4933"
"64.40200","1.07144","7,974.36377","0.1493","387.4067"
"64.60200","1.07519","8,007.20020","0.1498","389.0020"
"64.80200","1.07819","8,022.07568","0.1503","389.7246"
"65.00200","1.08212","8,057.27979","0.1510","391.4349"
"65.20200","1.08462","8,059.91211","0.1515","391.5628"
"65.40200","1.08837","8,095.45898","0.1518","393.2897"
"65.60200","1.09181","8,119.26367","0.1523","394.4462"
"65.80200","1.09494","8,140.04834","0.1528","395.4559"
"66.00200","1.09856","8,167.38770","0.1534","396.7841"
"66.20200","1.10162","8,186.41650","0.1537","397.7085"
"66.40200","1.10537","8,215.13281","0.1545","399.1036"
"66.60200","1.10787","8,223.26660","0.1545","399.4988"
"66.80200","1.11175","8,260.57617","0.1555","401.3113"
"67.00200","1.11500","8,278.23535","0.1558","402.1693"
"67.20200","1.11850","8,308.49121","0.1566","403.6391"
"67.40200","1.12169","8,322.97461","0.1568","404.3427"
"67.60200","1.12494","8,350.39258","0.1573","405.6747"
"67.80200","1.12856","8,375.85547","0.1579","406.9118"
"68.00200","1.13125","8,387.39258","0.1581","407.4723"
"68.20200","1.13506","8,424.04492","0.1590","409.2529"
"68.40200","1.13825","8,440.73633","0.1592","410.0638"
"68.60200","1.14200","8,475.52051","0.1602","411.7537"
"68.80200","1.14481","8,483.70898","0.1604","412.1515"
"69.00200","1.14831","8,515.66797","0.1608","413.7041"
"69.20200","1.15181","8,542.93066","0.1617","415.0285"
"69.40200","1.15475","8,558.43359","0.1621","415.7817"
"69.60200","1.15844","8,591.66113","0.1627","417.3959"
"69.80200","1.16156","8,608.34863","0.1632","418.2066"
"70.00200","1.16544","8,643.84863","0.1637","419.9313"
"70.20200","1.16794","8,647.83691","0.1641","420.1250"
"70.40200","1.17169","8,684.73047","0.1648","421.9174"
"70.60200","1.17512","8,708.12207","0.1652","423.0538"
"70.80200","1.17831","8,731.59277","0.1657","424.1940"
"71.00200","1.18187","8,757.61328","0.1662","425.4582"
"71.20200","1.18487","8,776.35059","0.1667","426.3684"
"71.40200","1.18875","8,809.66309","0.1673","427.9868"
"71.60200","1.19125","8,816.13086","0.1678","428.3010"
"71.80200","1.19506","8,854.51074","0.1684","430.1656"
"72.00200","1.19837","8,874.73340","0.1692","431.1480"
"72.20200","1.20181","8,905.49609","0.1695","432.6425"
"72.40200","1.20494","8,919.60449","0.1697","433.3279"
"72.60200","1.20831","8,949.59277","0.1706","434.7848"
"72.80200","1.21181","8,974.73438","0.1712","436.0062"
"73.00200","1.21462","8,989.74316","0.1714","436.7354"
"73.20200","1.21844","9,028.85156","0.1722","438.6353"
"73.40200","1.22156","9,044.24512","0.1726","439.3831"
"73.60200","1.22537","9,079.29980","0.1735","441.0862"
"73.80200","1.22812","9,086.56445","0.1738","441.4391"
"74.00200","1.23162","9,119.98438","0.1742","443.0627"
"74.20200","1.23519","9,147.82129","0.1751","444.4150"
"74.40200","1.23806","9,164.27930","0.1752","445.2146"
"74.60200","1.24187","9,200.91016","0.1760","446.9942"
"74.80200","1.24487","9,218.82715","0.1765","447.8646"
"75.00200","1.24875","9,251.28418","0.1771","449.4414"
"75.20200","1.25131","9,259.67188","0.1775","449.8489"
"94.76800","1.25244","9,074.59961","0.1803","440.8578"
"94.96800","1.25300","9,076.87891","0.1825","440.9686"
"95.16800","1.25781","9,194.00977","0.2010","446.6589"
"95.36800","1.26156","9,288.07520","0.2154","451.2288"
"95.56800","1.26500","9,348.99023","0.2286","454.1881"
"95.76800","1.26806","9,403.85938","0.2404","456.8538"
"95.96800","1.27187","9,439.41699","0.2551","458.5812"
"96.16800","1.27437","9,434.61133","0.2647","458.3477"
"96.36800","1.27825","9,460.25879","0.2796","459.5937"
"96.56800","1.28144","9,470.72754","0.2918","460.1023"
"96.76800","1.28512","9,503.03027","0.3060","461.6716"
"96.96800","1.28825","9,516.18164","0.3180","462.3105"
"97.16800","1.29144","9,543.41309","0.3303","463.6335"
"97.36800","1.29494","9,572.38379","0.3438","465.0409"
"97.56800","1.29787","9,589.97949","0.3551","465.8958"
"97.76800","1.30156","9,627.20801","0.3692","467.7044"
"97.96800","1.30469","9,645.91211","0.3813","468.6130"
"98.16800","1.30856","9,684.07129","0.3962","470.4669"
"98.36800","1.31125","9,689.51465","0.4065","470.7313"
"98.56800","1.31487","9,727.69141","0.4204","472.5860"
"98.76800","1.31819","9,751.76465","0.4332","473.7555"
"98.96800","1.32131","9,775.31836","0.4452","474.8998"
"99.16800","1.32506","9,808.35254","0.4596","476.5047"
"99.36800","1.32800","9,826.98730","0.4709","477.4100"
"99.56800","1.33194","9,863.41211","0.4861","479.1795"
"99.76800","1.33444","9,869.07910","0.4957","479.4548"
"99.96800","1.33819","9,908.11133","0.5101","481.3511"
"100.16800","1.34162","9,932.02734","0.5233","482.5130"
"100.36800","1.34481","9,959.01172","0.5356","483.8239"
"100.56800","1.34831","9,984.69434","0.5491","485.0716"
"100.76800","1.35144","10,009.77344","0.5611","486.2900"
"100.96800","1.35519","10,039.83008","0.5755","487.7502"
"101.16800","1.35775","10,051.04199","0.5853","488.2949"
"101.36800","1.36169","10,092.15234","0.6005","490.2921"
"101.56800","1.36475","10,110.06055","0.6123","491.1621"
"101.76800","1.36837","10,147.22559","0.6262","492.9676"
"101.96800","1.37137","10,160.00391","0.6378","493.5884"
"102.16800","1.37481","10,192.74902","0.6510","495.1792"
"102.36800","1.37837","10,221.35840","0.6647","496.5691"
"102.56800","1.38112","10,236.20117","0.6753","497.2902"
"102.76800","1.38494","10,275.15332","0.6899","499.1826"
"102.96800","1.38806","10,293.30469","0.7019","500.0644"
"103.16800","1.39181","10,329.02734","0.7164","501.7998"
"103.36800","1.39456","10,337.41602","0.7269","502.2074"
"103.56800","1.39819","10,372.72363","0.7409","503.9227"
"103.76800","1.40169","10,401.15625","0.7543","505.3040"
"103.96800","1.40469","10,421.41406","0.7659","506.2881"
"104.16800","1.40831","10,454.07324","0.7798","507.8748"
"104.36800","1.41144","10,474.55762","0.7918","508.8699"
"104.56800","1.41531","10,509.17480","0.8067","510.5517"
"104.76800","1.41775","10,515.73926","0.8161","510.8706"
"104.96800","1.42156","10,556.00977","0.8308","512.8270"
"105.16800","1.42487","10,579.31836","0.8435","513.9594"
"105.36800","1.42819","10,607.88477","0.8563","515.3472"
"105.56800","1.43169","10,631.17188","0.8697","516.4785"
"105.76800","1.43469","10,654.66113","0.8813","517.6196"
"105.96800","1.43850","10,688.19727","0.8959","519.2488"
"106.16800","1.44106","10,699.24512","0.9058","519.7856"
"106.36800","1.44487","10,739.38672","0.9204","521.7357"
"106.56800","1.44819","10,762.04199","0.9332","522.8364"
"106.76800","1.45175","10,796.70410","0.9469","524.5203"
"106.96800","1.45475","10,808.99414","0.9584","525.1174"
"107.16800","1.45819","10,843.38086","0.9716","526.7879"
"107.36800","1.46156","10,869.85645","0.9846","528.0741"
"107.56800","1.46450","10,889.04785","0.9959","529.0065"
"107.76800","1.46831","10,928.91797","1.0106","530.9434"
"107.96800","1.47137","10,945.46680","1.0224","531.7474"
"108.16800","1.47525","10,983.52539","1.0373","533.5963"
"108.36800","1.47787","10,992.03418","1.0474","534.0097"
"108.56800","1.48144","11,027.28711","1.0611","535.7224"
"108.76800","1.48500","11,058.07617","1.0748","537.2181"
"108.96800","1.48800","11,077.79785","1.0863","538.1762"
"109.16800","1.49175","11,111.06250","1.1007","539.7923"
"109.36800","1.49481","11,131.83984","1.1125","540.8017"
"109.56800","1.49856","11,164.81152","1.1269","542.4035"
"109.76800","1.50112","11,175.60645","1.1368","542.9279"
"109.96800","1.50487","11,213.75391","1.1512","544.7812"
"110.16800","1.50812","11,238.01270","1.1637","545.9597"
"110.36800","1.51156","11,271.28516","1.1769","547.5761"
"110.56800","1.51494","11,293.45996","1.1899","548.6534"
"110.76800","1.51806","11,320.65723","1.2019","549.9747"
"110.96800","1.52187","11,354.86914","1.2166","551.6368"
"111.16800","1.52444","11,365.69336","1.2265","552.1627"
"111.36800","1.52825","11,405.13281","1.2411","554.0787"
"111.56800","1.53144","11,427.69824","1.2534","555.1749"
"111.76800","1.53512","11,465.51172","1.2676","557.0120"
"111.96800","1.53825","11,479.85645","1.2796","557.7089"
"112.16800","1.54144","11,509.77637","1.2918","559.1624"
"112.36800","1.54494","11,540.27832","1.3053","560.6442"
"112.56800","1.54787","11,559.59180","1.3166","561.5825"
"112.76800","1.55156","11,596.70801","1.3308","563.3857"
"112.96800","1.55469","11,616.80078","1.3428","564.3618"
"113.16800","1.55850","11,655.74414","1.3575","566.2537"
"113.36800","1.56119","11,663.46094","1.3678","566.6287"
"113.56800","1.56487","11,703.11621","1.3820","568.5552"
"113.76800","1.56819","11,729.10254","1.3947","569.8176"
"113.96800","1.57137","11,754.16895","1.4070","571.0353"
"114.16800","1.57506","11,788.10840","1.4212","572.6842"
"114.36800","1.57800","11,809.22949","1.4325","573.7103"
"114.56800","1.58200","11,847.50781","1.4478","575.5699"
"114.76800","1.58444","11,853.96289","1.4572","575.8835"
"114.96800","1.58819","11,893.61426","1.4716","577.8098"
"115.16800","1.59162","11,919.34375","1.4849","579.0598"
"115.36800","1.59481","11,947.56250","1.4971","580.4307"
"115.56800","1.59831","11,975.90039","1.5106","581.8074"
"115.76800","1.60144","12,000.96973","1.5226","583.0253"
"115.96800","1.60512","12,033.79785","1.5368","584.6202"
"116.16800","1.60769","12,046.69434","1.5466","585.2467"
"116.36800","1.61156","12,088.59863","1.5616","587.2825"
"116.56800","1.61481","12,110.03613","1.5741","588.3239"
"116.76800","1.61844","12,147.34180","1.5880","590.1363"
"116.96800","1.62137","12,160.19824","1.5993","590.7609"
"117.16800","1.62481","12,195.77637","1.6125","592.4893"
"117.36800","1.62837","12,225.47754","1.6262","593.9323"
"117.56800","1.63112","12,242.70312","1.6368","594.7691"
"117.76800","1.63494","12,282.91797","1.6515","596.7228"
"117.96800","1.63806","12,301.88965","1.6635","597.6445"
"118.16800","1.64181","12,339.74023","1.6779","599.4833"
"118.36800","1.64456","12,348.87695","1.6885","599.9272"
"118.56800","1.64819","12,386.00586","1.7024","601.7310"
"118.76800","1.65162","12,416.05957","1.7156","603.1910"
"118.96800","1.65469","12,438.65527","1.7274","604.2888"
"119.16800","1.65837","12,472.10547","1.7416","605.9138"
"119.36800","1.66137","12,492.53613","1.7531","606.9064"
"119.56800","1.66525","12,529.56641","1.7680","608.7054"
"119.76800","1.66775","12,538.29492","1.7777","609.1294"
"119.96800","1.67156","12,579.45117","1.7923","611.1288"
"120.16800","1.67494","12,604.89355","1.8053","612.3649"
"120.36800","1.67819","12,635.12695","1.8178","613.8336"
"120.56800","1.68169","12,660.04004","1.8313","615.0439"
"120.76800","1.68475","12,684.60449","1.8430","616.2374"
"120.96800","1.68856","12,720.68652","1.8577","617.9902"
"121.16800","1.69106","12,731.38184","1.8673","618.5098"
"121.36800","1.69487","12,770.66504","1.8820","620.4183"
"121.56800","1.69819","12,795.02637","1.8947","621.6018"
"121.76800","1.70169","12,831.19727","1.9082","623.3590"
"121.96800","1.70469","12,844.04590","1.9197","623.9832"
"122.16800","1.70819","12,879.44727","1.9332","625.7031"
"122.36800","1.71156","12,907.33496","1.9462","627.0579"
"122.56800","1.71450","12,927.52930","1.9575","628.0390"
"122.76800","1.71831","12,968.01270","1.9721","630.0057"
"122.96800","1.72137","12,985.55273","1.9839","630.8578"
"123.16800","1.72531","13,027.02539","1.9991","632.8727"
"123.36800","1.72787","13,034.33496","2.0089","633.2278"
"123.56800","1.73150","13,072.51270","2.0228","635.0825"
"123.76800","1.73506","13,103.50195","2.0366","636.5880"
"123.96800","1.73800","13,125.16504","2.0478","637.6404"
"124.16800","1.74169","13,159.52539","2.0620","639.3097"
"124.36800","1.74481","13,183.81836","2.0741","640.4899"
"124.56800","1.74856","13,217.29004","2.0885","642.1160"
"124.76800","1.75112","13,228.60156","2.0983","642.6655"
"124.96800","1.75487","13,267.48730","2.1128","644.5547"
"125.16800","1.75819","13,292.55273","2.1255","645.7724"
"125.36800","1.76156","13,326.10059","2.1385","647.4022"
"125.56800","1.76500","13,348.90430","2.1517","648.5100"
"125.76800","1.76812","13,378.35059","2.1637","649.9406"
"125.96800","1.77187","13,411.62793","2.1781","651.5573"
"126.16800","1.77437","13,423.31738","2.1878","652.1251"
"126.36800","1.77825","13,465.60254","2.2027","654.1794"
"126.56800","1.78144","13,487.27930","2.2149","655.2325"
"126.76800","1.78512","13,527.42188","2.2291","657.1827"
"126.96800","1.78819","13,541.74609","2.2409","657.8786"
"127.16800","1.79144","13,573.15918","2.2534","659.4047"
"127.36800","1.79494","13,603.33008","2.2668","660.8704"
"127.56800","1.79787","13,624.26270","2.2781","661.8874"
"127.76800","1.80156","13,662.51074","2.2923","663.7455"
"127.96800","1.80475","13,683.46094","2.3046","664.7633"
"128.16800","1.80850","13,721.83594","2.3190","666.6276"
"128.36800","1.81119","13,730.63281","2.3293","667.0550"
"128.56800","1.81487","13,770.68457","2.3435","669.0007"
"128.76800","1.81819","13,797.42285","2.3563","670.2997"
"128.96800","1.82131","13,823.54395","2.3683","671.5687"
"129.16800","1.82506","13,858.51660","2.3827","673.2678"
"129.36800","1.82800","13,878.19238","2.3940","674.2236"
"129.56800","1.83194","13,917.05469","2.4091","676.1116"
"129.76800","1.83437","13,924.91602","2.4185","676.4935"
"129.96800","1.83819","13,965.57812","2.4332","678.4690"
"130.16800","1.84162","13,991.42285","2.4464","679.7245"
"130.36800","1.84481","14,021.65723","2.4587","681.1934"
"130.56800","1.84831","14,047.63477","2.4721","682.4554"
"130.76800","1.85144","14,075.02246","2.4841","683.7859"
"130.96800","1.85512","14,108.16504","2.4983","685.3961"
"131.16800","1.85775","14,122.12695","2.5084","686.0743"
"131.36800","1.86156","14,164.05176","2.5231","688.1111"
"131.56800","1.86481","14,185.89941","2.5356","689.1725"
"131.76800","1.86844","14,224.06836","2.5495","691.0269"
"131.96800","1.87137","14,237.55762","2.5608","691.6822"
"132.16800","1.87481","14,274.28711","2.5741","693.4666"
"132.36800","1.87831","14,304.58301","2.5875","694.9384"
"132.56800","1.88112","14,322.29395","2.5983","695.7988"
"132.76800","1.88494","14,362.57031","2.6130","697.7555"
"132.96800","1.88812","14,384.25293","2.6253","698.8088"
"133.16800","1.89181","14,421.10840","2.6394","700.5994"
"133.36800","1.89456","14,431.01465","2.6500","701.0806"
"133.56800","1.89819","14,469.64551","2.6640","702.9573"
"133.76800","1.90169","14,501.59570","2.6774","704.5095"
"133.96800","1.90469","14,523.98730","2.6890","705.5974"
"134.16800","1.90831","14,556.88672","2.7029","707.1957"
"134.36800","1.91144","14,580.52539","2.7149","708.3441"
"134.56800","1.91525","14,617.60449","2.7296","710.1454"
"134.76800","1.91769","14,626.93359","2.7390","710.5986"
"134.96800","1.92156","14,669.55664","2.7539","712.6693"
"135.16800","1.92487","14,695.22070","2.7666","713.9161"
"135.36800","1.92819","14,727.41113","2.7793","715.4800"
"135.56800","1.93169","14,752.07227","2.7928","716.6780"
"135.76800","1.93469","14,777.54297","2.8043","717.9155"
"135.96800","1.93856","14,815.04004","2.8192","719.7371"
"136.16800","1.94106","14,826.73730","2.8289","720.3054"
"136.36800","1.94494","14,869.28809","2.8438","722.3726"
"136.56800","1.94825","14,894.30957","2.8565","723.5882"
"136.76800","1.95169","14,929.67773","2.8697","725.3064"
"136.96800","1.95469","14,942.93555","2.8813","725.9505"
"137.16800","1.95819","14,980.94824","2.8947","727.7972"
"137.36800","1.96150","15,009.12207","2.9075","729.1660"
"137.56800","1.96450","15,031.54297","2.9190","730.2552"
"137.76800","1.96831","15,073.38867","2.9337","732.2881"
"137.96800","1.97137","15,092.46680","2.9454","733.2150"
"138.16800","1.97525","15,133.79102","2.9603","735.2225"
"138.36800","1.97781","15,142.62402","2.9702","735.6517"
"138.56800","1.98150","15,183.19727","2.9844","737.6227"
"138.76800","1.98500","15,215.14160","2.9978","739.1747"
"138.96800","1.98800","15,238.02148","3.0094","740.2862"
"139.16800","1.99169","15,273.53516","3.0236","742.0115"
"139.36800","1.99487","15,299.12793","3.0358","743.2549"
"139.56800","1.99856","15,331.91797","3.0500","744.8478"
"139.76800","2.00112","15,344.64551","3.0599","745.4662"
"139.96800","2.00481","15,385.27441","3.0741","747.4400"
"140.16800","2.00812","15,412.08301","3.0868","748.7424"
"140.36800","2.01156","15,447.53320","3.1000","750.4646"
"140.56800","2.01494","15,470.22168","3.1130","751.5668"
"140.76800","2.01812","15,500.62402","3.1253","753.0438"
"140.96800","2.02187","15,535.90723","3.1397","754.7579"
"141.16800","2.02437","15,548.11914","3.1493","755.3513"
"141.36800","2.02825","15,590.93262","3.1642","757.4312"
"141.56800","2.03150","15,614.98828","3.1767","758.5999"
"141.76800","2.03506","15,653.54199","3.1904","760.4728"
"141.96800","2.03825","15,670.85254","3.2027","761.3138"
"142.16800","2.04144","15,703.03027","3.2149","762.8771"
"142.36800","2.04494","15,734.48145","3.2284","764.4050"
"142.56800","2.04787","15,756.66504","3.2397","765.4827"
"142.76800","2.05156","15,794.99512","3.2539","767.3448"
"142.96800","2.05469","15,818.58887","3.2659","768.4910"
"143.16800","2.05850","15,859.51465","3.2805","770.4793"
"143.36800","2.06119","15,868.20215","3.2909","770.9014"
"143.56800","2.06487","15,909.31152","3.3051","772.8985"
"143.76800","2.06819","15,937.00391","3.3178","774.2438"
"143.96800","2.07131","15,963.18945","3.3298","775.5160"
"144.16800","2.07506","15,998.21777","3.3442","777.2177"
"144.36800","2.07794","16,018.06250","3.3553","778.1818"
"144.56800","2.08200","16,060.42871","3.3709","780.2400"
"144.76800","2.08444","16,068.59863","3.3803","780.6369"
"144.96800","2.08819","16,110.40039","3.3947","782.6677"
"145.16800","2.09169","16,138.33203","3.4082","784.0247"
"145.36800","2.09481","16,168.01660","3.4202","785.4668"
"145.56800","2.09825","16,195.04688","3.4334","786.7800"
"145.76800","2.10144","16,225.04395","3.4457","788.2372"
"145.96800","2.10512","16,257.76758","3.4599","789.8270"
"146.16800","2.10769","16,273.42090","3.4697","790.5875"
"146.36800","2.11156","16,315.68359","3.4846","792.6407"
"146.56800","2.11481","16,338.20801","3.4971","793.7349"
"146.76800","2.11844","16,376.86621","3.5111","795.6130"
"146.96800","2.12131","16,389.42773","3.5221","796.2233"
"147.16800","2.12481","16,426.38281","3.5356","798.0186"
"147.36800","2.12837","16,457.52148","3.5493","799.5314"
"147.56800","2.13112","16,475.95117","3.5599","800.4267"
"147.76800","2.13494","16,518.02148","3.5745","802.4706"
"147.96800","2.13806","16,540.78125","3.5866","803.5762"
"148.16800","2.14181","16,579.93750","3.6010","805.4785"
"148.23000","2.14300","16,082.70215","3.6055","781.3221"
"148.23400","2.14369","14,888.63965","3.6082","723.3127"
"148.23800","2.14444","13,270.54785","3.6111","644.7034"
"148.24200","2.14531","11,424.10449","3.6144","555.0004"
"148.24600","2.14619","9,525.78223","3.6178","462.7769"