File: data/Long/Specimen_RawData_2.csv
Specimen number (included),2
Modulus (Automatic Young's),"253,111.78885",MPa
Length,"26.00000",mm
Specimen ID,"0031"
Thickness,"2.01700",mm
Width,"10.19100",mm
Tensile stress at Tensile strength,"720.62848",MPa
Tensile strain (Strain 1) at Tensile strength,"0.02817",mm/mm

Time,Extension,Load,Tensile strain (Strain 1),Tensile stress
(s),(mm),(N),(%),(MPa)
"0.00000","-0.00963","508.07352","-0.0008","24.7175"
"0.20000","-0.00762","541.82727","-0.0001","26.3596"
"0.40000","-0.00300","670.75580","0.0021","32.6319"
"0.60000","0.00012","751.10590","0.0039","36.5408"
"0.80000","0.00387","833.66687","0.0053","40.5574"
"1.00000","0.00687","890.06171","0.0066","43.3009"
"1.20000","0.01081","966.89911","0.0078","47.0390"
"1.40000","0.01344","1,004.85541","0.0086","48.8856"
"1.60000","0.01712","1,072.93567","0.0100","52.1977"
"1.80000","0.02044","1,126.44287","0.0109","54.8007"
"2.00000","0.02369","1,180.87061","0.0120","57.4486"
"2.20000","0.02719","1,237.68860","0.0131","60.2128"
"2.40000","0.03025","1,282.73352","0.0139","62.4042"
"2.60000","0.03419","1,341.80505","0.0152","65.2780"
"2.80000","0.03662","1,369.89331","0.0155","66.6445"
"3.00000","0.04044","1,430.51428","0.0165","69.5936"
"3.20000","0.04356","1,471.44409","0.0174","71.5848"
"3.40000","0.04719","1,527.27356","0.0187","74.3009"
"3.60000","0.05056","1,565.23938","0.0191","76.1479"
"3.80000","0.05362","1,608.63806","0.0199","78.2592"
"4.00000","0.05737","1,657.27319","0.0212","80.6253"
"4.20000","0.06000","1,685.03918","0.0215","81.9761"
"4.40000","0.06381","1,741.35767","0.0226","84.7160"
"4.60000","0.06694","1,775.06921","0.0236","86.3560"
"4.80000","0.07069","1,828.75171","0.0245","88.9676"
"5.00000","0.07362","1,855.69055","0.0249","90.2782"
"5.20000","0.07706","1,902.83826","0.0259","92.5719"
"5.40000","0.08050","1,944.43335","0.0267","94.5955"
"5.60000","0.08344","1,975.86328","0.0269","96.1245"
"5.80000","0.08725","2,029.93298","0.0283","98.7550"
"6.00000","0.09019","2,056.67676","0.0288","100.0561"
"6.20000","0.09412","2,110.92529","0.0299","102.6952"
"6.40000","0.09675","2,129.70337","0.0301","103.6087"
"6.60000","0.10044","2,179.00806","0.0310","106.0074"
"6.80000","0.10381","2,217.29663","0.0320","107.8701"
"7.00000","0.10694","2,252.25684","0.0326","109.5709"
"7.20000","0.11062","2,299.19043","0.0334","111.8542"
"7.40000","0.11362","2,327.04810","0.0342","113.2094"
"7.60000","0.11750","2,375.36084","0.0350","115.5598"
"7.80000","0.11994","2,392.46973","0.0353","116.3922"
"8.00000","0.12381","2,442.81030","0.0364","118.8412"
"8.20000","0.12700","2,475.03662","0.0368","120.4090"
"8.40000","0.13050","2,516.98413","0.0376","122.4497"
"8.60000","0.13381","2,549.88916","0.0383","124.0505"
"8.80000","0.13694","2,583.70166","0.0388","125.6955"
"9.00000","0.14069","2,624.78345","0.0397","127.6941"
"9.20000","0.14331","2,645.23633","0.0405","128.6891"
"9.40000","0.14719","2,695.08838","0.0413","131.1144"
"9.60000","0.15031","2,722.80884","0.0418","132.4630"
"9.80000","0.15400","2,766.84399","0.0426","134.6052"
"10.00000","0.15694","2,789.07739","0.0430","135.6869"
"10.20000","0.16037","2,828.41113","0.0436","137.6004"
"10.40000","0.16387","2,866.66504","0.0445","139.4615"
"10.60000","0.16681","2,890.00879","0.0451","140.5971"
"10.80000","0.17050","2,937.26050","0.0461","142.8959"
"11.00000","0.17356","2,960.19727","0.0467","144.0118"
"11.20000","0.17744","3,004.83203","0.0474","146.1832"
"11.40000","0.18006","3,021.04224","0.0480","146.9718"
"11.60000","0.18375","3,063.73120","0.0485","149.0486"
"11.80000","0.18719","3,098.51172","0.0491","150.7407"
"12.00000","0.19031","3,126.94800","0.0496","152.1241"
"12.20000","0.19400","3,168.25317","0.0504","154.1336"
"12.40000","0.19687","3,189.15063","0.0512","155.1502"
"12.60000","0.20087","3,232.55981","0.0521","157.2620"
"12.80000","0.20331","3,245.49829","0.0527","157.8915"
"13.00000","0.20712","3,291.09399","0.0535","160.1097"
"13.20000","0.21037","3,319.60474","0.0538","161.4967"
"13.40000","0.21381","3,355.23926","0.0545","163.2303"
"13.60000","0.21719","3,385.74951","0.0554","164.7146"
"13.80000","0.22031","3,414.31860","0.0562","166.1045"
"14.00000","0.22387","3,448.95728","0.0566","167.7896"
"14.20000","0.22669","3,468.15698","0.0572","168.7237"
"14.40000","0.23050","3,514.26367","0.0579","170.9668"
"14.60000","0.23362","3,537.08276","0.0583","172.0769"
"14.80000","0.23744","3,579.07202","0.0593","174.1196"
"15.00000","0.24019","3,592.35229","0.0596","174.7657"
"15.20000","0.24375","3,629.97314","0.0601","176.5959"
"15.40000","0.24712","3,661.41089","0.0611","178.1254"
"15.60000","0.25012","3,682.16528","0.0614","179.1351"
"15.80000","0.25387","3,725.60327","0.0619","181.2483"
"16.00000","0.25694","3,743.72314","0.0627","182.1298"
"16.20000","0.26081","3,784.77734","0.0636","184.1271"
"16.40000","0.26344","3,795.84839","0.0637","184.6657"
"16.60000","0.26706","3,833.22021","0.0644","186.4838"
"16.80000","0.27044","3,861.87061","0.0647","187.8776"
"17.00000","0.27362","3,887.08374","0.0654","189.1042"
"17.20000","0.27725","3,924.38916","0.0660","190.9191"
"17.40000","0.28037","3,946.37427","0.0667","191.9887"
"17.60000","0.28419","3,981.14844","0.0672","193.6804"
"17.80000","0.28662","3,992.50342","0.0675","194.2328"
"18.00000","0.29044","4,031.84326","0.0685","196.1467"
"18.20000","0.29369","4,056.39160","0.0689","197.3409"
"18.40000","0.29719","4,091.56836","0.0696","199.0523"
"18.60000","0.30056","4,118.33691","0.0703","200.3545"
"18.80000","0.30369","4,142.40186","0.0710","201.5253"
"19.00000","0.30731","4,175.35938","0.0717","203.1286"
"19.20000","0.31000","4,188.86035","0.0718","203.7855"
"19.40000","0.31381","4,229.83594","0.0728","205.7789"
"19.60000","0.31694","4,248.95898","0.0732","206.7092"
"19.80000","0.32069","4,285.22510","0.0739","208.4735"
"20.00000","0.32362","4,299.51123","0.0742","209.1686"
"20.20000","0.32712","4,329.11084","0.0749","210.6086"
"20.40000","0.33050","4,353.47510","0.0754","211.7939"
"20.60000","0.33344","4,365.39648","0.0756","212.3738"
"20.80000","0.33719","4,402.98633","0.0764","214.2026"
"21.00000","0.34019","4,415.72412","0.0765","214.8222"
"21.20000","0.34419","4,449.39551","0.0775","216.4603"
"21.40000","0.34675","4,454.84912","0.0773","216.7256"
"21.60000","0.35044","4,487.33105","0.0781","218.3059"
"21.80000","0.35381","4,510.36035","0.0787","219.4262"
"22.00000","0.35694","4,529.58545","0.0791","220.3615"
"22.20000","0.36062","4,561.64160","0.0798","221.9210"
"22.40000","0.36362","4,575.38086","0.0800","222.5894"
"22.60000","0.36750","4,608.46631","0.0808","224.1990"
"22.80000","0.36994","4,612.71143","0.0809","224.4055"
"23.00000","0.37381","4,647.50391","0.0817","226.0982"
"23.20000","0.37706","4,666.76221","0.0819","227.0351"
"23.40000","0.38050","4,692.84424","0.0830","228.3040"
"23.60000","0.38387","4,715.84668","0.0830","229.4230"
"23.80000","0.38700","4,735.20264","0.0837","230.3647"
"24.00000","0.39069","4,763.04932","0.0842","231.7194"
"24.20000","0.39331","4,772.10938","0.0843","232.1602"
"24.40000","0.39712","4,807.83105","0.0853","233.8980"
"24.60000","0.40031","4,824.81592","0.0854","234.7243"
"24.80000","0.40400","4,855.27393","0.0863","236.2061"
"25.00000","0.40694","4,865.36377","0.0860","236.6969"
"25.20000","0.41031","4,889.48633","0.0866","237.8705"
"25.40000","0.41387","4,915.36670","0.0874","239.1295"
"25.60000","0.41681","4,925.71240","0.0873","239.6329"
"25.80000","0.42056","4,961.73779","0.0883","241.3855"
"26.00000","0.42362","4,972.64160","0.0884","241.9159"
"26.20000","0.42744","5,002.41309","0.0893","243.3643"
"26.40000","0.43006","5,004.32568","0.0894","243.4574"
"26.60000","0.43375","5,034.35938","0.0900","244.9185"
"26.80000","0.43719","5,057.13916","0.0906","246.0267"
"27.00000","0.44031","5,071.78467","0.0908","246.7392"
"27.20000","0.44394","5,101.92529","0.0911","248.2055"
"27.40000","0.44687","5,112.59375","0.0914","248.7245"
"27.60000","0.45087","5,142.66699","0.0925","250.1876"
"27.80000","0.45325","5,144.40723","0.0925","250.2722"
"28.00000","0.45712","5,180.74707","0.0933","252.0401"
"28.20000","0.46037","5,197.81055","0.0934","252.8703"
"28.40000","0.46381","5,221.54590","0.0939","254.0250"
"28.60000","0.46719","5,240.81738","0.0946","254.9625"
"28.80000","0.47037","5,258.31543","0.0950","255.8138"
"29.00000","0.47387","5,282.72168","0.0952","257.0011"
"29.20000","0.47669","5,290.56885","0.0955","257.3829"
"29.40000","0.48050","5,325.93066","0.0961","259.1032"
"29.60000","0.48362","5,338.88135","0.0967","259.7333"
"29.80000","0.48744","5,371.70264","0.0972","261.3300"
"30.00000","0.49019","5,377.77197","0.0972","261.6253"
"30.20000","0.49375","5,405.58594","0.0982","262.9784"
"30.40000","0.49712","5,427.14600","0.0984","264.0273"
"30.60000","0.50012","5,439.29834","0.0989","264.6185"
"30.80000","0.50387","5,474.18018","0.0997","266.3155"
"31.00000","0.50694","5,483.37451","0.0999","266.7628"
"31.20000","0.51087","5,516.24805","0.1004","268.3621"
"31.40000","0.51344","5,518.45459","0.1004","268.4694"
"31.60000","0.51706","5,547.67578","0.1013","269.8910"
"31.80000","0.52044","5,567.02246","0.1016","270.8322"
"32.00000","0.52362","5,583.28711","0.1021","271.6234"
"32.20000","0.52725","5,612.62598","0.1028","273.0508"
"32.40000","0.53025","5,625.49805","0.1031","273.6770"
"32.60000","0.53412","5,653.21533","0.1037","275.0254"
"32.80000","0.53662","5,655.68506","0.1039","275.1456"
"33.00000","0.54050","5,688.19434","0.1044","276.7271"
"33.20000","0.54369","5,703.72314","0.1046","277.4826"
"33.40000","0.54719","5,730.01416","0.1052","278.7616"
"33.60000","0.55056","5,747.23779","0.1059","279.5995"
"33.80000","0.55369","5,765.49170","0.1061","280.4876"
"34.00000","0.55737","5,791.09863","0.1068","281.7334"
"34.20000","0.56000","5,796.09814","0.1066","281.9766"
"34.40000","0.56381","5,831.21240","0.1073","283.6849"
"34.60000","0.56694","5,844.93115","0.1078","284.3523"
"34.80000","0.57069","5,876.70605","0.1085","285.8981"
"35.00000","0.57356","5,885.31738","0.1088","286.3170"
"35.20000","0.57706","5,912.37842","0.1092","287.6335"
"35.40000","0.58050","5,935.02393","0.1097","288.7352"
"35.60000","0.58344","5,947.06250","0.1103","289.3209"
"35.80000","0.58719","5,981.92041","0.1110","291.0167"
"36.00000","0.59019","5,992.78564","0.1110","291.5453"
"36.20000","0.59419","6,026.20410","0.1118","293.1711"
"36.40000","0.59675","6,028.35205","0.1120","293.2756"
"36.60000","0.60044","6,059.60107","0.1128","294.7958"
"36.80000","0.60381","6,078.60205","0.1131","295.7202"
"37.00000","0.60694","6,095.45703","0.1135","296.5402"
"37.20000","0.61062","6,124.22852","0.1140","297.9399"
"37.40000","0.61356","6,134.79932","0.1142","298.4542"
"37.60000","0.61750","6,165.34473","0.1149","299.9402"
"37.80000","0.61994","6,166.53076","0.1149","299.9979"
"38.00000","0.62375","6,201.73389","0.1157","301.7105"
"38.20000","0.62706","6,219.52734","0.1160","302.5761"
"38.40000","0.63044","6,244.88086","0.1168","303.8096"
"38.60000","0.63381","6,263.73584","0.1171","304.7269"
"38.80000","0.63700","6,283.93604","0.1173","305.7096"
"39.00000","0.64069","6,309.63672","0.1185","306.9599"
"39.20000","0.64331","6,317.34863","0.1184","307.3351"
"39.40000","0.64719","6,353.41699","0.1194","309.0898"
"39.60000","0.65031","6,367.68359","0.1191","309.7839"
"39.80000","0.65400","6,398.03418","0.1201","311.2604"
"40.00000","0.65694","6,407.79150","0.1205","311.7351"
"40.20000","0.66037","6,435.73486","0.1210","313.0945"
"40.40000","0.66387","6,460.49463","0.1214","314.2991"
"40.60000","0.66675","6,470.33594","0.1222","314.7778"
"40.80000","0.67056","6,505.37109","0.1226","316.4823"
"41.00000","0.67362","6,516.92090","0.1230","317.0442"
"41.20000","0.67744","6,547.25879","0.1234","318.5201"
"41.40000","0.68006","6,551.75879","0.1235","318.7390"
"41.60000","0.68375","6,583.31006","0.1241","320.2740"
"41.80000","0.68719","6,607.12402","0.1249","321.4325"
"42.00000","0.69031","6,624.30322","0.1252","322.2682"
"42.20000","0.69394","6,653.01904","0.1259","323.6653"
"42.40000","0.69694","6,668.64209","0.1261","324.4253"
"42.60000","0.70081","6,699.30518","0.1263","325.9171"
"42.80000","0.70325","6,701.87305","0.1269","326.0420"
"43.00000","0.70719","6,739.45020","0.1278","327.8701"
"43.20000","0.71037","6,755.69775","0.1281","328.6605"
"43.40000","0.71381","6,782.61133","0.1288","329.9698"
"43.60000","0.71725","6,801.12402","0.1291","330.8705"
"43.80000","0.72025","6,819.97754","0.1296","331.7877"
"44.00000","0.72394","6,846.67529","0.1302","333.0865"
"44.20000","0.72669","6,857.32373","0.1304","333.6046"
"44.40000","0.73050","6,892.61865","0.1311","335.3216"
"44.60000","0.73362","6,908.46875","0.1317","336.0927"
"44.80000","0.73737","6,941.50244","0.1324","337.6998"
"45.00000","0.74019","6,948.90234","0.1325","338.0598"
"45.20000","0.74375","6,979.93018","0.1330","339.5693"
"45.40000","0.74706","7,002.97119","0.1336","340.6902"
"45.60000","0.75012","7,018.92432","0.1337","341.4663"
"45.80000","0.75394","7,055.37061","0.1347","343.2394"
"46.00000","0.75687","7,066.30420","0.1351","343.7713"
"46.20000","0.76081","7,100.25000","0.1356","345.4228"
"46.40000","0.76344","7,104.59180","0.1360","345.6340"
"46.60000","0.76706","7,136.03418","0.1365","347.1636"
"46.80000","0.77050","7,158.71924","0.1371","348.2672"
"47.00000","0.77362","7,177.34326","0.1376","349.1733"
"47.20000","0.77725","7,206.58545","0.1386","350.5959"
"47.40000","0.78037","7,222.78809","0.1386","351.3842"
"47.60000","0.78412","7,251.09863","0.1390","352.7614"
"47.80000","0.78662","7,256.71875","0.1391","353.0349"
"48.00000","0.79044","7,291.55225","0.1397","354.7295"
"48.20000","0.79369","7,310.94775","0.1404","355.6731"
"48.40000","0.79725","7,340.08789","0.1411","357.0907"
"48.60000","0.80050","7,354.80176","0.1411","357.8065"
"48.80000","0.80362","7,376.67236","0.1418","358.8705"
"49.00000","0.80737","7,403.95850","0.1425","360.1980"
"49.20000","0.80994","7,411.08496","0.1430","360.5447"
"49.40000","0.81381","7,446.98193","0.1433","362.2910"
"49.60000","0.81694","7,463.30371","0.1437","363.0851"
"49.80000","0.82069","7,496.84961","0.1444","364.7171"
"50.00000","0.82362","7,507.22217","0.1451","365.2217"
"50.20000","0.82706","7,535.72754","0.1456","366.6085"
"50.40000","0.83050","7,560.82080","0.1459","367.8293"
"50.60000","0.83344","7,575.31689","0.1463","368.5345"
"50.80000","0.83712","7,610.08203","0.1469","370.2258"
"51.00000","0.84019","7,625.50586","0.1473","370.9761"
"51.20000","0.84412","7,661.95654","0.1483","372.7495"
"51.40000","0.84669","7,664.80469","0.1484","372.8880"
"51.60000","0.85044","7,700.39941","0.1489","374.6197"
"51.80000","0.85381","7,722.03223","0.1496","375.6721"
"52.00000","0.85694","7,742.86475","0.1499","376.6856"
"52.20000","0.86062","7,773.45605","0.1505","378.1738"
"52.40000","0.86356","7,789.40625","0.1508","378.9498"
"52.60000","0.86750","7,824.57568","0.1515","380.6608"
"52.80000","0.87000","7,829.02148","0.1520","380.8770"
"53.00000","0.87381","7,866.40576","0.1526","382.6958"
"53.20000","0.87712","7,886.86035","0.1534","383.6909"
"53.40000","0.88044","7,912.68945","0.1537","384.9474"
"53.60000","0.88387","7,934.45410","0.1539","386.0063"
"53.80000","0.88700","7,958.32275","0.1550","387.1675"
"54.00000","0.89062","7,986.11768","0.1551","388.5197"
"54.20000","0.89331","7,997.23877","0.1556","389.0607"
"54.40000","0.89719","8,035.14404","0.1565","390.9048"
"54.60000","0.90031","8,052.31836","0.1568","391.7403"
"54.80000","0.90400","8,086.40332","0.1575","393.3985"
"55.00000","0.90694","8,096.16016","0.1579","393.8732"
"55.20000","0.91037","8,126.54492","0.1585","395.3514"
"55.40000","0.91387","8,153.91602","0.1591","396.6830"
"55.60000","0.91675","8,168.53857","0.1596","397.3943"
"55.80000","0.92056","8,206.28223","0.1602","399.2306"
"56.00000","0.92362","8,221.39746","0.1601","399.9659"
"56.20000","0.92744","8,256.36230","0.1613","401.6669"
"56.40000","0.93006","8,262.64453","0.1618","401.9725"
"56.60000","0.93369","8,296.90430","0.1620","403.6393"
"56.80000","0.93719","8,324.29785","0.1625","404.9719"
"57.00000","0.94031","8,345.38574","0.1631","405.9978"
"57.20000","0.94394","8,374.00488","0.1638","407.3901"
"57.40000","0.94694","8,393.74805","0.1645","408.3506"
"57.60000","0.95087","8,426.99805","0.1651","409.9682"
"57.80000","0.95325","8,431.65625","0.1655","410.1949"
"58.00000","0.95719","8,472.01953","0.1663","412.1585"
"58.20000","0.96037","8,491.61035","0.1664","413.1116"
"58.40000","0.96387","8,522.33691","0.1672","414.6064"
"58.60000","0.96731","8,541.66211","0.1676","415.5466"
"58.80000","0.97031","8,565.40137","0.1680","416.7015"
"59.00000","0.97394","8,594.23535","0.1688","418.1042"
"59.20000","0.97669","8,608.23730","0.1693","418.7854"
"59.40000","0.98044","8,645.60254","0.1699","420.6032"
"59.60000","0.98362","8,663.95410","0.1705","421.4960"
"59.80000","0.98737","8,699.79590","0.1712","423.2397"
"60.00000","0.99019","8,707.83984","0.1713","423.6310"
"60.20000","0.99375","8,742.34961","0.1723","425.3099"
"60.40000","0.99712","8,766.44531","0.1726","426.4821"
"60.60000","1.00012","8,785.58984","0.1733","427.4135"
"60.80000","1.00394","8,822.22656","0.1740","429.1959"
"61.00000","1.00694","8,836.75488","0.1744","429.9026"
"61.20000","1.01087","8,874.99512","0.1752","431.7630"
"61.40000","1.01344","8,879.97754","0.1751","432.0054"
"61.60000","1.01706","8,916.19727","0.1759","433.7675"
"61.80000","1.02050","8,942.17871","0.1767","435.0315"
"62.00000","1.02362","8,963.94727","0.1771","436.0905"
"62.20000","1.02725","8,994.73438","0.1777","437.5883"
"62.40000","1.03031","9,014.32715","0.1780","438.5414"
"62.60000","1.03412","9,046.40137","0.1788","440.1018"
"62.80000","1.03662","9,055.91992","0.1791","440.5649"
"63.00000","1.04044","9,093.90332","0.1799","442.4128"
"63.20000","1.04369","9,115.54980","0.1807","443.4659"
"63.40000","1.04725","9,149.29395","0.1814","445.1075"
"63.60000","1.05044","9,166.15234","0.1815","445.9276"
"63.80000","1.05369","9,193.77832","0.1824","447.2716"
"64.00000","1.05744","9,223.83203","0.1829","448.7337"
"64.20000","1.06000","9,233.84668","0.1834","449.2209"
"85.23200","1.06256","9,044.70703","0.1859","440.0194"
"85.43200","1.06300","9,046.84766","0.1876","440.1235"
"85.63200","1.06781","9,163.94043","0.2061","445.8200"
"85.83200","1.07131","9,254.95410","0.2196","450.2478"
"86.03200","1.07506","9,329.73730","0.2340","453.8859"
"86.23200","1.07800","9,381.84375","0.2453","456.4209"
"86.43200","1.08200","9,431.37012","0.2607","458.8303"
"86.63200","1.08444","9,427.72363","0.2701","458.6529"
"86.83200","1.08819","9,454.11719","0.2845","459.9370"
"87.03200","1.09162","9,469.10645","0.2977","460.6662"
"87.23200","1.09481","9,490.98730","0.3100","461.7307"
"87.43200","1.09837","9,514.73633","0.3237","462.8860"
"87.63200","1.10144","9,537.03809","0.3355","463.9710"
"87.83200","1.10519","9,567.78516","0.3499","465.4668"
"88.03200","1.10769","9,577.09961","0.3595","465.9200"
"88.23200","1.11162","9,616.94434","0.3746","467.8584"
"88.43200","1.11469","9,634.79102","0.3864","468.7266"
"88.63200","1.11837","9,671.53516","0.4006","470.5142"
"88.83200","1.12137","9,683.50488","0.4121","471.0965"
"89.03200","1.12481","9,715.96973","0.4254","472.6759"
"89.23200","1.12837","9,743.00098","0.4391","473.9910"
"89.43200","1.13112","9,757.90430","0.4496","474.7160"
"89.63200","1.13500","9,797.99512","0.4645","476.6664"
"89.83200","1.13812","9,815.25000","0.4766","477.5058"
"90.03200","1.14181","9,851.40625","0.4908","479.2648"
"90.23200","1.14450","9,859.89941","0.5011","479.6780"
"90.43200","1.14819","9,895.85254","0.5153","481.4271"
"90.63200","1.15162","9,924.39258","0.5285","482.8156"
"90.83200","1.15469","9,943.46875","0.5403","483.7436"
"91.03200","1.15831","9,975.80371","0.5542","485.3167"
"91.23200","1.16137","9,994.80469","0.5660","486.2411"
"91.43200","1.16531","10,031.60742","0.5811","488.0315"
"91.63200","1.16775","10,037.11133","0.5905","488.2993"
"91.83200","1.17156","10,076.77734","0.6052","490.2290"
"92.03200","1.17487","10,100.99023","0.6179","491.4069"
"92.23200","1.17819","10,129.13770","0.6307","492.7763"
"92.43200","1.18169","10,153.79688","0.6441","493.9759"
"92.63200","1.18469","10,175.73047","0.6557","495.0430"
"92.83200","1.18856","10,210.16211","0.6706","496.7180"
"93.03200","1.19106","10,218.62891","0.6802","497.1300"
"93.23200","1.19494","10,259.69043","0.6951","499.1276"
"93.43200","1.19812","10,280.58203","0.7073","500.1440"
"93.63200","1.20169","10,315.86719","0.7210","501.8605"
"93.83200","1.20469","10,327.88770","0.7326","502.4453"
"94.03200","1.20812","10,362.43262","0.7458","504.1259"
"94.23200","1.21156","10,389.00879","0.7590","505.4189"
"94.43200","1.21450","10,406.86035","0.7703","506.2873"
"94.63200","1.21837","10,447.47363","0.7852","508.2631"
"94.83200","1.22131","10,461.62598","0.7965","508.9516"
"95.03200","1.22531","10,501.49316","0.8119","510.8911"
"95.23200","1.22787","10,507.11035","0.8218","511.1644"
"95.43200","1.23150","10,543.98633","0.8357","512.9584"
"95.63200","1.23500","10,570.95117","0.8492","514.2702"
"95.83200","1.23800","10,592.35449","0.8607","515.3115"
"96.03200","1.24169","10,626.11914","0.8749","516.9541"
"96.23200","1.24475","10,645.94531","0.8867","517.9186"
"96.43200","1.24856","10,677.98633","0.9013","519.4774"
"96.63200","1.25106","10,687.40039","0.9109","519.9354"
"96.83200","1.25481","10,725.65527","0.9254","521.7965"
"97.03200","1.25812","10,749.37109","0.9381","522.9503"
"97.23200","1.26156","10,782.23340","0.9513","524.5490"
"97.43200","1.26487","10,800.96484","0.9641","525.4603"
"97.63200","1.26812","10,829.59961","0.9766","526.8533"
"97.83200","1.27194","10,862.79492","0.9912","528.4683"
"98.03200","1.27444","10,872.11719","1.0008","528.9218"
"98.23400","1.27831","10,913.07910","1.0158","530.9146"
"98.43400","1.28144","10,934.05371","1.0278","531.9349"
"98.63400","1.28512","10,971.45117","1.0420","533.7543"
"98.83400","1.28825","10,985.97754","1.0540","534.4610"
"99.03400","1.29144","11,014.23926","1.0662","535.8359"
"99.23400","1.29494","11,043.57812","1.0797","537.2632"
"99.43400","1.29787","11,062.35254","1.0910","538.1766"
"99.63400","1.30162","11,099.69336","1.1054","539.9932"
"99.83400","1.30475","11,118.79883","1.1174","540.9227"
"100.03400","1.30856","11,156.90527","1.1321","542.7766"
"100.23400","1.31125","11,164.69434","1.1424","543.1555"
"100.43400","1.31494","11,203.05859","1.1566","545.0219"
"100.63400","1.31825","11,227.90039","1.1694","546.2304"
"100.83400","1.32137","11,252.19434","1.1814","547.4123"
"101.03400","1.32512","11,286.60547","1.1958","549.0864"
"101.23400","1.32800","11,305.27637","1.2069","549.9947"
"101.43400","1.33200","11,344.47363","1.2222","551.9016"
"101.63400","1.33444","11,351.08594","1.2316","552.2233"
"101.83400","1.33819","11,390.25098","1.2460","554.1287"
"102.03400","1.34162","11,416.21875","1.2593","555.3920"
"102.23400","1.34481","11,443.93457","1.2715","556.7404"
"102.43400","1.34837","11,471.56055","1.2852","558.0843"
"102.63400","1.35150","11,497.16211","1.2972","559.3298"
"102.83400","1.35519","11,528.20117","1.3114","560.8398"
"103.03400","1.35775","11,540.24023","1.3213","561.4255"
"103.23400","1.36169","11,582.61328","1.3364","563.4869"
"103.43400","1.36481","11,602.62793","1.3484","564.4606"
"103.63400","1.36844","11,640.11621","1.3624","566.2844"
"103.83400","1.37144","11,653.47754","1.3739","566.9344"
"104.03400","1.37481","11,688.31641","1.3869","568.6293"
"104.23400","1.37837","11,717.50781","1.4006","570.0495"
"104.43400","1.38112","11,733.38379","1.4112","570.8218"
"104.63400","1.38500","11,774.22070","1.4261","572.8085"
"104.83400","1.38812","11,793.45605","1.4381","573.7443"
"105.03400","1.39181","11,830.90332","1.4523","575.5661"
"105.23400","1.39456","11,839.90039","1.4629","576.0038"
"105.43400","1.39819","11,876.34473","1.4768","577.7768"
"105.63400","1.40169","11,907.20605","1.4903","579.2782"
"105.83400","1.40469","11,927.36133","1.5018","580.2587"
"106.03400","1.40837","11,962.10645","1.5160","581.9491"
"106.23400","1.41144","11,982.94727","1.5278","582.9630"
"106.43400","1.41531","12,020.51660","1.5427","584.7907"
"106.63400","1.41775","12,028.25977","1.5520","585.1674"
"106.83400","1.42156","12,070.52930","1.5667","587.2238"
"107.03400","1.42494","12,095.37207","1.5797","588.4324"
"107.23400","1.42819","12,127.73145","1.5922","590.0066"
"107.43400","1.43175","12,152.12988","1.6059","591.1936"
"107.63400","1.43469","12,177.02344","1.6172","592.4047"
"107.83400","1.43862","12,214.74707","1.6323","594.2399"
"108.03400","1.44112","12,224.63867","1.6420","594.7211"
"108.23400","1.44494","12,266.06348","1.6566","596.7364"
"108.43400","1.44825","12,288.64160","1.6694","597.8348"
"108.63400","1.45169","12,324.64453","1.6826","599.5863"
"108.83400","1.45475","12,338.26660","1.6944","600.2490"
"109.03400","1.45819","12,373.68164","1.7076","601.9719"
"109.23400","1.46162","12,402.77148","1.7208","603.3871"
"109.43400","1.46450","12,422.51270","1.7319","604.3475"
"109.63400","1.46831","12,463.50781","1.7465","606.3419"
"109.83400","1.47137","12,482.25293","1.7583","607.2538"
"110.03400","1.47525","12,523.52441","1.7732","609.2617"
"110.23400","1.47781","12,530.82617","1.7831","609.6169"
"110.43400","1.48150","12,569.92090","1.7972","611.5189"
"110.63400","1.48500","12,600.02734","1.8107","612.9835"
"110.83400","1.48800","12,622.01855","1.8222","614.0534"
"111.03400","1.49175","12,658.03320","1.8367","615.8055"
"111.23400","1.49481","12,679.75684","1.8484","616.8623"
"111.43400","1.49862","12,714.67383","1.8631","618.5610"
"111.63400","1.50112","12,725.18164","1.8727","619.0722"
"111.83400","1.50487","12,764.80371","1.8871","620.9998"
"112.03400","1.50819","12,790.51172","1.8999","622.2505"
"112.23400","1.51156","12,824.11035","1.9129","623.8850"
"112.43400","1.51500","12,847.20703","1.9261","625.0087"
"112.63400","1.51812","12,876.25098","1.9381","626.4216"
"112.83400","1.52194","12,910.69434","1.9528","628.0973"
"113.03400","1.52437","12,921.19434","1.9621","628.6081"
"113.23400","1.52825","12,962.54395","1.9770","630.6198"
"113.43400","1.53144","12,985.29785","1.9893","631.7267"
"113.63400","1.53512","13,024.54883","2.0035","633.6362"
"113.83400","1.53825","13,039.66602","2.0155","634.3716"
"114.03400","1.54150","13,070.23047","2.0280","635.8586"
"114.23400","1.54494","13,101.23926","2.0412","637.3672"
"114.43400","1.54794","13,123.05371","2.0528","638.4284"
"114.63400","1.55162","13,160.43848","2.0670","640.2472"
"114.83400","1.55475","13,181.59961","2.0790","641.2767"
"115.03400","1.55850","13,221.98535","2.0934","643.2414"
"115.23400","1.56125","13,231.98242","2.1040","643.7277"
"115.43400","1.56487","13,271.30371","2.1179","645.6407"
"115.63400","1.56819","13,298.33008","2.1307","646.9555"
"115.83400","1.57137","13,324.59473","2.1429","648.2333"
"116.03400","1.57512","13,360.02637","2.1573","649.9570"
"116.23400","1.57806","13,380.22461","2.1686","650.9396"
"116.43400","1.58200","13,419.33496","2.1838","652.8423"
"116.63400","1.58444","13,426.71387","2.1932","653.2013"
"116.83400","1.58819","13,467.17578","2.2076","655.1697"
"117.03400","1.59169","13,494.81934","2.2210","656.5146"
"117.23400","1.59481","13,524.79883","2.2331","657.9731"
"117.43400","1.59831","13,551.48730","2.2465","659.2715"
"117.63400","1.60150","13,579.02148","2.2588","660.6110"
"117.83400","1.60512","13,610.17676","2.2727","662.1266"
"118.03400","1.60775","13,625.64258","2.2828","662.8791"
"118.23400","1.61162","13,666.08691","2.2977","664.8467"
"118.43400","1.61481","13,688.82812","2.3100","665.9530"
"118.63400","1.61844","13,727.08203","2.3239","667.8140"
"118.83400","1.62144","13,740.89551","2.3355","668.4860"
"119.03400","1.62487","13,777.34375","2.3487","670.2592"
"119.23400","1.62844","13,807.25488","2.3624","671.7144"
"119.43400","1.63112","13,825.15625","2.3727","672.5853"
"119.63400","1.63500","13,867.73242","2.3876","674.6566"
"119.83400","1.63812","13,887.64258","2.3996","675.6252"
"120.03400","1.64187","13,926.78613","2.4141","677.5295"
"120.23400","1.64456","13,937.29883","2.4244","678.0410"
"120.43400","1.64812","13,974.48926","2.4381","679.8502"
"120.63400","1.65169","14,008.04102","2.4518","681.4825"
"120.83400","1.65469","14,030.91504","2.4633","682.5953"
"121.03400","1.65837","14,065.83496","2.4775","684.2941"
"121.23400","1.66144","14,088.03613","2.4893","685.3742"
"121.43400","1.66525","14,125.80566","2.5040","687.2117"
"121.63400","1.66775","14,136.22949","2.5136","687.7188"
"121.83400","1.67162","14,178.38379","2.5285","689.7696"
"122.03400","1.67494","14,203.87012","2.5412","691.0095"
"122.23400","1.67819","14,236.09961","2.5537","692.5775"
"122.43400","1.68175","14,261.74512","2.5674","693.8251"
"122.63400","1.68475","14,286.51855","2.5790","695.0303"
"122.83400","1.68869","14,324.81445","2.5941","696.8934"
"123.03400","1.69106","14,334.70508","2.6033","697.3745"
"123.23400","1.69494","14,378.39258","2.6182","699.4999"
"123.43400","1.69819","14,402.59180","2.6307","700.6772"
"123.63400","1.70169","14,438.92090","2.6441","702.4446"
"123.83400","1.70469","14,453.17285","2.6557","703.1379"
"124.03400","1.70825","14,490.07422","2.6694","704.9331"
"124.23400","1.71162","14,518.62891","2.6823","706.3223"
"124.43400","1.71450","14,538.51465","2.6934","707.2897"
"124.63400","1.71831","14,580.59668","2.7081","709.3370"
"124.83400","1.72144","14,598.93555","2.7201","710.2292"
"125.03400","1.72531","14,640.87402","2.7350","712.2695"
"125.23400","1.72787","14,648.39258","2.7448","712.6353"
"125.43400","1.73150","14,688.86621","2.7588","714.6042"
"125.63400","1.73506","14,717.78027","2.7725","716.0109"
"125.83400","1.73800","14,740.66992","2.7838","717.1245"
"126.03400","1.74175","14,775.96191","2.7982","718.8414"
"126.23400","1.74481","14,799.82324","2.8100","720.0023"
"126.42200","1.74862","14,606.49707","2.8246","710.5970"
"126.42600","1.74925","13,754.45117","2.8270","669.1455"
"126.43000","1.75000","12,417.12402","2.8299","604.0854"
"126.43400","1.75081","10,821.19824","2.8331","526.4446"
"126.43800","1.75156","9,126.57227","2.8359","444.0021"
"126.44000","1.75194","8,282.01367","2.8374","402.9148"